Workbook

Sheet กราฟ
B1: ต.ค. 67 | C1: พ.ย. 67 | D1: ธ.ค. 67 | E1: ม.ค. 68 | F1: ก.พ. 68 | G1: มี.ค. 68 | H1: เม.ย. 68 | I1: พ.ค. 68 | J1: มิ.ย. 68 | K1: ก.ค. 68 | L1: ส.ค. 68 | M1: ก.ย. 68
A2: ชลบุรี (พ) | B2: ='ต.ค.67'!H4 -> 21.087063 | C2: ='พ.ย.67'!H4 -> 20.514384 | D2: ='ธ.ค.67'!H4 -> 22.152389 | E2: ='ม.ค.68'!H4 -> 22.513501 | F2: ='ก.พ.68'!H4 -> 20.071272 | G2: ='มี.ค.68'!H4 -> 19.228967 | H2: ='เม.ย.68'!H4 -> 21.992245 | I2: 23.359155 | J2: 22.692473 | K2: 21.923846 | L2: 22.500438 | M2: 20.8733
A3: พัทยา (พ) | B3: ='ต.ค.67'!H5 -> 22.052914 | C3: ='พ.ย.67'!H5 -> 23.01982 | D3: ='ธ.ค.67'!H5 -> 15.892192 | E3: ='ม.ค.68'!H5 -> 24.224127 | F3: ='ก.พ.68'!H5 -> 24.87097 | G3: ='มี.ค.68'!H5 -> 22.307143 | H3: ='เม.ย.68'!H5 -> 22.131162 | I3: 23.322064 | J3: 27.696094 | K3: 23.66851 | L3: 18.183747 | M3: 18.20005
A4: บ้านบึง | B4: ='ต.ค.67'!H6 -> 28.527022 | C4: ='พ.ย.67'!H6 -> 22.385757 | D4: ='ธ.ค.67'!H6 -> 28.244876 | E4: ='ม.ค.68'!H6 -> 25.644863 | F4: ='ก.พ.68'!H6 -> 21.208302 | G4: ='มี.ค.68'!H6 -> 22.644528 | H4: ='เม.ย.68'!H6 -> 23.344991 | I4: 26.110526 | J4: 25.874725 | K4: 23.435902 | L4: 24.960211 | M4: 26.833944
A5: พนัสนิคม | B5: ='ต.ค.67'!H7 -> 21.92799 | C5: ='พ.ย.67'!H7 -> 19.462547 | D5: ='ธ.ค.67'!H7 -> 24.265374 | E5: ='ม.ค.68'!H7 -> 20.34341 | F5: ='ก.พ.68'!H7 -> 18.3155 | G5: ='มี.ค.68'!H7 -> 19.989282 | H5: ='เม.ย.68'!H7 -> 21.765327 | I5: 24.982035 | J5: 20.107714 | K5: 26.93757 | L5: 24.263136 | M5: 20.27631
A6: ศรีราชา | B6: ='ต.ค.67'!H8 -> 24.569307 | C6: ='พ.ย.67'!H8 -> 26.220477 | D6: ='ธ.ค.67'!H8 -> 25.544572 | E6: ='ม.ค.68'!H8 -> 28.280223 | F6: ='ก.พ.68'!H8 -> 28.942336 | G6: ='มี.ค.68'!H8 -> 29.256897 | H6: ='เม.ย.68'!H8 -> 30.245541 | I6: 31.606866 | J6: 34.698798 | K6: 35.144435 | L6: 34.816272 | M6: 30.307215
A7: แหลมฉบัง | B7: ='ต.ค.67'!H9 -> 17.640718 | C7: ='พ.ย.67'!H9 -> 16.38058 | D7: ='ธ.ค.67'!H9 -> 15.535723 | E7: ='ม.ค.68'!H9 -> 17.457824 | F7: ='ก.พ.68'!H9 -> 21.767911 | G7: ='มี.ค.68'!H9 -> 24.42813 | H7: ='เม.ย.68'!H9 -> 26.181291 | I7: 26.391884 | J7: 24.868521 | K7: 24.7059 | L7: 21.911979 | M7: 22.478473
A8: ฉะเชิงเทรา | B8: ='ต.ค.67'!H10 -> 14.982422 | C8: ='พ.ย.67'!H10 -> 15.03273 | D8: ='ธ.ค.67'!H10 -> 14.639489 | E8: ='ม.ค.68'!H10 -> 12.324339 | F8: ='ก.พ.68'!H10 -> 14.075352 | G8: ='มี.ค.68'!H10 -> 14.910156 | H8: ='เม.ย.68'!H10 -> 12.815924 | I8: 15.875684 | J8: 13.678822 | K8: 10.191646 | L8: 8.6675224 | M8: 9.1558411
A9: บางปะกง | B9: ='ต.ค.67'!H11 -> 11.457724 | C9: ='พ.ย.67'!H11 -> 9.9945792 | D9: ='ธ.ค.67'!H11 -> 11.821707 | E9: ='ม.ค.68'!H11 -> 11.218265 | F9: ='ก.พ.68'!H11 -> 9.1388132 | G9: ='มี.ค.68'!H11 -> 8.3447192 | H9: ='เม.ย.68'!H11 -> 7.2029939 | I9: 8.0368643 | J9: 9.9967224 | K9: 8.8465823 | L9: 1.1742889 | M9: 7.4081092
A10: บางคล้า | B10: ='ต.ค.67'!H12 -> 28.602361 | C10: ='พ.ย.67'!H12 -> 28.214867 | D10: ='ธ.ค.67'!H12 -> 27.317381 | E10: ='ม.ค.68'!H12 -> 25.893601 | F10: ='ก.พ.68'!H12 -> 25.830319 | G10: ='มี.ค.68'!H12 -> 27.335961 | H10: ='เม.ย.68'!H12 -> 25.6773 | I10: 29.65373 | J10: 29.195829 | K10: 28.985286 | L10: 26.971163 | M10: 22.845477
A11: พนมสารคาม | B11: ='ต.ค.67'!H13 -> 31.751512 | C11: ='พ.ย.67'!H13 -> 30.737005 | D11: ='ธ.ค.67'!H13 -> 30.060293 | E11: ='ม.ค.68'!H13 -> 37.110738 | F11: ='ก.พ.68'!H13 -> 35.320423 | G11: ='มี.ค.68'!H13 -> 24.220744 | H11: ='เม.ย.68'!H13 -> 33.033048 | I11: 31.378375 | J11: 30.627374 | K11: 31.380545 | L11: 30.118001 | M11: 28.452671
A12: ระยอง | B12: ='ต.ค.67'!H14 -> 15.575874 | C12: ='พ.ย.67'!H14 -> 12.548684 | D12: ='ธ.ค.67'!H14 -> 11.328834 | E12: ='ม.ค.68'!H14 -> 15.619641 | F12: ='ก.พ.68'!H14 -> 14.137799 | G12: ='มี.ค.68'!H14 -> 10.226945 | H12: ='เม.ย.68'!H14 -> 16.015116 | I12: 17.033272 | J12: 13.293066 | K12: 16.444164 | L12: 13.21031 | M12: 11.057851
A13: บ้านฉาง | B13: ='ต.ค.67'!H15 -> 34.945302 | C13: ='พ.ย.67'!H15 -> 30.601873 | D13: ='ธ.ค.67'!H15 -> 32.003109 | E13: ='ม.ค.68'!H15 -> 30.59501 | F13: ='ก.พ.68'!H15 -> 31.926676 | G13: ='มี.ค.68'!H15 -> 27.367891 | H13: ='เม.ย.68'!H15 -> 28.344373 | I13: 27.26882 | J13: 17.980375 | K13: 20.106952 | L13: 22.09413 | M13: 24.165905
... A24: ภาพรวม กปภ.ข.1 | B24: ='ต.ค.67'!H26 -> 27.80425 | C24: ='พ.ย.67'!H26 -> 26.803906 | D24: ='ธ.ค.67'!H26 -> 26.071636 | E24: ='ม.ค.68'!H26 -> 26.864509 | F24: ='ก.พ.68'!H26 -> 26.351473 | G24: ='มี.ค.68'!H26 -> 25.753814 | H24: ='เม.ย.68'!H26 -> 26.855899 | I24: 28.12121 | J24: 27.170513 | K24: 27.540516 | L24: 25.96553 | M24: 25.342944

Sheet ต.ค.67
A1: ข้อมูลน้ำสูญเสียตัวจริงที่ใช้ในการบริหารของ กปภ.เขต 1 เดือนตุลาคม 2567
A2: ลำดับ | B2: กปภ.สาขา | C2: น้ำผลิตรวมจริง | D2: น้ำผลิตจ่ายสุทธิจริง | E2: น้ำจำหน่ายจริง | F2: น้ำ Blow off จริง | G2: น้ำสูญเสียจริง | I2: หมายเหตุ
C3: (ลบ.ม.) | D3: (ลบ.ม.) | E3: (ลบ.ม.) | F3: (ลบ.ม.) | G3: ปริมาณ (ลบ.ม.) | H3: อัตรา (%)
A4: 1 | B4: ชลบุรี (พ) | C4: 4724559 | D4: 5351753.4 | E4: 3852205 | F4: 371020.78 | G4: =D4-E4-F4 -> 1128527.6 | H4: =(G4/D4)*100 -> 21.087063
A5: 2 | B5: พัทยา (พ) | C5: 6208172 | D5: 5911462.8 | E5: 4522933 | F5: 84880 | G5: =D5-E5-F5 -> 1303649.8 | H5: =(G5/D5)*100 -> 22.052914 | I5: น้ำล้างเส้นท่อ-ทดสอบท่อใหม่ (531,778 ลบ.ม.
A6: 3 | B6: บ้านบึง | C6: 2020422.6 | D6: 1830345.1 | E6: 1255153 | F6: 53049.15 | G6: =D6-E6-F6 -> 522142.95 | H6: =(G6/D6)*100 -> 28.527022
A7: 4 | B7: พนัสนิคม | C7: 2309480 | D7: 2164430 | E7: 1664101 | F7: 25713 | G7: =D7-E7-F7 -> 474616 | H7: =(G7/D7)*100 -> 21.92799
A8: 5 | B8: ศรีราชา | C8: 2550250 | D8: 2348807.8 | E8: 1546722 | F8: 225000 | G8: =D8-E8-F8 -> 577085.81 | H8: =(G8/D8)*100 -> 24.569307
A9: 6 | B9: แหลมฉบัง | C9: 2566368 | D9: 2545891 | E9: 2037831 | F9: 58946.55 | G9: =D9-E9-F9 -> 449113.45 | H9: =(G9/D9)*100 -> 17.640718
A10: 7 | B10: ฉะเชิงเทรา | C10: 1090298.8 | D10: 1085316 | E10: 853412 | F10: 69297.38 | G10: =D10-E10-F10 -> 162606.62 | H10: =(G10/D10)*100 -> 14.982422
A11: 8 | B11: บางปะกง | C11: 1352765 | D11: 1336466 | E11: 1134622 | F11: 48715.42 | G11: =D11-E11-F11 -> 153128.58 | H11: =(G11/D11)*100 -> 11.457724
A12: 9 | B12: บางคล้า | C12: 2762431 | D12: 2481639.5 | E12: 1731832 | F12: 40000 | G12: =D12-E12-F12 -> 709807.5 | H12: =(G12/D12)*100 -> 28.602361
A13: 10 | B13: พนมสารคาม | C13: 960470.31 | D13: 817054 | E13: 533604 | F13: 24023 | G13: =D13-E13-F13 -> 259427 | H13: =(G13/D13)*100 -> 31.751512
A14: 11 | B14: ระยอง | C14: 2058303 | D14: 2038717 | E14: 1608533 | F14: 112636 | G14: =D14-E14-F14 -> 317548 | H14: =(G14/D14)*100 -> 15.575874
A15: 12 | B15: บ้านฉาง | C15: 3208007 | D15: 3721516 | E15: 2254150 | F15: 166871 | G15: =D15-E15-F15 -> 1300495 | H15: =(G15/D15)*100 -> 34.945302
A16: 13 | B16: ปากน้ำประแสร์ | C16: 1010058 | D16: 966190 | E16: 431294 | F16: 6184 | G16: =D16-E16-F16 -> 528712 | H16: =(G16/D16)*100 -> 54.721328
A17: 14 | B17: จันทบุรี | C17: 2254063 | D17: 1993568 | E17: 1295347 | F17: 76000 | G17: =D17-E17-F17 -> 622221 | H17: =(G17/D17)*100 -> 31.211426
... A25: 22 | B25: กบินทร์บุรี | C25: 657424 | D25: 627424 | E25: 382850 | F25: 20000 | G25: =D25-E25-F25 -> 224574 | H25: =(G25/D25)*100 -> 35.79302
A26: รวม กปภ.ข.1 | C26: =SUM(C4:C25) -> 41210096 | D26: =SUM(D4:D25) -> 40241769 | E26: =SUM(E4:E25) -> 27547232 | F26: =SUM(F4:F25) -> 1505615 | G26: =SUM(G4:G25) -> 11188922 | H26: =(G26/D26)*100 -> 27.80425

Sheet พ.ย.67
A1: ข้อมูลน้ำสูญเสียตัวจริงที่ใช้ในการบริหารของ กปภ.เขต 1 เดือนพฤศจิกายน 2567
A2: ลำดับ | B2: กปภ.สาขา | C2: น้ำผลิตรวมจริง | D2: น้ำผลิตจ่ายสุทธิจริง | E2: น้ำจำหน่ายจริง | F2: น้ำ Blow off จริง | G2: น้ำสูญเสียจริง | I2: หมายเหตุ | J2: ผู้ลงข้อมูล | K2: เบอร์ติดต่อ
C3: (ลบ.ม.) | D3: (ลบ.ม.) | E3: (ลบ.ม.) | F3: (ลบ.ม.) | G3: ปริมาณ (ลบ.ม.) | H3: อัตรา (%)
A4: 1 | B4: ชลบุรี (พ) | C4: 3844427 | D4: 5242837 | E4: 3788303 | F4: 378998.27 | G4: =D4-E4-F4 -> 1075535.7 | H4: =(G4/D4)*100 -> 20.514384
A5: 2 | B5: พัทยา (พ) | C5: 6415265 | D5: 6235435 | E5: 4699040 | F5: 101009.08 | G5: =D5-E5-F5 -> 1435385.9 | H5: =(G5/D5)*100 -> 23.01982
A6: 3 | B6: บ้านบึง | C6: 2528680.9 | D6: 1675103.9 | E6: 1248268 | F6: 51851.17 | G6: =D6-E6-F6 -> 374984.68 | H6: =(G6/D6)*100 -> 22.385757
A7: 4 | B7: พนัสนิคม | C7: 2302731 | D7: 2076871 | E7: 1644539 | F7: 28120 | G7: =D7-E7-F7 -> 404212 | H7: =(G7/D7)*100 -> 19.462547
A8: 5 | B8: ศรีราชา | C8: 2636781 | D8: 2328154.1 | E8: 1551876 | F8: 165825 | G8: =D8-E8-F8 -> 610453.1 | H8: =(G8/D8)*100 -> 26.220477
A9: 6 | B9: แหลมฉบัง | C9: 2462553 | D9: 2437903 | E9: 1986241 | F9: 52319.36 | G9: =D9-E9-F9 -> 399342.64 | H9: =(G9/D9)*100 -> 16.38058
A10: 7 | B10: ฉะเชิงเทรา | C10: 1064149 | D10: 1063774 | E10: 860921 | F10: 42938.73 | G10: =D10-E10-F10 -> 159914.27 | H10: =(G10/D10)*100 -> 15.03273
A11: 8 | B11: บางปะกง | C11: 1293021 | D11: 1279509 | E11: 1104105 | F11: 47522.46 | G11: =D11-E11-F11 -> 127881.54 | H11: =(G11/D11)*100 -> 9.9945792
A12: 9 | B12: บางคล้า | C12: 2781017 | D12: 2470662 | E12: 1733568 | F12: 40000 | G12: =D12-E12-F12 -> 697094 | H12: =(G12/D12)*100 -> 28.214867
A13: 10 | B13: พนัมสารคาม | C13: 852216.02 | D13: 813495 | E13: 544398 | F13: 19053 | G13: =D13-E13-F13 -> 250044 | H13: =(G13/D13)*100 -> 30.737005
A14: 11 | B14: ระยอง | C14: 1990228 | D14: 1971139 | E14: 1611998 | F14: 111789 | G14: =D14-E14-F14 -> 247352 | H14: =(G14/D14)*100 -> 12.548684
A15: 12 | B15: บ้านฉาง | C15: 3141363 | D15: 3520242 | E15: 2266685 | F15: 176297 | G15: =D15-E15-F15 -> 1077260 | H15: =(G15/D15)*100 -> 30.601873
... A25: 22 | B25: กบินทร์บุรี | C25: 494228 | D25: 490228 | E25: 287008 | F25: 20000 | G25: =D25-E25-F25 -> 183220 | H25: =(G25/D25)*100 -> 37.374446
A26: รวม กปภ.ข.1 | C26: =SUM(C4:C25) -> 40198328 | D26: =SUM(D4:D25) -> 39549512 | E26: =SUM(E4:E25) -> 27514903 | F26: =SUM(F4:F25) -> 1433794.8 | G26: =SUM(G4:G25) -> 10600814 | H26: =(G26/D26)*100 -> 26.803906

Sheet ธ.ค.67
A1: ข้อมูลน้ำสูญเสียตัวจริงที่ใช้ในการบริหารของ กปภ.เขต 1 เดือนธันวาคม 2567
A2: ลำดับ | B2: กปภ.สาขา | C2: น้ำผลิตรวมจริง | D2: น้ำผลิตจ่ายสุทธิจริง | E2: น้ำจำหน่ายจริง | F2: น้ำ Blow off จริง | G2: น้ำสูญเสียจริง | I2: หมายเหตุ | J2: ผู้ลงข้อมูล | K2: เบอร์ติดต่อ
C3: (ลบ.ม.) | D3: (ลบ.ม.) | E3: (ลบ.ม.) | F3: (ลบ.ม.) | G3: ปริมาณ (ลบ.ม.) | H3: อัตรา (%)
A4: 1 | B4: ชลบุรี (พ) | C4: 4619902 | D4: 5311816 | E4: 3957284 | F4: 177837.88 | G4: =D4-E4-F4 -> 1176694.1 | H4: =(G4/D4)*100 -> 22.152389
A5: 2 | B5: พัทยา (พ) | C5: 6660498 | D5: 6326117 | E5: 5217576 | F5: 103182.29 | G5: =D5-E5-F5 -> 1005358.7 | H5: =(G5/D5)*100 -> 15.892192
A6: 3 | B6: บ้านบึง | C6: 2285214.4 | D6: 1864825.9 | E6: 1282695 | F6: 55413.1 | G6: =D6-E6-F6 -> 526717.75 | H6: =(G6/D6)*100 -> 28.244876
A7: 4 | B7: พนัสนิคม | C7: 2277134 | D7: 2219498 | E7: 1650947.5 | F7: 29981 | G7: =D7-E7-F7 -> 538569.5 | H7: =(G7/D7)*100 -> 24.265374
A8: 5 | B8: ศรีราชา | C8: 2571127 | D8: 2482411.3 | E8: 1650290 | F8: 198000 | G8: =D8-E8-F8 -> 634121.34 | H8: =(G8/D8)*100 -> 25.544572
A9: 6 | B9: แหลมฉบัง | C9: 2502732 | D9: 2441961 | E9: 2012399 | F9: 50185.7 | G9: =D9-E9-F9 -> 379376.3 | H9: =(G9/D9)*100 -> 15.535723
A10: 7 | B10: ฉะเชิงเทรา | C10: 1114734 | D10: 1109607 | E10: 903347 | F10: 43819.21 | G10: =D10-E10-F10 -> 162440.79 | H10: =(G10/D10)*100 -> 14.639489
A11: 8 | B11: บางปะกง | C11: 1317557 | D11: 1297537 | E11: 1100943 | F11: 43202.98 | G11: =D11-E11-F11 -> 153391.02 | H11: =(G11/D11)*100 -> 11.821707
A12: 9 | B12: บางคล้า | C12: 2772984.1 | D12: 2460097.1 | E12: 1748063 | F12: 40000 | G12: =D12-E12-F12 -> 672034.1 | H12: =(G12/D12)*100 -> 27.317381
A13: 10 | B13: พนมสารคาม | C13: 871661.43 | D13: 830115 | E13: 557524 | F13: 23056 | G13: =D13-E13-F13 -> 249535 | H13: =(G13/D13)*100 -> 30.060293
A14: 11 | B14: ระยอง | C14: 2075219 | D14: 2055772 | E14: 1721909 | F14: 100968 | G14: =D14-E14-F14 -> 232895 | H14: =(G14/D14)*100 -> 11.328834
A15: 12 | B15: บ้านฉาง | C15: 3316918 | D15: 3740671 | E15: 2369933 | F15: 173607 | G15: =D15-E15-F15 -> 1197131 | H15: =(G15/D15)*100 -> 32.003109
... A25: 22 | B25: กบินทร์บุรี | C25: 503026 | D25: 503026 | E25: 298196 | F25: 20000 | G25: =D25-E25-F25 -> 184830 | H25: =(G25/D25)*100 -> 36.743628
A26: รวม กปภ.ข.1 | C26: =SUM(C4:C25) -> 41842947 | D26: =SUM(D4:D25) -> 40859140 | E26: =SUM(E4:E25) -> 28944522 | F26: =SUM(F4:F25) -> 1261972 | G26: =SUM(G4:G25) -> 10652646 | H26: =(G26/D26)*100 -> 26.071636

Sheet ม.ค.68
A1: ข้อมูลน้ำสูญเสียตัวจริงที่ใช้ในการบริหารของ กปภ.เขต 1 เดือนมกราคม 2568
A2: ลำดับ | B2: กปภ.สาขา | C2: น้ำผลิตรวมจริง | D2: น้ำผลิตจ่ายสุทธิจริง | E2: น้ำจำหน่ายจริง | F2: น้ำ Blow off จริง | G2: น้ำสูญเสียจริง | I2: หมายเหตุ | J2: ผู้ลงข้อมูล | K2: เบอร์ติดต่อ
C3: (ลบ.ม.) | D3: (ลบ.ม.) | E3: (ลบ.ม.) | F3: (ลบ.ม.) | G3: ปริมาณ (ลบ.ม.) | H3: อัตรา (%)
A4: 1 | B4: ชลบุรี (พ) | C4: 4374144 | D4: 5071114.5 | E4: 3823833 | F4: 105596.09 | G4: =D4-E4-F4 -> 1141685.4 | H4: =(G4/D4)*100 -> 22.513501
A5: 2 | B5: พัทยา (พ) | C5: 6907950 | D5: 6693203 | E5: 4950343 | F5: 121489.95 | G5: =D5-E5-F5 -> 1621370 | H5: =(G5/D5)*100 -> 24.224127
A6: 3 | B6: บ้านบึง | C6: 2433352 | D6: 1793243.2 | E6: 1277163 | F6: 56205.4 | G6: =D6-E6-F6 -> 459874.76 | H6: =(G6/D6)*100 -> 25.644863
A7: 4 | B7: พนัสนิคม | C7: 2337157 | D7: 2249758 | E7: 1723472.5 | F7: 68608 | G7: =D7-E7-F7 -> 457677.5 | H7: =(G7/D7)*100 -> 20.34341
A8: 5 | B8: ศรีราชา | C8: 2600390 | D8: 2458999.6 | E8: 1583339 | F8: 180250 | G8: =D8-E8-F8 -> 695410.56 | H8: =(G8/D8)*100 -> 28.280223
A9: 6 | B9: แหลมฉบัง | C9: 2549462 | D9: 2481043 | E9: 1970317 | F9: 77589.89 | G9: =D9-E9-F9 -> 433136.11 | H9: =(G9/D9)*100 -> 17.457824
A10: 7 | B10: ฉะเชิงเทรา | C10: 1049191.3 | D10: 1044507 | E10: 871730 | F10: 44048.42 | G10: =D10-E10-F10 -> 128728.58 | H10: =(G10/D10)*100 -> 12.324339
A11: 8 | B11: บางปะกง | C11: 1353852 | D11: 1325317 | E11: 1130888 | F11: 45751.43 | G11: =D11-E11-F11 -> 148677.57 | H11: =(G11/D11)*100 -> 11.218265
A12: 9 | B12: บางคล้า | C12: 2768546.6 | D12: 2481947.6 | E12: 1799282 | F12: 40000 | G12: =D12-E12-F12 -> 642665.6 | H12: =(G12/D12)*100 -> 25.893601
A13: 10 | B13: พนัมสารคาม | C13: 981625.2 | D13: 942905 | E13: 574951 | F13: 18035 | G13: =D13-E13-F13 -> 349919 | H13: =(G13/D13)*100 -> 37.110738
A14: 11 | B14: ระยอง | C14: 2100163 | D14: 2080592 | E14: 1642925 | F14: 112686 | G14: =D14-E14-F14 -> 324981 | H14: =(G14/D14)*100 -> 15.619641
A15: 12 | B15: บ้านฉาง | C15: 3331820 | D15: 3655802 | E15: 2412173 | F15: 125136 | G15: =D15-E15-F15 -> 1118493 | H15: =(G15/D15)*100 -> 30.59501
... A25: 22 | B25: กบินทร์บุรี | C25: 502946 | D25: 486945 | E25: 298196 | F25: 30000 | G25: =D25-E25-F25 -> 158749 | H25: =(G25/D25)*100 -> 32.601012
A26: รวม กปภ.ข.1 | C26: =SUM(C4:C25) -> 42165120 | D26: =SUM(D4:D25) -> 40633571 | E26: =SUM(E4:E25) -> 28527482 | F26: =SUM(F4:F25) -> 1190080.2 | G26: =SUM(G4:G25) -> 10916009 | H26: =(G26/D26)*100 -> 26.864509

Sheet ก.พ.68
A1: ข้อมูลน้ำสูญเสียตัวจริงที่ใช้ในการบริหารของ กปภ.เขต 1 เดือนกุมภาพันธ์ 2568
A2: ลำดับ | B2: กปภ.สาขา | C2: น้ำผลิตรวมจริง | D2: น้ำผลิตจ่ายสุทธิจริง | E2: น้ำจำหน่ายจริง | F2: น้ำ Blow off จริง | G2: น้ำสูญเสียจริง | I2: หมายเหตุ | J2: ผู้ลงข้อมูล | K2: เบอร์ติดต่อ
C3: (ลบ.ม.) | D3: (ลบ.ม.) | E3: (ลบ.ม.) | F3: (ลบ.ม.) | G3: ปริมาณ (ลบ.ม.) | H3: อัตรา (%)
A4: 1 | B4: ชลบุรี (พ) | C4: 3863302 | D4: 4731909 | E4: 3652154 | F4: 130000.69 | G4: =D4-E4-F4 -> 949754.31 | H4: =(G4/D4)*100 -> 20.071272
A5: 2 | B5: พัทยา (พ) | C5: 7030088 | D5: 6761072 | E5: 4949694 | F5: 129833.8 | G5: =D5-E5-F5 -> 1681544.2 | H5: =(G5/D5)*100 -> 24.87097
A6: 3 | B6: บ้านบึง | C6: 2488017 | D6: 1623133.8 | E6: 1219536 | F6: 59358.7 | G6: =D6-E6-F6 -> 344239.13 | H6: =(G6/D6)*100 -> 21.208302
A7: 4 | B7: พนัสนิคม | C7: 2084940 | D7: 2020065 | E7: 1593660 | F7: 56420 | G7: =D7-E7-F7 -> 369985 | H7: =(G7/D7)*100 -> 18.3155
A8: 5 | B8: ศรีราชา | C8: 2321138 | D8: 2221031.4 | E8: 1472713 | F8: 105500 | G8: =D8-E8-F8 -> 642818.35 | H8: =(G8/D8)*100 -> 28.942336
A9: 6 | B9: แหลมฉบัง | C9: 2546399 | D9: 2470570 | E9: 1873115 | F9: 59663.52 | G9: =D9-E9-F9 -> 537791.48 | H9: =(G9/D9)*100 -> 21.767911
A10: 7 | B10: ฉะเชิงเทรา | C10: 1026917.3 | D10: 1023840 | E10: 834966 | F10: 44764.92 | G10: =D10-E10-F10 -> 144109.08 | H10: =(G10/D10)*100 -> 14.075352
A11: 8 | B11: บางปะกง | C11: 1251385 | D11: 1233118 | E11: 1076481 | F11: 43944.65 | G11: =D11-E11-F11 -> 112692.35 | H11: =(G11/D11)*100 -> 9.1388132
A12: 9 | B12: บางคล้า | C12: 2580196.8 | D12: 2341276.1 | E12: 1696517 | F12: 40000 | G12: =D12-E12-F12 -> 604759.07 | H12: =(G12/D12)*100 -> 25.830319
A13: 10 | B13: พนมสารคาม | C13: 862517.91 | D13: 829840 | E13: 531725 | F13: 5012 | G13: =D13-E13-F13 -> 293103 | H13: =(G13/D13)*100 -> 35.320423
A14: 11 | B14: ระยอง | C14: 1904201 | D14: 1886312 | E14: 1536977 | F14: 82652 | G14: =D14-E14-F14 -> 266683 | H14: =(G14/D14)*100 -> 14.137799
A15: 12 | B15: บ้านฉาง | C15: 3016264 | D15: 3292510 | E15: 2211273 | F15: 30048 | G15: =D15-E15-F15 -> 1051189 | H15: =(G15/D15)*100 -> 31.926676
... A25: 22 | B25: กบินทร์บุรี | C25: 468959 | D25: 448026 | E25: 307828 | F25: 30000 | G25: =D25-E25-F25 -> 110198 | H25: =(G25/D25)*100 -> 24.59634
A26: รวม กปภ.ข.1 | C26: =SUM(C4:C25) -> 39422184 | D26: =SUM(D4:D25) -> 38077182 | E26: =SUM(E4:E25) -> 27095820 | F26: =SUM(F4:F25) -> 947463.64 | G26: =SUM(G4:G25) -> 10033898 | H26: =(G26/D26)*100 -> 26.351473

Sheet มี.ค.68
A1: ข้อมูลน้ำสูญเสียตัวจริงที่ใช้ในการบริหารของ กปภ.เขต 1 เดือนมีนาคม 2568
A2: ลำดับ | B2: กปภ.สาขา | C2: น้ำผลิตรวมจริง | D2: น้ำผลิตจ่ายสุทธิจริง | E2: น้ำจำหน่ายจริง | F2: น้ำ Blow off จริง | G2: น้ำสูญเสียจริง | I2: หมายเหตุ | J2: ผู้ลงข้อมูล | K2: เบอร์ติดต่อ
C3: (ลบ.ม.) | D3: (ลบ.ม.) | E3: (ลบ.ม.) | F3: (ลบ.ม.) | G3: ปริมาณ (ลบ.ม.) | H3: อัตรา (%)
A4: 1 | B4: ชลบุรี (พ) | C4: 4226373 | D4: 5166865 | E4: 4029726.9 | F4: 143603.38 | G4: =D4-E4-F4 -> 993534.76 | H4: =(G4/D4)*100 -> 19.228967 | L4: 4029726.9
A5: 2 | B5: พัทยา (พ) | C5: 6411988 | D5: 6023911 | E5: 4551075 | F5: 129073.6 | G5: =D5-E5-F5 -> 1343762.4 | H5: =(G5/D5)*100 -> 22.307143 | L5: 5038075.7
A6: 3 | B6: บ้านบึง | C6: 2756226 | D6: 1808091.2 | E6: 1338324 | F6: 60333.49 | G6: =D6-E6-F6 -> 409433.71 | H6: =(G6/D6)*100 -> 22.644528 | L6: 1338324
A7: 4 | B7: พนัสนิคม | C7: 2428517 | D7: 2272768 | E7: 1760440 | F7: 58018 | G7: =D7-E7-F7 -> 454310 | H7: =(G7/D7)*100 -> 19.989282 | L7: 1760440
A8: 5 | B8: ศรีราชา | C8: 2589155 | D8: 2565185.7 | E8: 1625192 | F8: 189500 | G8: =D8-E8-F8 -> 750493.74 | H8: =(G8/D8)*100 -> 29.256897 | L8: 1625192
A9: 6 | B9: แหลมฉบัง | C9: 2953572 | D9: 2853990 | E9: 2094899 | F9: 61914.6 | G9: =D9-E9-F9 -> 697176.4 | H9: =(G9/D9)*100 -> 24.42813 | L9: 2094899
A10: 7 | B10: ฉะเชิงเทรา | C10: 1134755 | D10: 1129063 | E10: 911183 | F10: 49534.95 | G10: =D10-E10-F10 -> 168345.05 | H10: =(G10/D10)*100 -> 14.910156 | L10: 911183
A11: 8 | B11: บางปะกง | C11: 1390919 | D11: 1371763 | E11: 1212629 | F11: 44664.23 | G11: =D11-E11-F11 -> 114469.77 | H11: =(G11/D11)*100 -> 8.3447192 | L11: 1212629
A12: 9 | B12: บางคล้า | C12: 2925520 | D12: 2656329.1 | E12: 1890196 | F12: 40000 | G12: =D12-E12-F12 -> 726133.1 | H12: =(G12/D12)*100 -> 27.335961 | L12: 1890196
A13: 10 | B13: พนมสารคาม | C13: 981525.98 | D13: 939133 | E13: 602593 | F13: 109075 | G13: =D13-E13-F13 -> 227465 | H13: =(G13/D13)*100 -> 24.220744 | L13: 602593
A14: 11 | B14: ระยอง | C14: 2094345 | D14: 2075274 | E14: 1730510.9 | F14: 132526 | G14: =D14-E14-F14 -> 212237.13 | H14: =(G14/D14)*100 -> 10.226945 | L14: 1730510.9
A15: 12 | B15: บ้านฉาง | C15: 3544389 | D15: 3705660 | E15: 2502282 | F15: 189217 | G15: =D15-E15-F15 -> 1014161 | H15: =(G15/D15)*100 -> 27.367891 | L15: 2502282
... A25: 22 | B25: กบินทร์บุรี | C25: 557727 | D25: 533721 | E25: 326885 | F25: 30000 | G25: =D25-E25-F25 -> 176836 | H25: =(G25/D25)*100 -> 33.132667 | L25: 326885
A26: รวม กปภ.ข.1 | C26: =SUM(C4:C25) -> 43060485 | D26: =SUM(D4:D25) -> 41067734 | E26: =SUM(E4:E25) -> 29089011 | F26: =SUM(F4:F25) -> 1402215.3 | G26: =SUM(G4:G25) -> 10576508 | H26: =(G26/D26)*100 -> 25.753814

Sheet เม.ย.68
A1: ข้อมูลน้ำสูญเสียตัวจริงที่ใช้ในการบริหารของ กปภ.เขต 1 เดือนเมษายน 2568
A2: ลำดับ | B2: กปภ.สาขา | C2: น้ำผลิตรวมจริง | D2: น้ำผลิตจ่ายสุทธิจริง | E2: น้ำจำหน่ายจริง | F2: น้ำ Blow off จริง | G2: น้ำสูญเสียจริง | I2: หมายเหตุ | J2: ผู้ลงข้อมูล | K2: เบอร์ติดต่อ
C3: (ลบ.ม.) | D3: (ลบ.ม.) | E3: (ลบ.ม.) | F3: (ลบ.ม.) | G3: ปริมาณ (ลบ.ม.) | H3: อัตรา (%)
A4: 1 | B4: ชลบุรี (พ) | C4: 3862486 | D4: 4986164 | E4: 3826169.2 | F4: 63425.42 | G4: =D4-E4-F4 -> 1096569.4 | H4: =(G4/D4)*100 -> 21.992245
A5: 2 | B5: พัทยา (พ) | C5: 7011624 | D5: 6797161.6 | E5: 5142167 | F5: 150703.7 | G5: =D5-E5-F5 -> 1504290.9 | H5: =(G5/D5)*100 -> 22.131162
A6: 3 | B6: บ้านบึง | C6: 2789954 | D6: 1760144.6 | E6: 1292400 | F6: 56839.02 | G6: =D6-E6-F6 -> 410905.61 | H6: =(G6/D6)*100 -> 23.344991
A7: 4 | B7: พนัสนิคม | C7: 2450893 | D7: 2297355 | E7: 1719027 | F7: 78301.18 | G7: =D7-E7-F7 -> 500026.82 | H7: =(G7/D7)*100 -> 21.765327 | J7: ธีรภัทร์ วงษ์จันนา | K7: 084-095-6569
A8: 5 | B8: ศรีราชา | C8: 2563076 | D8: 2466134.8 | E8: 1604959 | F8: 115280 | G8: =D8-E8-F8 -> 745895.82 | H8: =(G8/D8)*100 -> 30.245541 | J8: นิลาวัลย์ | K8: 099-016-3648
A9: 6 | B9: แหลมฉบัง | C9: 2945750 | D9: 2820453 | E9: 1992240 | F9: 89782 | G9: =D9-E9-F9 -> 738431 | H9: =(G9/D9)*100 -> 26.181291 | J9: ธนกฤต เล็กตระกูลชัย | K9: 083-767-4284
A10: 7 | B10: ฉะเชิงเทรา | C10: 1088607.8 | D10: 1083941 | E10: 895489 | F10: 49534.95 | G10: =D10-E10-F10 -> 138917.05 | H10: =(G10/D10)*100 -> 12.815924 | J10: ธนชนัญ สิทธิเวช | K10: 083-014-1725
A11: 8 | B11: บางปะกง | C11: 1303940 | D11: 1288970 | E11: 1156980 | F11: 39145.57 | G11: =D11-E11-F11 -> 92844.43 | H11: =(G11/D11)*100 -> 7.2029939 | J11: จีรพงศ์ พึ่งเกษม | K11: 085-115-6645
A12: 9 | B12: บางคล้า | C12: 2870180 | D12: 2626717 | E12: 1817247 | F12: 135000 | G12: =D12-E12-F12 -> 674470 | H12: =(G12/D12)*100 -> 25.6773 | J12: สมยศ นาคอุไร | K12: 081-248-5959
A13: 10 | B13: พนมสารคาม | C13: 1010690 | D13: 963084 | E13: 584519 | F13: 60429 | G13: =D13-E13-F13 -> 318136 | H13: =(G13/D13)*100 -> 33.033048
A14: 11 | B14: ระยอง | C14: 2026720 | D14: 2008252 | E14: 1643946.1 | F14: 42682 | G14: =D14-E14-F14 -> 321623.89 | H14: =(G14/D14)*100 -> 16.015116
A15: 12 | B15: บ้านฉาง | C15: 3293240 | D15: 3590000 | E15: 2426134 | F15: 146303 | G15: =D15-E15-F15 -> 1017563 | H15: =(G15/D15)*100 -> 28.344373
A16: 13 | B16: ปากน้ำประแสร์ | C16: 1159933 | D16: 931434 | E16: 497042 | F16: 6952 | G16: =D16-E16-F16 -> 427440 | H16: =(G16/D16)*100 -> 45.89053 | J16: จตุพร | K16: 096-669-5536
A17: 14 | B17: จันทบุรี | C17: 2060540 | D17: 2041277 | E17: 1326264 | F17: 44468 | G17: =D17-E17-F17 -> 670545 | H17: =(G17/D17)*100 -> 32.84929 | J17: ไพรชยนต์ ไชยลิ้นฟ้า | K17: 091-4685354
A18: 15 | B18: ขลุง | C18: 607277.71 | D18: 563578 | E18: 287675 | F18: 27276.98 | G18: =D18-E18-F18 -> 248626.02 | H18: =(G18/D18)*100 -> 44.115636 | J18: กัญญารัตน์ ศรีอุดม
A19: 16 | B19: ตราด | C19: 1581094.9 | D19: 1224990.9 | E19: 549009 | F19: 8960 | G19: =D19-E19-F19 -> 667021.92 | H19: =(G19/D19)*100 -> 54.451173 | J19: สุทธิพงศ์ นิลเพ็ชร | K19: 970059909
A20: 17 | B20: คลองใหญ่ | C20: 158120.64 | D20: 147273 | E20: 79136 | F20: 10000 | G20: =D20-E20-F20 -> 58137 | H20: =(G20/D20)*100 -> 39.475668
A21: 18 | B21: สระแก้ว | C21: 600154.74 | D21: 515919.57 | E21: 312823 | F21: 18027 | G21: =D21-E21-F21 -> 185069.57 | H21: =(G21/D21)*100 -> 35.871787
A22: 19 | B22: วัฒนานคร | C22: 190225 | D22: 149825 | E22: 117209 | F22: 4658.46 | G22: =D22-E22-F22 -> 27957.54 | H22: =(G22/D22)*100 -> 18.66013
A23: 20 | B23: อรัญประเทศ | C23: 690684 | D23: 644902 | E23: 420495 | F23: 8023 | G23: =D23-E23-F23 -> 216384 | H23: =(G23/D23)*100 -> 33.553005
A24: 21 | B24: ปราจีนบุรี | C24: 1738204 | D24: 1628956 | E24: 821788 | F24: 14425 | G24: =D24-E24-F24 -> 792743 | H24: =(G24/D24)*100 -> 48.66571
A25: 22 | B25: กบินทร์บุรี | C25: 575632 | D25: 521977 | E25: 318943 | F25: 30000 | G25: =D25-E25-F25 -> 173034 | H25: =(G25/D25)*100 -> 33.149736 | J25: ภาณุพัฒน์ ศรีวงษา | K25: 095-8574448
A26: รวม กปภ.ข.1 | C26: =SUM(C4:C25) -> 42579027 | D26: =SUM(D4:D25) -> 41058510 | E26: =SUM(E4:E25) -> 28831661 | F26: =SUM(F4:F25) -> 1200216.3 | G26: =SUM(G4:G25) -> 11026632 | H26: =(G26/D26)*100 -> 26.855899

Sheet พ.ค.68
A1: ข้อมูลน้ำสูญเสียตัวจริงที่ใช้ในการบริหารของ กปภ.เขต 1 เดือนพฤษภาคม 2568
A2: ลำดับ | B2: กปภ.สาขา | C2: น้ำผลิตรวมจริง | D2: น้ำผลิตจ่ายสุทธิจริง | E2: น้ำจำหน่ายจริง | F2: น้ำ Blow off จริง | G2: น้ำสูญเสียจริง | I2: หมายเหตุ | J2: ผู้ลงข้อมูล | K2: เบอร์ติดต่อ
C3: (ลบ.ม.) | D3: (ลบ.ม.) | E3: (ลบ.ม.) | F3: (ลบ.ม.) | G3: ปริมาณ (ลบ.ม.) | H3: อัตรา (%)
A4: 1 | B4: ชลบุรี (พ) | C4: 3941475 | D4: 5115484.5 | E4: 3823274 | F4: 97276.57 | G4: =D4-E4-F4 -> 1194933.9 | H4: =(G4/D4)*100 -> 23.359155
A5: 2 | B5: พัทยา (พ) | C5: 7011624 | D5: 6450076 | E5: 4530155 | F5: 250000 | G5: 1504290.9 | H5: =(G5/D5)*100 -> 23.322064
A6: 3 | B6: บ้านบึง | C6: 3008457 | D6: 1904575 | E6: 1351630 | F6: 55650.44 | G6: =D6-E6-F6 -> 497294.56 | H6: =(G6/D6)*100 -> 26.110526
A7: 4 | B7: พนัสนิคม | C7: 2558707 | D7: 2378205 | E7: 1714895 | F7: 69186 | G7: =D7-E7-F7 -> 594124 | H7: =(G7/D7)*100 -> 24.982035 | J7: บริพัฒน์ คมดี | K7: 092-501-3245
A8: 5 | B8: ศรีราชา | C8: 2535287 | D8: 2593694.5 | E8: 1604959 | F8: 168950 | G8: =D8-E8-F8 -> 819785.55 | H8: =(G8/D8)*100 -> 31.606866 | J8: จิราพัชร | K8: 064-3963619
A9: 6 | B9: แหลมฉบัง | C9: 2925952 | D9: 2819219 | E9: 1992240 | F9: 82934 | G9: =D9-E9-F9 -> 744045 | H9: =(G9/D9)*100 -> 26.391884 | J9: ธนกฤต เล็กตระกูลชัย | K9: 083-767-4284
A10: 7 | B10: ฉะเชิงเทรา | C10: 1145498 | D10: 1138316 | E10: 908056 | F10: 49544.55 | G10: =D10-E10-F10 -> 180715.45 | H10: =(G10/D10)*100 -> 15.875684 | J10: ธนชนัญ สิทธิเวช | K10: 0.83014173
A11: 8 | B11: บางปะกง | C11: 1368173.4 | D11: 1314722.5 | E11: 1177163 | F11: 31897 | G11: =D11-E11-F11 -> 105662.46 | H11: =(G11/D11)*100 -> 8.0368643 | J11: จีรพงศ์ พึ่งเกษม | K11: 085-1156645
A12: 9 | B12: บางคล้า | C12: 3079490.1 | D12: 2838284.1 | E12: 1811627 | F12: 185000 | G12: =D12-E12-F12 -> 841657.1 | H12: =(G12/D12)*100 -> 29.65373 | J12: สมยศ นาคอุไร | K12: 081-248-5959
A13: 10 | B13: พนมสารคาม | C13: 1031150.2 | D13: 929413 | E13: 584519 | F13: 53259.3 | G13: =D13-E13-F13 -> 291634.7 | H13: =(G13/D13)*100 -> 31.378375
A14: 11 | B14: ระยอง | C14: 2083066 | D14: 2063772 | E14: 1643946.1 | F14: 68298 | G14: =D14-E14-F14 -> 351527.89 | H14: =(G14/D14)*100 -> 17.033272
A15: 12 | B15: บ้านฉาง | C15: 2475314 | D15: 3480939 | E15: 2425092 | F15: 106636 | G15: =D15-E15-F15 -> 949211 | H15: =(G15/D15)*100 -> 27.26882
A16: 13 | B16: ปากน้ำประแสร์ | C16: 1225957 | D16: 938396 | E16: 497035 | F16: 7184 | G16: =D16-E16-F16 -> 434177 | H16: =(G16/D16)*100 -> 46.267993 | J16: จตุพร | K16: 096-669-5536
A17: 14 | B17: จันทบุรี | C17: 2158963 | D17: 2072035 | E17: 1392006 | F17: 47467 | G17: =D17-E17-F17 -> 632562 | H17: =(G17/D17)*100 -> 30.528538 | J17: ไพรชยนต์ ไชยลิ้นฟ้า | K17: 091-4685354
A18: 15 | B18: ขลุง | C18: 616152.98 | D18: 591855 | E18: 287675 | F18: 10090.72 | G18: =D18-E18-F18 -> 294089.28 | H18: =(G18/D18)*100 -> 49.689414 | J18: กัญญารัตน์ ศรีอุดม | K18: 092-6658041
A19: 16 | B19: ตราด | C19: 1639736 | D19: 1276355 | E19: 548898 | F19: 3943 | G19: =D19-E19-F19 -> 723514 | H19: =(G19/D19)*100 -> 56.685953 | J19: สุทธิพงศ์ นิลเพ็ชร | K19: 097-005-9909
A20: 17 | B20: คลองใหญ่ | C20: 171730.56 | D20: 150788 | E20: 79136 | F20: 10000 | G20: =D20-E20-F20 -> 61652 | H20: =(G20/D20)*100 -> 40.886543
A21: 18 | B21: สระแก้ว | C21: 607545 | D21: 605722.54 | E21: 312823 | F21: 18027 | G21: =D21-E21-F21 -> 274872.54 | H21: =(G21/D21)*100 -> 45.379282 | J21: ฉัตรชัย จันทร์สงค์ | K21: 992470958
A22: 19 | B22: วัฒนานคร | C22: 182557 | D22: 155609 | E22: 115570 | F22: 5639.04 | G22: =D22-E22-F22 -> 34399.96 | H22: =(G22/D22)*100 -> 22.106665 | J22: พัฒนพณ นรสิงห์ | K22: 064-240-7555
A23: 20 | B23: อรัญประเทศ | C23: 722289 | D23: 682238 | E23: 427660 | F23: 23567 | G23: =D23-E23-F23 -> 231011 | H23: =(G23/D23)*100 -> 33.860764
A24: 21 | B24: ปราจีนบุรี | C24: 1735217 | D24: 1625680 | E24: 821008 | F24: 20378 | G24: =D24-E24-F24 -> 784294 | H24: =(G24/D24)*100 -> 48.244058
A25: 22 | B25: กบินทร์บุรี | C25: 602333 | D25: 547370 | E25: 318943 | F25: 55000 | G25: =D25-E25-F25 -> 173427 | H25: =(G25/D25)*100 -> 31.683687 | J25: ภาณุพัฒน์ ศรีวงษา | K25: 095-8574448
A26: รวม กปภ.ข.1 | C26: =SUM(C4:C25) -> 42826674 | D26: =SUM(D4:D25) -> 41672749 | E26: =SUM(E4:E25) -> 28368310 | F26: =SUM(F4:F25) -> 1419927.6 | G26: =SUM(G4:G25) -> 11718881 | H26: =(G26/D26)*100 -> 28.12121

Sheet มิ.ย.68
A1: ข้อมูลน้ำสูญเสียตัวจริงที่ใช้ในการบริหารของ กปภ.เขต 1 เดือนมิถุนายน 2568
A2: ลำดับ | B2: กปภ.สาขา | C2: น้ำผลิตรวมจริง | D2: น้ำผลิตจ่ายสุทธิจริง | E2: น้ำจำหน่ายจริง | F2: น้ำ Blow off จริง | G2: น้ำสูญเสียจริง | I2: หมายเหตุ | J2: ผู้ลงข้อมูล | K2: เบอร์ติดต่อ
C3: (ลบ.ม.) | D3: (ลบ.ม.) | E3: (ลบ.ม.) | F3: (ลบ.ม.) | G3: ปริมาณ (ลบ.ม.) | H3: อัตรา (%)
A4: 1 | B4: ชลบุรี (พ) | C4: 3763318 | D4: 5143184 | E4: 3825304 | F4: 150764.36 | G4: =D4-E4-F4 -> 1167115.6 | H4: =(G4/D4)*100 -> 22.692473
A5: 2 | B5: พัทยา (พ) | C5: 6763272 | D5: 6621617.9 | E5: 4541689.7 | F5: 245998.67 | G5: =D5-E5-F5 -> 1833929.6 | H5: =(G5/D5)*100 -> 27.696094
A6: 3 | B6: บ้านบึง | C6: 2988356.9 | D6: 1840685 | E6: 1309841 | F6: 54571.81 | G6: =D6-E6-F6 -> 476272.19 | H6: =(G6/D6)*100 -> 25.874725
A7: 4 | B7: พนัสนิคม | C7: 2541344 | D7: 2246811 | E7: 1749968 | F7: 45060.68 | G7: =D7-E7-F7 -> 451782.32 | H7: =(G7/D7)*100 -> 20.107714 | J7: บริพัฒน์ คมดี | K7: 092-501-3245
A8: 5 | B8: ศรีราชา | C8: 2601744 | D8: 2547636.1 | E8: 1483777 | F8: 179860 | G8: =D8-E8-F8 -> 883999.09 | H8: =(G8/D8)*100 -> 34.698798
A9: 6 | B9: แหลมฉบัง | C9: 2870100 | D9: 2752528 | E9: 1986469 | F9: 81546 | G9: =D9-E9-F9 -> 684513 | H9: =(G9/D9)*100 -> 24.868521 | J9: ธนกฤต เล็กตระกูลชัย | K9: 083-767-4284
A10: 7 | B10: ฉะเชิงเทรา | C10: 1087149 | D10: 1079786 | E10: 887054 | F10: 45030 | G10: =D10-E10-F10 -> 147702 | H10: =(G10/D10)*100 -> 13.678822 | J10: ธนชนัญ สิทธิเวช | K10: 083-0141725
A11: 8 | B11: บางปะกง | C11: 1302125.2 | D11: 1302125.2 | E11: 1136215 | F11: 35740.34 | G11: =D11-E11-F11 -> 130169.84 | H11: =(G11/D11)*100 -> 9.9967224 | J11: จีรพงศ์ พึ่งเกษม | K11: 085-1156645
A12: 9 | B12: บางคล้า | C12: 3204921 | D12: 2938567 | E12: 1695628 | F12: 385000 | G12: =D12-E12-F12 -> 857939 | H12: =(G12/D12)*100 -> 29.195829 | J12: สมยศ นาคอุไร | K12: 081-248-5959
A13: 10 | B13: พนมสารคาม | C13: 1024912.7 | D13: 914463 | E13: 583159 | F13: 51228 | G13: =D13-E13-F13 -> 280076 | H13: =(G13/D13)*100 -> 30.627374 | J13: 111
A14: 11 | B14: ระยอง | C14: 2023121 | D14: 2004278 | E14: 1665602 | F14: 72246 | G14: =D14-E14-F14 -> 266430 | H14: =(G14/D14)*100 -> 13.293066 | J14: 111
A15: 12 | B15: บ้านฉาง | C15: 2212762 | D15: 3043813 | E15: 2389888 | F15: 106636 | G15: =D15-E15-F15 -> 547289 | H15: =(G15/D15)*100 -> 17.980375
A16: 13 | B16: ปากน้ำประแสร์ | C16: 1077934 | D16: 818337 | E16: 463869 | F16: 8725 | G16: =D16-E16-F16 -> 345743 | H16: =(G16/D16)*100 -> 42.249464 | J16: จตุพร | K16: 096-669-5536
A17: 14 | B17: จันทบุรี | C17: 2022788 | D17: 1972463 | E17: 1288326 | F17: 40957 | G17: =D17-E17-F17 -> 643180 | H17: =(G17/D17)*100 -> 32.607963 | J17: ไพรชยนต์ | K17: 091-4685354
A18: 15 | B18: ขลุง | C18: 565469.78 | D18: 507714 | E18: 285533 | F18: 6264.89 | G18: =D18-E18-F18 -> 215916.11 | H18: =(G18/D18)*100 -> 42.527114 | J18: กัญญารัตน์ ศรีอุดม | K18: 092-6658041
A19: 16 | B19: ตราด | C19: 1565742 | D19: 1232873 | E19: 548839 | F19: 2077 | G19: =D19-E19-F19 -> 681957 | H19: =(G19/D19)*100 -> 55.314457
A20: 17 | B20: คลองใหญ่ | C20: 164134.08 | D20: 142084 | E20: 74663 | F20: 10000 | G20: =D20-E20-F20 -> 57421 | H20: =(G20/D20)*100 -> 40.413417
A21: 18 | B21: สระแก้ว | C21: 573092.75 | D21: 496731.67 | E21: 312048 | F21: 18027 | G21: =D21-E21-F21 -> 166656.67 | H21: =(G21/D21)*100 -> 33.550643
A22: 19 | B22: วัฒนานคร | C22: 179903 | D22: 153966 | E22: 110046 | F22: 6918.83 | G22: =D22-E22-F22 -> 37001.17 | H22: =(G22/D22)*100 -> 24.03204 | J22: พัฒนพณ นรสิงห์ | K22: 06-42407555
A23: 20 | B23: อรัญประเทศ | C23: 677766 | D23: 619445 | E23: 377634 | F23: 23810 | G23: =D23-E23-F23 -> 218001 | H23: =(G23/D23)*100 -> 35.192955
A24: 21 | B24: ปราจีนบุรี | C24: 1753615 | D24: 1608460 | E24: 828043 | F24: 20404 | G24: =D24-E24-F24 -> 760013 | H24: =(G24/D24)*100 -> 47.250973
A25: 22 | B25: กบินทร์บุรี | C25: 566229 | D25: 501048 | E25: 313190 | F25: 40000 | G25: =D25-E25-F25 -> 147858 | H25: =(G25/D25)*100 -> 29.509748 | J25: ภาณุพัฒน์ ศรีวงษา | K25: 095-8574448
A26: รวม กปภ.ข.1 | C26: =SUM(C4:C25) -> 41529799 | D26: =SUM(D4:D25) -> 40488616 | E26: =SUM(E4:E25) -> 27856786 | F26: =SUM(F4:F25) -> 1630865.6 | G26: =SUM(G4:G25) -> 11000965 | H26: =(G26/D26)*100 -> 27.170513

Sheet ก.ค.68
A2: ลำดับ | B2: กปภ.สาขา | C2: น้ำผลิตรวมจริง | D2: น้ำผลิตจ่ายสุทธิจริง | E2: น้ำจำหน่ายจริง | F2: น้ำ Blow off จริง | G2: น้ำสูญเสียจริง | I2: หมายเหตุ | J2: ผู้ลงข้อมูล | K2: เบอร์ติดต่อ
C3: (ลบ.ม.) | D3: (ลบ.ม.) | E3: (ลบ.ม.) | F3: (ลบ.ม.) | G3: ปริมาณ (ลบ.ม.) | H3: อัตรา (%)
A4: 1 | B4: ชลบุรี (พ) | C4: 4041934.2 | D4: 5210352.4 | E4: 3928538 | F4: 139504.74 | G4: =D4-E4-F4 -> 1142309.6 | H4: =(G4/D4)*100 -> 21.923846
A5: 2 | B5: พัทยา (พ) | C5: 6470352 | D5: 6280879.2 | E5: 4498256 | F5: 296032.72 | G5: =D5-E5-F5 -> 1486590.5 | H5: =(G5/D5)*100 -> 23.66851
A6: 3 | B6: บ้านบึง | C6: 3046913.8 | D6: 1839637 | E6: 1347647 | F6: 60854.47 | G6: =D6-E6-F6 -> 431135.53 | H6: =(G6/D6)*100 -> 23.435902
A7: 4 | B7: พนัสนิคม | C7: 2620890 | D7: 2432032 | E7: 1694530 | F7: 82371.68 | G7: =D7-E7-F7 -> 655130.32 | H7: =(G7/D7)*100 -> 26.93757 | J7: บริพัฒน์ คมดี | K7: 092-501-3245
A8: 5 | B8: ศรีราชา | C8: 2758912 | D8: 2644943.4 | E8: 1535893 | F8: 179500 | G8: =D8-E8-F8 -> 929550.44 | H8: =(G8/D8)*100 -> 35.144435 | J8: จีิราพัชร ปั้นชู | K8: 064-3963619
A9: 6 | B9: แหลมฉบัง | C9: 2990551 | D9: 2757228 | E9: 1993465 | F9: 82565 | G9: =D9-E9-F9 -> 681198 | H9: =(G9/D9)*100 -> 24.7059 | J9: ธนกฤต เล็กตระกูลชัย | K9: 083-767-4284
A10: 7 | B10: ฉะเชิงเทรา | C10: 1072756 | D10: 1053096.9 | E10: 898869 | F10: 46900 | G10: =D10-E10-F10 -> 107327.91 | H10: =(G10/D10)*100 -> 10.191646 | J10: ธนชนัญ สิทธิเวช | K10: 083-014-1725
A11: 8 | B11: บางปะกง | C11: 1377391.4 | D11: 1337119.6 | E11: 1175957 | F11: 42873.25 | G11: =D11-E11-F11 -> 118289.39 | H11: =(G11/D11)*100 -> 8.8465823 | J11: จีรพงศ์ พึ่งเกษม | K11: 085-1156645
A12: 9 | B12: บางคล้า | C12: 3180792.6 | D12: 2927511.6 | E12: 1743164 | F12: 335800 | G12: =D12-E12-F12 -> 848547.62 | H12: =(G12/D12)*100 -> 28.985286 | J12: สมยศ นาคอุไร | K12: 081-248-5959
A13: 10 | B13: พนมสารคาม | C13: 1044787.4 | D13: 908502 | E13: 551826 | F13: 71583.12 | G13: =D13-E13-F13 -> 285092.88 | H13: =(G13/D13)*100 -> 31.380545
A14: 11 | B14: ระยอง | C14: 2096427 | D14: 2076378 | E14: 1650343 | F14: 84592 | G14: =D14-E14-F14 -> 341443 | H14: =(G14/D14)*100 -> 16.444164 | J14: นายวันเฉลิม เวียงนนท์ | K14: 081-369-8451
A15: 12 | B15: บ้านฉาง | C15: 2051079 | D15: 3057440 | E15: 2355590 | F15: 87092 | G15: =D15-E15-F15 -> 614758 | H15: =(G15/D15)*100 -> 20.106952
A16: 13 | B16: ปากน้ำประแสร์ | C16: 1081381 | D16: 894147 | E16: 433764 | F16: 9082 | G16: =D16-E16-F16 -> 451301 | H16: =(G16/D16)*100 -> 50.472797 | J16: จตุพร | K16: 096-669-5536
A17: 14 | B17: จันทบุรี | C17: 2116782 | D17: 1997420 | E17: 1287543 | F17: 49159 | G17: =D17-E17-F17 -> 660718 | H17: =(G17/D17)*100 -> 33.078571 | J17: ไพรชยนต์ | K17: 091-4685354
A18: 15 | B18: ขลุง | C18: 600809.43 | D18: 564838 | E18: 256731 | F18: 9610.86 | G18: =D18-E18-F18 -> 298496.14 | H18: =(G18/D18)*100 -> 52.846328 | J18: กัญญารัตน์ ศรีอุดม | K18: 092-6658041
A19: 16 | B19: ตราด | C19: 1629239 | D19: 1282268 | E19: 507339 | F19: 2041 | G19: =D19-E19-F19 -> 772888 | H19: =(G19/D19)*100 -> 60.275075 | K19: 970059909
A20: 17 | B20: คลองใหญ่ | C20: 150597.12 | D20: 139232 | E20: 63156 | F20: 10000 | G20: =D20-E20-F20 -> 66076 | H20: =(G20/D20)*100 -> 47.457481
A21: 18 | B21: สระแก้ว | C21: 586124.05 | D21: 517082.77 | E21: 298875 | F21: 18027 | G21: =D21-E21-F21 -> 200180.77 | H21: =(G21/D21)*100 -> 38.713487 | J21: นายฉัตรชัย จันทร์สงค์ | K21: 992470958
A22: 19 | B22: วัฒนานคร | C22: 192057 | D22: 164384 | E22: 110126 | F22: 7613 | G22: =D22-E22-F22 -> 46645 | H22: =(G22/D22)*100 -> 28.375633 | J22: พัฒนพณ นรสิงห์ | K22: 064-2407555
A23: 20 | B23: อรัญประเทศ | C23: 623007 | D23: 567853 | E23: 355626 | F23: 23645 | G23: =D23-E23-F23 -> 188582 | H23: =(G23/D23)*100 -> 33.209651
A24: 21 | B24: ปราจีนบุรี | C24: 1638272 | D24: 1526823 | E24: 789086 | F24: 23573 | G24: =D24-E24-F24 -> 714164 | H24: =(G24/D24)*100 -> 46.774512
A25: 22 | B25: กบินทร์บุรี | C25: 605952 | D25: 536242 | E25: 298432 | F25: 65000 | G25: =D25-E25-F25 -> 172810 | H25: =(G25/D25)*100 -> 32.226122 | J25: ภาณุพัฒน์ ศรีวงษา | K25: 095-8574448
A26: รวม กปภ.ข.1 | C26: =SUM(C4:C25) -> 41977007 | D26: =SUM(D4:D25) -> 40715410 | E26: =SUM(E4:E25) -> 27774756 | F26: =SUM(F4:F25) -> 1727419.8 | G26: =SUM(G4:G25) -> 11213234 | H26: =(G26/D26)*100 -> 27.540516

Sheet ส.ค.68
A2: ลำดับ | B2: กปภ.สาขา | C2: น้ำผลิตรวมจริง | D2: น้ำผลิตจ่ายสุทธิจริง | E2: น้ำจำหน่ายจริง | F2: น้ำ Blow off จริง | G2: น้ำสูญเสียจริง | I2: หมายเหตุ | J2: ผู้ลงข้อมูล | K2: เบอร์ติดต่อ
C3: (ลบ.ม.) | D3: (ลบ.ม.) | E3: (ลบ.ม.) | F3: (ลบ.ม.) | G3: ปริมาณ (ลบ.ม.) | H3: อัตรา (%)
A4: 1 | B4: ชลบุรี (พ) | C4: 4162051 | D4: 5095360.5 | E4: 3878670 | F4: 70212.06 | G4: =D4-E4-F4 -> 1146478.4 | H4: =(G4/D4)*100 -> 22.500438 | J4: อุดมพร ปะระคะ | K4: 098-9095654
A5: 2 | B5: พัทยา (พ) | C5: 6501965.4 | D5: 6273883.8 | E5: 4792447.1 | F5: 340609.52 | G5: =D5-E5-F5 -> 1140827.2 | H5: =(G5/D5)*100 -> 18.183747
A6: 3 | B6: บ้านบึง | C6: 2900264.8 | D6: 1872040 | E6: 1348280 | F6: 56494.86 | G6: =D6-E6-F6 -> 467265.14 | H6: =(G6/D6)*100 -> 24.960211
A7: 4 | B7: พนัสนิคม | C7: 2620773 | D7: 2450645 | E7: 1790520 | F7: 65521.68 | G7: =D7-E7-F7 -> 594603.32 | H7: =(G7/D7)*100 -> 24.263136 | J7: บริพัฒน์ คมดี | K7: 092-501-3245
A8: 5 | B8: ศรีราชา | C8: 2765974 | D8: 2772873 | E8: 1621862 | F8: 185600 | G8: =D8-E8-F8 -> 965411 | H8: =(G8/D8)*100 -> 34.816272 | J8: จิราพัชร ปั้นชู | K8: 064-3963619
A9: 6 | B9: แหลมฉบัง | C9: 2859062 | D9: 2805867 | E9: 2111272 | F9: 79774 | G9: =D9-E9-F9 -> 614821 | H9: =(G9/D9)*100 -> 21.911979 | J9: ธนกฤต เล็กตระกูลชัย | K9: 083-767-4284
A10: 7 | B10: ฉะเชิงเทรา | C10: 1057794 | D10: 1049773 | E10: 909749 | F10: 49034.69 | G10: =D10-E10-F10 -> 90989.31 | H10: =(G10/D10)*100 -> 8.6675224 | J10: ธนชนัญ สิทธิเวช | K10: 083-014-1725
A11: 8 | B11: บางปะกง | C11: 1408545.4 | D11: 1372319.9 | E11: 1167183 | F11: 43977.53 | G11: 16115 | H11: =(G11/D11)*100 -> 1.1742889 | J11: จีรพงศ์ พึ่งเกษม | K11: 085-1156645
A12: 9 | B12: บางคล้า | C12: 2989787 | D12: 2732752 | E12: 1751447 | F12: 244250 | G12: =D12-E12-F12 -> 737055 | H12: =(G12/D12)*100 -> 26.971163 | J12: สมยศ นาคอุไร | K12: 081-248-5959
A13: 10 | B13: พนมสารคาม | C13: 1011505 | D13: 874062 | E13: 565280 | F13: 45532 | G13: =D13-E13-F13 -> 263250 | H13: =(G13/D13)*100 -> 30.118001
A14: 11 | B14: ระยอง | C14: 2098319 | D14: 2065735 | E14: 1696787 | F14: 96058 | G14: =D14-E14-F14 -> 272890 | H14: =(G14/D14)*100 -> 13.21031 | J14: นายวันเฉลิม เวียงนนท์ | K14: 081-369-8451
A15: 12 | B15: บ้านฉาง | C15: 3377627 | D15: 3285479 | E15: 2448155 | F15: 111426 | G15: =D15-E15-F15 -> 725898 | H15: =(G15/D15)*100 -> 22.09413
A16: 13 | B16: ปากน้ำประแสร์ | C16: 1073178 | D16: 870596 | E16: 458117 | F16: 8916 | G16: =D16-E16-F16 -> 403563 | H16: =(G16/D16)*100 -> 46.354796 | J16: จตุพร เปี่ยมพงศ์สานต์
A17: 14 | B17: จันทบุรี | C17: 2180694 | D17: 2028303 | E17: 1272035 | F17: 51054 | G17: =D17-E17-F17 -> 705214 | H17: =(G17/D17)*100 -> 34.768671 | J17: ไพรชยนต์ ไชยลิ้นฟ้า | K17: 091-4685354
A18: 15 | B18: ขลุง | C18: 599861.2 | D18: 571182 | E18: 254028 | F18: 13921.18 | G18: =D18-E18-F18 -> 303232.82 | H18: =(G18/D18)*100 -> 53.088651 | J18: กัญญารัตน์ | K18: 092-6658041
A19: 16 | B19: ตราด | C19: 1636449 | D19: 1282080 | E19: 519853 | F19: 1640 | G19: =D19-E19-F19 -> 760587 | H19: =(G19/D19)*100 -> 59.324457
A20: 17 | B20: คลองใหญ่ | C20: 153013.44 | D20: 139219 | E20: 64404 | F20: 10000 | G20: =D20-E20-F20 -> 64815 | H20: =(G20/D20)*100 -> 46.556145
A21: 18 | B21: สระแก้ว | C21: 623409.78 | D21: 533620.24 | E21: 314031 | F21: 30800 | G21: =D21-E21-F21 -> 188789.24 | H21: =(G21/D21)*100 -> 35.37895 | J21: ฉัตรชัย | K21: 992470958
A22: 19 | B22: วัฒนานคร | C22: 185547 | D22: 156595 | E22: 109903 | F22: 7473.51 | G22: =D22-E22-F22 -> 39218.49 | H22: =(G22/D22)*100 -> 25.044535 | J22: อภิรัติ เครืออนันต์ | K22: 082-2077831
A23: 20 | B23: อรัญประเทศ | C23: 627955 | D23: 565754 | E23: 360887 | F23: 23452 | G23: =D23-E23-F23 -> 181415 | H23: =(G23/D23)*100 -> 32.066057
A24: 21 | B24: ปราจีนบุรี | C24: 1709251 | D24: 1624815 | E24: 808279 | F24: 27150 | G24: =D24-E24-F24 -> 789386 | H24: =(G24/D24)*100 -> 48.583131
A25: 22 | B25: กบินทร์บุรี | C25: 620866 | D25: 545268 | E25: 319476 | F25: 60000 | G25: =D25-E25-F25 -> 165792 | H25: =(G25/D25)*100 -> 30.405599 | J25: ภาณุพัฒน์ ศรีวงษา | K25: 095-8574448
A26: รวม กปภ.ข.1 | C26: =SUM(C4:C25) -> 43163892 | D26: =SUM(D4:D25) -> 40968222 | E26: =SUM(E4:E25) -> 28562665 | F26: =SUM(F4:F25) -> 1622897 | G26: =SUM(G4:G25) -> 10637616 | H26: =(G26/D26)*100 -> 25.96553

Sheet ก.ย.68
A1: ลำดับ | B1: กปภ.สาขา
C2: น้ำผลิตรวมจริง | D2: น้ำผลิตจ่ายสุทธิจริง | E2: น้ำจำหน่ายจริง | F2: น้ำ Blow off จริง | G2: น้ำสูญเสียจริง | J2: ผู้ลงข้อมูล | K2: เบอร์ติดต่อ
C3: (ลบ.ม.) | D3: (ลบ.ม.) | E3: (ลบ.ม.) | F3: (ลบ.ม.) | G3: ปริมาณ (ลบ.ม.) | H3: อัตรา (%)
A4: 1 | B4: ชลบุรี (พ) | C4: 4099855 | D4: 4974159 | E4: 3878670 | F4: 57217.88 | G4: =D4-E4-F4 -> 1038271.1 | H4: =(G4/D4)*100 -> 20.8733 | J4: อุดมพร ปะระคะ | K4: 098-9095654 | L4: ='ต.ค.67'!D4+'พ.ย.67'!D4+'ธ.ค.67'!D4+'ม.ค.68'!D4+'ก.พ.68'!D4+'มี.ค.68'!D4+'เม.ย.68'!D4+'พ.ค.68'!D4+'มิ.ย.68'!D4+'ก.ค.68'!D4+'ส.ค.68'!D4+D4 -> 61400999 | M4: ='ต.ค.67'!G4+'พ.ย.67'!G4+'ธ.ค.67'!G4+'ม.ค.68'!G4+'ก.พ.68'!G4+'มี.ค.68'!G4+'เม.ย.68'!G4+'พ.ค.68'!G4+'มิ.ย.68'!G4+'ก.ค.68'!G4+'ส.ค.68'!G4+G4 -> 13251410 | N4: =(M4/L4)*100 -> 21.58175
A5: 2 | B5: พัทยา (พ) | C5: 6653559 | D5: 6028186 | E5: 4782625 | F5: 148428.13 | G5: =D5-E5-F5 -> 1097132.9 | H5: =(G5/D5)*100 -> 18.20005 | J5: ยศภัทร อยู่สอน | K5: 084-5315332 | L5: ='ต.ค.67'!D5+'พ.ย.67'!D5+'ธ.ค.67'!D5+'ม.ค.68'!D5+'ก.พ.68'!D5+'มี.ค.68'!D5+'เม.ย.68'!D5+'พ.ค.68'!D5+'มิ.ย.68'!D5+'ก.ค.68'!D5+'ส.ค.68'!D5+D5 -> 76403005 | M5: ='ต.ค.67'!G5+'พ.ย.67'!G5+'ธ.ค.67'!G5+'ม.ค.68'!G5+'ก.พ.68'!G5+'มี.ค.68'!G5+'เม.ย.68'!G5+'พ.ค.68'!G5+'มิ.ย.68'!G5+'ก.ค.68'!G5+'ส.ค.68'!G5+G5 -> 16958133 | N5: =(M5/L5)*100 -> 22.195636
A6: 3 | B6: บ้านบึง | C6: 2676674 | D6: 1823662 | E6: 1275625 | F6: 58676.56 | G6: =D6-E6-F6 -> 489360.44 | H6: =(G6/D6)*100 -> 26.833944 | L6: ='ต.ค.67'!D6+'พ.ย.67'!D6+'ธ.ค.67'!D6+'ม.ค.68'!D6+'ก.พ.68'!D6+'มี.ค.68'!D6+'เม.ย.68'!D6+'พ.ค.68'!D6+'มิ.ย.68'!D6+'ก.ค.68'!D6+'ส.ค.68'!D6+D6 -> 21635487 | M6: ='ต.ค.67'!G6+'พ.ย.67'!G6+'ธ.ค.67'!G6+'ม.ค.68'!G6+'ก.พ.68'!G6+'มี.ค.68'!G6+'เม.ย.68'!G6+'พ.ค.68'!G6+'มิ.ย.68'!G6+'ก.ค.68'!G6+'ส.ค.68'!G6+G6 -> 5409626.5 | N6: =(M6/L6)*100 -> 25.003489
A7: 4 | B7: พนัสนิคม | C7: 2521963 | D7: 2273798 | E7: 1786333 | F7: 26422.68 | G7: =D7-E7-F7 -> 461042.32 | H7: =(G7/D7)*100 -> 20.27631 | J7: บริพัฒน์ คมดี | K7: 092-501-3245 | L7: ='ต.ค.67'!D7+'พ.ย.67'!D7+'ธ.ค.67'!D7+'ม.ค.68'!D7+'ก.พ.68'!D7+'มี.ค.68'!D7+'เม.ย.68'!D7+'พ.ค.68'!D7+'มิ.ย.68'!D7+'ก.ค.68'!D7+'ส.ค.68'!D7+D7 -> 27082236 | M7: ='ต.ค.67'!G7+'พ.ย.67'!G7+'ธ.ค.67'!G7+'ม.ค.68'!G7+'ก.พ.68'!G7+'มี.ค.68'!G7+'เม.ย.68'!G7+'พ.ค.68'!G7+'มิ.ย.68'!G7+'ก.ค.68'!G7+'ส.ค.68'!G7+G7 -> 5956079.1 | N7: =(M7/L7)*100 -> 21.992568
A8: 5 | B8: ศรีราชา | C8: 2495139 | D8: 2489932.1 | E8: 1589503 | F8: 145800 | G8: =D8-E8-F8 -> 754629.07 | H8: =(G8/D8)*100 -> 30.307215 | L8: ='ต.ค.67'!D8+'พ.ย.67'!D8+'ธ.ค.67'!D8+'ม.ค.68'!D8+'ก.พ.68'!D8+'มี.ค.68'!D8+'เม.ย.68'!D8+'พ.ค.68'!D8+'มิ.ย.68'!D8+'ก.ค.68'!D8+'ส.ค.68'!D8+D8 -> 29919804 | M8: ='ต.ค.67'!G8+'พ.ย.67'!G8+'ธ.ค.67'!G8+'ม.ค.68'!G8+'ก.พ.68'!G8+'มี.ค.68'!G8+'เม.ย.68'!G8+'พ.ค.68'!G8+'มิ.ย.68'!G8+'ก.ค.68'!G8+'ส.ค.68'!G8+G8 -> 9009653.9 | N8: =(M8/L8)*100 -> 30.112677
A9: 6 | B9: แหลมฉบัง | C9: 2796725 | D9: 2787725 | E9: 2079856 | F9: 81231 | G9: =D9-E9-F9 -> 626638 | H9: =(G9/D9)*100 -> 22.478473 | J9: ธนกฤต เล็กตระกูลชัย | K9: 083-767-4284 | L9: ='ต.ค.67'!D9+'พ.ย.67'!D9+'ธ.ค.67'!D9+'ม.ค.68'!D9+'ก.พ.68'!D9+'มี.ค.68'!D9+'เม.ย.68'!D9+'พ.ค.68'!D9+'มิ.ย.68'!D9+'ก.ค.68'!D9+'ส.ค.68'!D9+D9 -> 31974378 | M9: ='ต.ค.67'!G9+'พ.ย.67'!G9+'ธ.ค.67'!G9+'ม.ค.68'!G9+'ก.พ.68'!G9+'มี.ค.68'!G9+'เม.ย.68'!G9+'พ.ค.68'!G9+'มิ.ย.68'!G9+'ก.ค.68'!G9+'ส.ค.68'!G9+G9 -> 6985582.4 | N9: =(M9/L9)*100 -> 21.847438
A10: 7 | B10: ฉะเชิงเทรา | C10: 1002662.3 | D10: 993499 | E10: 856019 | F10: 46516.81 | G10: =D10-E10-F10 -> 90963.19 | H10: =(G10/D10)*100 -> 9.1558411 | J10: ธนชนัญ สิทธิเวช | K10: 083-014-1725 | L10: ='ต.ค.67'!D10+'พ.ย.67'!D10+'ธ.ค.67'!D10+'ม.ค.68'!D10+'ก.พ.68'!D10+'มี.ค.68'!D10+'เม.ย.68'!D10+'พ.ค.68'!D10+'มิ.ย.68'!D10+'ก.ค.68'!D10+'ส.ค.68'!D10+D10 -> 12854519 | M10: ='ต.ค.67'!G10+'พ.ย.67'!G10+'ธ.ค.67'!G10+'ม.ค.68'!G10+'ก.พ.68'!G10+'มี.ค.68'!G10+'เม.ย.68'!G10+'พ.ค.68'!G10+'มิ.ย.68'!G10+'ก.ค.68'!G10+'ส.ค.68'!G10+G10 -> 1682759.3 | N10: =(M10/L10)*100 -> 13.0908
A11: 8 | B11: บางปะกง | C11: 1344421.2 | D11: 1296595.5 | E11: 1155904 | F11: 44638.29 | G11: =D11-E11-F11 -> 96053.21 | H11: =(G11/D11)*100 -> 7.4081092 | J11: ปัทมา สาริกาแก้ว | K11: 08-6975-3781 | L11: ='ต.ค.67'!D11+'พ.ย.67'!D11+'ธ.ค.67'!D11+'ม.ค.68'!D11+'ก.พ.68'!D11+'มี.ค.68'!D11+'เม.ย.68'!D11+'พ.ค.68'!D11+'มิ.ย.68'!D11+'ก.ค.68'!D11+'ส.ค.68'!D11+D11 -> 15755563 | M11: ='ต.ค.67'!G11+'พ.ย.67'!G11+'ธ.ค.67'!G11+'ม.ค.68'!G11+'ก.พ.68'!G11+'มี.ค.68'!G11+'เม.ย.68'!G11+'พ.ค.68'!G11+'มิ.ย.68'!G11+'ก.ค.68'!G11+'ส.ค.68'!G11+G11 -> 1369375.2 | N11: =(M11/L11)*100 -> 8.6913758
A12: 9 | B12: บางคล้า | C12: 2840544 | D12: 2573214 | E12: 1752101 | F12: 233250 | G12: =D12-E12-F12 -> 587863 | H12: =(G12/D12)*100 -> 22.845477 | J12: สมยศ นาคอุไร | K12: 081-248-5959 | L12: ='ต.ค.67'!D12+'พ.ย.67'!D12+'ธ.ค.67'!D12+'ม.ค.68'!D12+'ก.พ.68'!D12+'มี.ค.68'!D12+'เม.ย.68'!D12+'พ.ค.68'!D12+'มิ.ย.68'!D12+'ก.ค.68'!D12+'ส.ค.68'!D12+D12 -> 31528997 | M12: ='ต.ค.67'!G12+'พ.ย.67'!G12+'ธ.ค.67'!G12+'ม.ค.68'!G12+'ก.พ.68'!G12+'มี.ค.68'!G12+'เม.ย.68'!G12+'พ.ค.68'!G12+'มิ.ย.68'!G12+'ก.ค.68'!G12+'ส.ค.68'!G12+G12 -> 8600025.1 | N12: =(M12/L12)*100 -> 27.276558
A13: 10 | B13: พนมสารคาม | C13: 855996.58 | D13: 773365 | E13: 547414 | F13: 5908 | G13: =D13-E13-F13 -> 220043 | H13: =(G13/D13)*100 -> 28.452671 | L13: ='ต.ค.67'!D13+'พ.ย.67'!D13+'ธ.ค.67'!D13+'ม.ค.68'!D13+'ก.พ.68'!D13+'มี.ค.68'!D13+'เม.ย.68'!D13+'พ.ค.68'!D13+'มิ.ย.68'!D13+'ก.ค.68'!D13+'ส.ค.68'!D13+D13 -> 10535431 | M13: ='ต.ค.67'!G13+'พ.ย.67'!G13+'ธ.ค.67'!G13+'ม.ค.68'!G13+'ก.พ.68'!G13+'มี.ค.68'!G13+'เม.ย.68'!G13+'พ.ค.68'!G13+'มิ.ย.68'!G13+'ก.ค.68'!G13+'ส.ค.68'!G13+G13 -> 3287725.6 | N13: =(M13/L13)*100 -> 31.20637
A14: 11 | B14: ระยอง | C14: 2005561 | D14: 1957885 | E14: 1659979 | F14: 81406 | G14: =D14-E14-F14 -> 216500 | H14: =(G14/D14)*100 -> 11.057851 | J14: นายวันเฉลิม เวียงนนท์ | K14: 081-369-8451 | L14: ='ต.ค.67'!D14+'พ.ย.67'!D14+'ธ.ค.67'!D14+'ม.ค.68'!D14+'ก.พ.68'!D14+'มี.ค.68'!D14+'เม.ย.68'!D14+'พ.ค.68'!D14+'มิ.ย.68'!D14+'ก.ค.68'!D14+'ส.ค.68'!D14+D14 -> 24284106 | M14: ='ต.ค.67'!G14+'พ.ย.67'!G14+'ธ.ค.67'!G14+'ม.ค.68'!G14+'ก.พ.68'!G14+'มี.ค.68'!G14+'เม.ย.68'!G14+'พ.ค.68'!G14+'มิ.ย.68'!G14+'ก.ค.68'!G14+'ส.ค.68'!G14+G14 -> 3372110.9 | N14: =(M14/L14)*100 -> 13.886082
A15: 12 | B15: บ้านฉาง | C15: 3598117 | D15: 3329687 | E15: 2410991 | F15: 114047 | G15: =D15-E15-F15 -> 804649 | H15: =(G15/D15)*100 -> 24.165905 | L15: ='ต.ค.67'!D15+'พ.ย.67'!D15+'ธ.ค.67'!D15+'ม.ค.68'!D15+'ก.พ.68'!D15+'มี.ค.68'!D15+'เม.ย.68'!D15+'พ.ค.68'!D15+'มิ.ย.68'!D15+'ก.ค.68'!D15+'ส.ค.68'!D15+D15 -> 41423759 | M15: ='ต.ค.67'!G15+'พ.ย.67'!G15+'ธ.ค.67'!G15+'ม.ค.68'!G15+'ก.พ.68'!G15+'มี.ค.68'!G15+'เม.ย.68'!G15+'พ.ค.68'!G15+'มิ.ย.68'!G15+'ก.ค.68'!G15+'ส.ค.68'!G15+G15 -> 11418097 | N15: =(M15/L15)*100 -> 27.564126 | S15: .
A16: 13 | B16: ปากน้ำประแสร์ | C16: 1047252 | D16: 824454 | E16: 443554 | F16: 9124 | G16: =D16-E16-F16 -> 371776 | H16: =(G16/D16)*100 -> 45.093601 | J16: จตุพร เปี่ยมพงศ์สานต์ | L16: ='ต.ค.67'!D16+'พ.ย.67'!D16+'ธ.ค.67'!D16+'ม.ค.68'!D16+'ก.พ.68'!D16+'มี.ค.68'!D16+'เม.ย.68'!D16+'พ.ค.68'!D16+'มิ.ย.68'!D16+'ก.ค.68'!D16+'ส.ค.68'!D16+D16 -> 10803416 | M16: ='ต.ค.67'!G16+'พ.ย.67'!G16+'ธ.ค.67'!G16+'ม.ค.68'!G16+'ก.พ.68'!G16+'มี.ค.68'!G16+'เม.ย.68'!G16+'พ.ค.68'!G16+'มิ.ย.68'!G16+'ก.ค.68'!G16+'ส.ค.68'!G16+G16 -> 5109425 | N16: =(M16/L16)*100 -> 47.294532
A17: 14 | B17: จันทบุรี | C17: 2177802 | D17: 1953689 | E17: 1220348 | F17: 47214 | G17: =D17-E17-F17 -> 686127 | H17: =(G17/D17)*100 -> 35.119561 | J17: ไพรชยนต์ ไชยลิ้นฟ้า | K17: 091-4685354 | L17: ='ต.ค.67'!D17+'พ.ย.67'!D17+'ธ.ค.67'!D17+'ม.ค.68'!D17+'ก.พ.68'!D17+'มี.ค.68'!D17+'เม.ย.68'!D17+'พ.ค.68'!D17+'มิ.ย.68'!D17+'ก.ค.68'!D17+'ส.ค.68'!D17+D17 -> 23869587 | M17: ='ต.ค.67'!G17+'พ.ย.67'!G17+'ธ.ค.67'!G17+'ม.ค.68'!G17+'ก.พ.68'!G17+'มี.ค.68'!G17+'เม.ย.68'!G17+'พ.ค.68'!G17+'มิ.ย.68'!G17+'ก.ค.68'!G17+'ส.ค.68'!G17+G17 -> 7581367 | N17: =(M17/L17)*100 -> 31.761618
A18: 15 | B18: ขลุง | C18: 580675.68 | D18: 559476 | E18: 245542 | F18: 3967.41 | G18: =D18-E18-F18 -> 309966.59 | H18: =(G18/D18)*100 -> 55.403018 | J18: กัญญารัตน์ ศรีอุดม | K18: 092-6658041 | L18: ='ต.ค.67'!D18+'พ.ย.67'!D18+'ธ.ค.67'!D18+'ม.ค.68'!D18+'ก.พ.68'!D18+'มี.ค.68'!D18+'เม.ย.68'!D18+'พ.ค.68'!D18+'มิ.ย.68'!D18+'ก.ค.68'!D18+'ส.ค.68'!D18+D18 -> 6471887 | M18: ='ต.ค.67'!G18+'พ.ย.67'!G18+'ธ.ค.67'!G18+'ม.ค.68'!G18+'ก.พ.68'!G18+'มี.ค.68'!G18+'เม.ย.68'!G18+'พ.ค.68'!G18+'มิ.ย.68'!G18+'ก.ค.68'!G18+'ส.ค.68'!G18+G18 -> 3166792.3 | N18: =(M18/L18)*100 -> 48.931515
A19: 16 | B19: ตราด | C19: 1560951 | D19: 1211355 | E19: 508034 | F19: 703 | G19: =D19-E19-F19 -> 702618 | H19: =(G19/D19)*100 -> 58.00265 | L19: ='ต.ค.67'!D19+'พ.ย.67'!D19+'ธ.ค.67'!D19+'ม.ค.68'!D19+'ก.พ.68'!D19+'มี.ค.68'!D19+'เม.ย.68'!D19+'พ.ค.68'!D19+'มิ.ย.68'!D19+'ก.ค.68'!D19+'ส.ค.68'!D19+D19 -> 16244772 | M19: ='ต.ค.67'!G19+'พ.ย.67'!G19+'ธ.ค.67'!G19+'ม.ค.68'!G19+'ก.พ.68'!G19+'มี.ค.68'!G19+'เม.ย.68'!G19+'พ.ค.68'!G19+'มิ.ย.68'!G19+'ก.ค.68'!G19+'ส.ค.68'!G19+G19 -> 9591867.1 | N19: =(M19/L19)*100 -> 59.045871
A20: 17 | B20: คลองใหญ่ | C20: 158267.52 | D20: 137841 | E20: 63168 | F20: 10000 | G20: =D20-E20-F20 -> 64673 | H20: =(G20/D20)*100 -> 46.918551 | L20: ='ต.ค.67'!D20+'พ.ย.67'!D20+'ธ.ค.67'!D20+'ม.ค.68'!D20+'ก.พ.68'!D20+'มี.ค.68'!D20+'เม.ย.68'!D20+'พ.ค.68'!D20+'มิ.ย.68'!D20+'ก.ค.68'!D20+'ส.ค.68'!D20+D20 -> 1732978 | M20: ='ต.ค.67'!G20+'พ.ย.67'!G20+'ธ.ค.67'!G20+'ม.ค.68'!G20+'ก.พ.68'!G20+'มี.ค.68'!G20+'เม.ย.68'!G20+'พ.ค.68'!G20+'มิ.ย.68'!G20+'ก.ค.68'!G20+'ส.ค.68'!G20+G20 -> 733163 | N20: =(M20/L20)*100 -> 42.306538
A21: 18 | B21: สระแก้ว | C21: 625420.58 | D21: 529461.3 | E21: 307885 | F21: 33300 | G21: =D21-E21-F21 -> 188276.3 | H21: =(G21/D21)*100 -> 35.559974 | L21: ='ต.ค.67'!D21+'พ.ย.67'!D21+'ธ.ค.67'!D21+'ม.ค.68'!D21+'ก.พ.68'!D21+'มี.ค.68'!D21+'เม.ย.68'!D21+'พ.ค.68'!D21+'มิ.ย.68'!D21+'ก.ค.68'!D21+'ส.ค.68'!D21+D21 -> 6417182 | M21: ='ต.ค.67'!G21+'พ.ย.67'!G21+'ธ.ค.67'!G21+'ม.ค.68'!G21+'ก.พ.68'!G21+'มี.ค.68'!G21+'เม.ย.68'!G21+'พ.ค.68'!G21+'มิ.ย.68'!G21+'ก.ค.68'!G21+'ส.ค.68'!G21+G21 -> 2437358 | N21: =(M21/L21)*100 -> 37.98175
A22: 19 | B22: วัฒนานคร | C22: 177102 | D22: 147567 | E22: 113719 | F22: 5141.89 | G22: =D22-E22-F22 -> 28706.11 | H22: =(G22/D22)*100 -> 19.452933 | J22: อภิรัติ เครืออนันต์ | K22: 082-2077831 | L22: ='ต.ค.67'!D22+'พ.ย.67'!D22+'ธ.ค.67'!D22+'ม.ค.68'!D22+'ก.พ.68'!D22+'มี.ค.68'!D22+'เม.ย.68'!D22+'พ.ค.68'!D22+'มิ.ย.68'!D22+'ก.ค.68'!D22+'ส.ค.68'!D22+D22 -> 1821485 | M22: ='ต.ค.67'!G22+'พ.ย.67'!G22+'ธ.ค.67'!G22+'ม.ค.68'!G22+'ก.พ.68'!G22+'มี.ค.68'!G22+'เม.ย.68'!G22+'พ.ค.68'!G22+'มิ.ย.68'!G22+'ก.ค.68'!G22+'ส.ค.68'!G22+G22 -> 381436.27 | N22: =(M22/L22)*100 -> 20.94095
A23: 20 | B23: อรัญประเทศ | C23: 613674 | D23: 581983 | E23: 347733 | F23: 23662 | G23: =D23-E23-F23 -> 210588 | H23: =(G23/D23)*100 -> 36.184562 | L23: ='ต.ค.67'!D23+'พ.ย.67'!D23+'ธ.ค.67'!D23+'ม.ค.68'!D23+'ก.พ.68'!D23+'มี.ค.68'!D23+'เม.ย.68'!D23+'พ.ค.68'!D23+'มิ.ย.68'!D23+'ก.ค.68'!D23+'ส.ค.68'!D23+D23 -> 7319562 | M23: ='ต.ค.67'!G23+'พ.ย.67'!G23+'ธ.ค.67'!G23+'ม.ค.68'!G23+'ก.พ.68'!G23+'มี.ค.68'!G23+'เม.ย.68'!G23+'พ.ค.68'!G23+'มิ.ย.68'!G23+'ก.ค.68'!G23+'ส.ค.68'!G23+G23 -> 2372089 | N23: =(M23/L23)*100 -> 32.407527
A24: 21 | B24: ปราจีนบุรี | C24: 1670011 | D24: 1594572 | E24: 796225 | F24: 22055 | G24: =D24-E24-F24 -> 776292 | H24: =(G24/D24)*100 -> 48.683408 | L24: ='ต.ค.67'!D24+'พ.ย.67'!D24+'ธ.ค.67'!D24+'ม.ค.68'!D24+'ก.พ.68'!D24+'มี.ค.68'!D24+'เม.ย.68'!D24+'พ.ค.68'!D24+'มิ.ย.68'!D24+'ก.ค.68'!D24+'ส.ค.68'!D24+D24 -> 18954093 | M24: ='ต.ค.67'!G24+'พ.ย.67'!G24+'ธ.ค.67'!G24+'ม.ค.68'!G24+'ก.พ.68'!G24+'มี.ค.68'!G24+'เม.ย.68'!G24+'พ.ค.68'!G24+'มิ.ย.68'!G24+'ก.ค.68'!G24+'ส.ค.68'!G24+G24 -> 8842890.6 | N24: =(M24/L24)*100 -> 46.654253
A25: 22 | B25: กบินทร์บุรี | C25: 561717 | D25: 531730 | E25: 310409 | F25: 65000 | G25: =D25-E25-F25 -> 156321 | H25: =(G25/D25)*100 -> 29.398567 | J25: ภาณุพัฒน์ ศรีวงษา | K25: 095-8574448 | L25: ='ต.ค.67'!D25+'พ.ย.67'!D25+'ธ.ค.67'!D25+'ม.ค.68'!D25+'ก.พ.68'!D25+'มี.ค.68'!D25+'เม.ย.68'!D25+'พ.ค.68'!D25+'มิ.ย.68'!D25+'ก.ค.68'!D25+'ส.ค.68'!D25+D25 -> 6273005 | M25: ='ต.ค.67'!G25+'พ.ย.67'!G25+'ธ.ค.67'!G25+'ม.ค.68'!G25+'ก.พ.68'!G25+'มี.ค.68'!G25+'เม.ย.68'!G25+'พ.ค.68'!G25+'มิ.ย.68'!G25+'ก.ค.68'!G25+'ส.ค.68'!G25+G25 -> 2027649 | N25: =(M25/L25)*100 -> 32.323408
A26: รวม กปภ.ข.1 | C26: =SUM(C4:C25) -> 42064090 | D26: =SUM(D4:D25) -> 39373836 | E26: =SUM(E4:E25) -> 28131637 | F26: =SUM(F4:F25) -> 1263709.6 | G26: =SUM(G4:G25) -> 9978489.2 | H26: =(G26/D26)*100 -> 25.342944 | L26: ='ต.ค.67'!D26+'พ.ย.67'!D26+'ธ.ค.67'!D26+'ม.ค.68'!D26+'ก.พ.68'!D26+'มี.ค.68'!D26+'เม.ย.68'!D26+'พ.ค.68'!D26+'มิ.ย.68'!D26+'ก.ค.68'!D26+'ส.ค.68'!D26+D26 -> 484706251 | M26: ='ต.ค.67'!G26+'พ.ย.67'!G26+'ธ.ค.67'!G26+'ม.ค.68'!G26+'ก.พ.68'!G26+'มี.ค.68'!G26+'เม.ย.68'!G26+'พ.ค.68'!G26+'มิ.ย.68'!G26+'ก.ค.68'!G26+'ส.ค.68'!G26+G26 -> 1.2954462e+08 | N26: =(M26/L26)*100 -> 26.726417
G27: ='ต.ค.67'!G26+'พ.ย.67'!G26+'ธ.ค.67'!G26+'ม.ค.68'!G26+'ก.พ.68'!G26+'มี.ค.68'!G26+'เม.ย.68'!G26+'พ.ค.68'!G26+'มิ.ย.68'!G26+'ก.ค.68'!G26+'ส.ค.68'!G26+G26 -> 1.2954462e+08

Sheet ต.ค.68
A1: ลำดับ | B1: กปภ.สาขา
C2: น้ำผลิตรวมจริง | D2: น้ำผลิตจ่ายสุทธิจริง | E2: น้ำจำหน่ายจริง | F2: น้ำ Blow off จริง | G2: น้ำสูญเสียจริง | J2: ผู้ลงข้อมูล | K2: เบอร์ติดต่อ
C3: (ลบ.ม.) | D3: (ลบ.ม.) | E3: (ลบ.ม.) | F3: (ลบ.ม.) | G3: ปริมาณ (ลบ.ม.) | H3: อัตรา (%)
A4: 1 | B4: ชลบุรี (พ) | C4: 4045731.2 | D4: 5047852 | E4: 3708284 | F4: 74669.87 | G4: =D4-E4-F4 -> 1264898.1 | H4: =(G4/D4)*100 -> 25.058146 | J4: อุดมพร ปะระคะ | K4: 098-9095654
A5: 2 | B5: พัทยา (พ) | G5: =D5-E5-F5 -> 0 | H5: =(G5/D5)*100 -> #DIV/0!
A6: 3 | B6: บ้านบึง | C6: 2868881 | D6: 1950897.5 | E6: 1334884 | F6: 63446.31 | G6: =D6-E6-F6 -> 552567.19 | H6: =(G6/D6)*100 -> 28.323743
A7: 4 | B7: พนัสนิคม | C7: 2654800 | D7: 2377215 | E7: 1701438 | F7: 66822 | G7: =D7-E7-F7 -> 608955 | H7: =(G7/D7)*100 -> 25.61632 | J7: บริพัฒน์ คมดี | K7: 092-501-3245
A8: 5 | B8: ศรีราชา | C8: 2382265 | D8: 2632872 | E8: 1488023 | F8: 210500 | G8: =D8-E8-F8 -> 934349.02 | H8: =(G8/D8)*100 -> 35.487825 | J8: จิราพัชร ปั้นชู | K8: 064-3963619
A9: 6 | B9: แหลมฉบัง | C9: 2962242 | D9: 2893286 | E9: 1971000 | F9: 60000 | G9: =D9-E9-F9 -> 862286 | H9: =(G9/D9)*100 -> 29.802999 | J9: ธนกฤต เล็กตระกูลชัย | K9: 083-767-4284
A10: 7 | B10: ฉะเชิงเทรา | C10: 1065114 | D10: 1039906 | E10: 870609 | F10: 46847 | G10: =D10-E10-F10 -> 122450 | H10: =(G10/D10)*100 -> 11.775103 | J10: ธนชนัญ สิทธิเวช | K10: 083-014-1725
A11: 8 | B11: บางปะกง | E11: 1128045 | F11: 42515.02 | G11: =D11-E11-F11 -> -1170560 | H11: =(G11/D11)*100 -> #DIV/0!
A12: 9 | B12: บางคล้า | C12: 3105426 | D12: 2824500 | E12: 1723018 | F12: 175950 | G12: =D12-E12-F12 -> 925532 | H12: =(G12/D12)*100 -> 32.767994 | J12: สมยศ นาคอุไร | K12: 081-248-5959
A13: 10 | B13: พนมสารคาม | C13: 986356.6 | D13: 790180 | E13: 525905 | F13: 27046 | G13: =D13-E13-F13 -> 237229 | H13: =(G13/D13)*100 -> 30.022147
A14: 11 | B14: ระยอง | C14: 2058303 | D14: 2038717 | E14: 1565127 | F14: 112636 | G14: =D14-E14-F14 -> 360954 | H14: =(G14/D14)*100 -> 17.704959 | J14: นายวันเฉลิม เวียงนนท์ | K14: 081-369-8451
A15: 12 | B15: บ้านฉาง | C15: 3344490 | D15: 3242974 | E15: 2262585 | F15: 131653 | G15: =D15-E15-F15 -> 848736 | H15: =(G15/D15)*100 -> 26.171533 | S15: .
A16: 13 | B16: ปากน้ำประแสร์ | C16: 1050797 | D16: 852449 | E16: 460127 | F16: 17876 | G16: =D16-E16-F16 -> 374446 | H16: =(G16/D16)*100 -> 43.925912 | J16: จตุพร เปี่ยมพงศ์สานต์
A17: 14 | B17: จันทบุรี | C17: 2284323 | D17: 2012679 | E17: 1281755 | F17: 55149 | G17: =D17-E17-F17 -> 675775 | H17: =(G17/D17)*100 -> 33.575896 | J17: ไพรชยนต์ ไชยลิ้นฟ้า | K17: 091-4685354
A18: 15 | B18: ขลุง | C18: 596361.89 | D18: 576657 | E18: 233970 | F18: 11400.69 | G18: =D18-E18-F18 -> 331286.31 | H18: =(G18/D18)*100 -> 57.449456 | J18: กัญญารัตน์ ศรีอุดม | K18: 092-665-8041
A19: 16 | B19: ตราด | C19: 1644981.9 | D19: 1279169 | E19: 489725 | F19: 1693 | G19: =D19-E19-F19 -> 787751 | H19: =(G19/D19)*100 -> 61.583028 | J19: สุทธิพงศ์ นิลเพ็ชร
A20: 17 | B20: คลองใหญ่ | C20: 164949.12 | D20: 160700 | E20: 70762 | F20: 10000 | G20: =D20-E20-F20 -> 79938 | H20: =(G20/D20)*100 -> 49.743622
A21: 18 | B21: สระแก้ว | C21: 663582.85 | D21: 586321.87 | E21: 299556 | F21: 35810 | G21: =D21-E21-F21 -> 250955.87 | H21: =(G21/D21)*100 -> 42.801724
A22: 19 | B22: วัฒนานคร | C22: 186039 | D22: 154079 | E22: 107984 | F22: 8090.15 | G22: =D22-E22-F22 -> 38004.85 | H22: =(G22/D22)*100 -> 24.665821 | J22: อภิรัติ เครืออนันต์ | K22: 082-207-7831
A23: 20 | B23: อรัญประเทศ | C23: 637274 | D23: 634818 | E23: 360337 | F23: 23554 | G23: =D23-E23-F23 -> 250927 | H23: =(G23/D23)*100 -> 39.527392 | J23: ณัฐวุฒิ อ่างเข็ม | K23: 090-9099277
A24: 21 | B24: ปราจีนบุรี | C24: 1726776 | D24: 1647287 | E24: 759325 | F24: 17150 | G24: =D24-E24-F24 -> 870812 | H24: =(G24/D24)*100 -> 52.863405 | J24: ธีทัต ลีอุดม | K24: 081-7232595
A25: 22 | B25: กบินทร์บุรี | C25: 569141 | D25: 543555 | E25: 293413 | F25: 62000 | G25: =D25-E25-F25 -> 188142 | H25: =(G25/D25)*100 -> 34.613241 | J25: ภาณุพัฒน์ ศรีวงษา | K25: 095-8574448
A26: รวม กปภ.ข.1 | C26: =SUM(C4:C25) -> 34997835 | D26: =SUM(D4:D25) -> 33286114 | E26: =SUM(E4:E25) -> 22635872 | F26: =SUM(F4:F25) -> 1254808 | G26: =SUM(G4:G25) -> 9395434.3 | H26: =(G26/D26)*100 -> 28.226288

Sheet พ.ย.68
A1: ลำดับ | B1: กปภ.สาขา
C2: น้ำผลิตรวมจริง | D2: น้ำผลิตจ่ายสุทธิจริง | E2: น้ำจำหน่ายจริง | F2: น้ำ Blow off จริง | G2: น้ำสูญเสียจริง | J2: ผู้ลงข้อมูล | K2: เบอร์ติดต่อ
C3: (ลบ.ม.) | D3: (ลบ.ม.) | E3: (ลบ.ม.) | F3: (ลบ.ม.) | G3: ปริมาณ (ลบ.ม.) | H3: อัตรา (%)
A4: 1 | B4: ชลบุรี (พ) | G4: =D4-E4-F4 -> 0 | H4: =(G4/D4)*100 -> #DIV/0!
A5: 2 | B5: พัทยา (พ) | G5: =D5-E5-F5 -> 0 | H5: =(G5/D5)*100 -> #DIV/0!
A6: 3 | B6: บ้านบึง | G6: =D6-E6-F6 -> 0 | H6: =(G6/D6)*100 -> #DIV/0!
A7: 4 | B7: พนัสนิคม | C7: 3069972 | D7: 2347776 | E7: 1772574 | F7: 33346.68 | G7: =D7-E7-F7 -> 541855.32 | H7: =(G7/D7)*100 -> 23.079515 | J7: บริพัฒน์ คมดี | K7: 092-501-3245
A8: 5 | B8: ศรีราชา | C8: 2443241 | D8: 2655240 | E8: 1542140 | F8: 185000 | G8: =D8-E8-F8 -> 928099.95 | H8: =(G8/D8)*100 -> 34.953525 | J8: จิราพัชร ปั้นชู | K8: 064-3963619
A9: 6 | B9: แหลมฉบัง | C9: 2952750 | D9: 2844557 | E9: 2079189 | F9: 62946 | G9: =D9-E9-F9 -> 702422 | H9: =(G9/D9)*100 -> 24.693546 | J9: ธนกฤต เล็กตระกูลชัย | K9: 083-767-4284
A10: 7 | B10: ฉะเชิงเทรา | C10: 1036078.3 | D10: 1008705 | E10: 856295 | F10: 47226.45 | G10: =D10-E10-F10 -> 105183.55 | H10: =(G10/D10)*100 -> 10.427583 | J10: สุทธิรักษ์ รอบคอบ | K10: 091-873-6353
A11: 8 | B11: บางปะกง | G11: =D11-E11-F11 -> 0 | H11: =(G11/D11)*100 -> #DIV/0!
A12: 9 | B12: บางคล้า | G12: =D12-E12-F12 -> 0 | H12: =(G12/D12)*100 -> #DIV/0!
A13: 10 | B13: พนมสารคาม | G13: =D13-E13-F13 -> 0 | H13: =(G13/D13)*100 -> #DIV/0!
A14: 11 | B14: ระยอง | G14: =D14-E14-F14 -> 0 | H14: =(G14/D14)*100 -> #DIV/0!
A15: 12 | B15: บ้านฉาง | C15: 3467137 | D15: 3397842 | E15: 2347266 | F15: 124508 | G15: =D15-E15-F15 -> 926068 | H15: =(G15/D15)*100 -> 27.254593 | S15: .
A16: 13 | B16: ปากน้ำประแสร์ | C16: 1096965 | D16: 838937 | E16: 458832 | F16: 16226 | G16: =D16-E16-F16 -> 363879 | H16: =(G16/D16)*100 -> 43.373817
A17: 14 | B17: จันทบุรี | G17: =D17-E17-F17 -> 0 | H17: =(G17/D17)*100 -> #DIV/0!
