Workbook

Sheet สรุป
A1: ลำดับ | B1: กปภ. สาขา | C1: รวมทั้งหมด | F1: ธ.ค.68 | I1: ม.ค.69 | L1: ก.พ.69 | O1: มี.ค.69 | R1: เม.ย.69 | U1: พ.ค.69 | X1: มิ.ย.69 | AA1: ก.ค.69 | AD1: ส.ค.69 | AG1: ก.ย.69 | AJ1: ต.ค.69 | AM1: พ.ย.69 | AP1: ธ.ค.69
C2: เชิงกายภาพ | D2: เชิงพาณิชย์ | E2: รวม | F2: เชิงกายภาพ | G2: เชิงพาณิชย์ | H2: รวม | I2: เชิงกายภาพ | J2: เชิงพาณิชย์ | K2: รวม | L2: เชิงกายภาพ | M2: เชิงพาณิชย์ | N2: รวม | O2: เชิงกายภาพ | P2: เชิงพาณิชย์ | Q2: รวม | R2: เชิงกายภาพ | S2: เชิงพาณิชย์ | T2: รวม | U2: เชิงกายภาพ | V2: เชิงพาณิชย์ | W2: รวม | X2: เชิงกายภาพ | Y2: เชิงพาณิชย์ | Z2: รวม | AA2: เชิงกายภาพ | AB2: เชิงพาณิชย์ | AC2: รวม | AD2: เชิงกายภาพ | AE2: เชิงพาณิชย์ | AF2: รวม | AG2: เชิงกายภาพ | AH2: เชิงพาณิชย์ | AI2: รวม | AJ2: เชิงกายภาพ | AK2: เชิงพาณิชย์ | AL2: รวม | AM2: เชิงกายภาพ | AN2: เชิงพาณิชย์ | AO2: รวม | AP2: เชิงกายภาพ | AQ2: เชิงพาณิชย์ | AR2: รวม
A3: 1 | B3: ชลบุรี(พิเศษ) | C3: =SUM(F3,I3,L3,O3,R3,U3,X3,AA3,AD3,AG3,AJ3,AM3,AP3) -> 41 | D3: =SUM(G3,J3,M3,P3,S3,V3,Y3,AB3,AE3,AH3,AK3,AN3,AQ3) -> 17 | E3: =C3+D3 -> 58 | F3: ='ธ.ค.68'!AJ37 -> 2 | G3: ='ธ.ค.68'!AK37 -> 1 | H3: ='ธ.ค.68'!AL37 -> 3 | I3: ='ม.ค.69'!AJ3 -> 16 | J3: ='ม.ค.69'!AK3 -> 5 | K3: ='ม.ค.69'!AL3 -> 21 | L3: ='ก.พ.69'!AG3 -> 12 | M3: ='ก.พ.69'!AH3 -> 5 | N3: ='ก.พ.69'!AI3 -> 17 | O3: ='มี.ค.69'!AJ3 -> 11 | P3: ='มี.ค.69'!AK3 -> 6 | Q3: ='มี.ค.69'!AL3 -> 17 | R3: ='เม.ย.69'!AI3 -> 0 | S3: ='เม.ย.69'!AJ3 -> 0 | T3: ='เม.ย.69'!AK3 -> 0 | U3: ='พ.ค.69'!AJ3 -> 0 | V3: ='พ.ค.69'!AK3 -> 0 | W3: ='พ.ค.69'!AL3 -> 0 | X3: ='มิ.ย.69'!AI3 -> 0 | Y3: ='มิ.ย.69'!AJ3 -> 0 | Z3: ='มิ.ย.69'!AK3 -> 0 | AA3: ='ก.ค.69'!AJ3 -> 0 | AB3: ='ก.ค.69'!AK3 -> 0 | AC3: ='ก.ค.69'!AL3 -> 0 | AD3: ='ส.ค.69'!AJ3 -> 0 | AE3: ='ส.ค.69'!AK3 -> 0 | AF3: ='ส.ค.69'!AL3 -> 0 | AG3: ='ก.ย.69'!AI3 -> 0 | AH3: ='ก.ย.69'!AJ3 -> 0 | AI3: ='ก.ย.69'!AK3 -> 0 | AJ3: ='ต.ค.69'!AJ3 -> 0 | AK3: ='ต.ค.69'!AK3 -> 0 | AL3: ='ต.ค.69'!AL3 -> 0 | AM3: ='พ.ย.69'!AI3 -> 0 | AN3: ='พ.ย.69'!AJ3 -> 0 | AO3: ='พ.ย.69'!AK3 -> 0 | AP3: ='ธ.ค.69'!AJ3 -> 0 | AQ3: ='ธ.ค.69'!AK3 -> 0 | AR3: ='ธ.ค.69'!AL3 -> 0
A5: 2 | B5: พัทยา(พิเศษ) | C5: =SUM(F5,I5,L5,O5,R5,U5,X5,AA5,AD5,AG5,AJ5,AM5,AP5) -> 13 | D5: =SUM(G5,J5,M5,P5,S5,V5,Y5,AB5,AE5,AH5,AK5,AN5,AQ5) -> 1 | E5: =C5+D5 -> 14 | F5: ='ธ.ค.68'!AJ41 -> 0 | G5: ='ธ.ค.68'!AK41 -> 0 | H5: ='ธ.ค.68'!AL41 -> 0 | I5: ='ม.ค.69'!AJ5 -> 1 | J5: ='ม.ค.69'!AK5 -> 0 | K5: ='ม.ค.69'!AL5 -> 1 | L5: ='ก.พ.69'!AG5 -> 6 | M5: ='ก.พ.69'!AH5 -> 0 | N5: ='ก.พ.69'!AI5 -> 6 | O5: ='มี.ค.69'!AJ5 -> 6 | P5: ='มี.ค.69'!AK5 -> 1 | Q5: ='มี.ค.69'!AL5 -> 7 | R5: ='เม.ย.69'!AI5 -> 0 | S5: ='เม.ย.69'!AJ5 -> 0 | T5: ='เม.ย.69'!AK5 -> 0 | U5: ='พ.ค.69'!AJ5 -> 0 | V5: ='พ.ค.69'!AK5 -> 0 | W5: ='พ.ค.69'!AL5 -> 0 | X5: ='มิ.ย.69'!AI5 -> 0 | Y5: ='มิ.ย.69'!AJ5 -> 0 | Z5: ='มิ.ย.69'!AK5 -> 0 | AA5: ='ก.ค.69'!AJ5 -> 0 | AB5: ='ก.ค.69'!AK5 -> 0 | AC5: ='ก.ค.69'!AL5 -> 0 | AD5: ='ส.ค.69'!AJ5 -> 0 | AE5: ='ส.ค.69'!AK5 -> 0 | AF5: ='ส.ค.69'!AL5 -> 0 | AG5: ='ก.ย.69'!AI5 -> 0 | AH5: ='ก.ย.69'!AJ5 -> 0 | AI5: ='ก.ย.69'!AK5 -> 0 | AJ5: ='ต.ค.69'!AJ5 -> 0 | AK5: ='ต.ค.69'!AK5 -> 0 | AL5: ='ต.ค.69'!AL5 -> 0 | AM5: ='พ.ย.69'!AI5 -> 0 | AN5: ='พ.ย.69'!AJ5 -> 0 | AO5: ='พ.ย.69'!AK5 -> 0 | AP5: ='ธ.ค.69'!AJ5 -> 0 | AQ5: ='ธ.ค.69'!AK5 -> 0 | AR5: ='ธ.ค.69'!AL5 -> 0
A7: 3 | B7: บ้านบึง | C7: =SUM(F7,I7,L7,O7,R7,U7,X7,AA7,AD7,AG7,AJ7,AM7,AP7) -> 7 | D7: =SUM(G7,J7,M7,P7,S7,V7,Y7,AB7,AE7,AH7,AK7,AN7,AQ7) -> 0 | E7: =C7+D7 -> 7 | F7: ='ธ.ค.68'!AJ7 -> 3 | G7: ='ธ.ค.68'!AK7 -> 0 | H7: ='ธ.ค.68'!AL7 -> 3 | I7: ='ม.ค.69'!AJ7 -> 1 | J7: ='ม.ค.69'!AK7 -> 0 | K7: ='ม.ค.69'!AL7 -> 1 | L7: ='ก.พ.69'!AG7 -> 2 | M7: ='ก.พ.69'!AH7 -> 0 | N7: ='ก.พ.69'!AI7 -> 2 | O7: ='มี.ค.69'!AJ7 -> 1 | P7: ='มี.ค.69'!AK7 -> 0 | Q7: ='มี.ค.69'!AL7 -> 1 | R7: ='เม.ย.69'!AI7 -> 0 | S7: ='เม.ย.69'!AJ7 -> 0 | T7: ='เม.ย.69'!AK7 -> 0 | U7: ='พ.ค.69'!AJ7 -> 0 | V7: ='พ.ค.69'!AK7 -> 0 | W7: ='พ.ค.69'!AL7 -> 0 | X7: ='มิ.ย.69'!AI7 -> 0 | Y7: ='มิ.ย.69'!AJ7 -> 0 | Z7: ='มิ.ย.69'!AK7 -> 0 | AA7: ='ก.ค.69'!AJ7 -> 0 | AB7: ='ก.ค.69'!AK7 -> 0 | AC7: ='ก.ค.69'!AL7 -> 0 | AD7: ='ส.ค.69'!AJ7 -> 0 | AE7: ='ส.ค.69'!AK7 -> 0 | AF7: ='ส.ค.69'!AL7 -> 0 | AG7: ='ก.ย.69'!AI7 -> 0 | AH7: ='ก.ย.69'!AJ7 -> 0 | AI7: ='ก.ย.69'!AK7 -> 0 | AJ7: ='ต.ค.69'!AJ7 -> 0 | AK7: ='ต.ค.69'!AK7 -> 0 | AL7: ='ต.ค.69'!AL7 -> 0 | AM7: ='พ.ย.69'!AI7 -> 0 | AN7: ='พ.ย.69'!AJ7 -> 0 | AO7: ='พ.ย.69'!AK7 -> 0 | AP7: ='ธ.ค.69'!AJ7 -> 0 | AQ7: ='ธ.ค.69'!AK7 -> 0 | AR7: ='ธ.ค.69'!AL7 -> 0
A9: 4 | B9: พนัสนิคม | C9: =SUM(F9,I9,L9,O9,R9,U9,X9,AA9,AD9,AG9,AJ9,AM9,AP9) -> 10 | D9: =SUM(G9,J9,M9,P9,S9,V9,Y9,AB9,AE9,AH9,AK9,AN9,AQ9) -> 2 | E9: =C9+D9 -> 12 | F9: ='ธ.ค.68'!AJ31 -> 1 | G9: ='ธ.ค.68'!AK31 -> 0 | H9: ='ธ.ค.68'!AL31 -> 1 | I9: ='ม.ค.69'!AJ9 -> 5 | J9: ='ม.ค.69'!AK9 -> 2 | K9: ='ม.ค.69'!AL9 -> 7 | L9: ='ก.พ.69'!AG9 -> 3 | M9: ='ก.พ.69'!AH9 -> 0 | N9: ='ก.พ.69'!AI9 -> 3 | O9: ='มี.ค.69'!AJ9 -> 1 | P9: ='มี.ค.69'!AK9 -> 0 | Q9: ='มี.ค.69'!AL9 -> 1 | R9: ='เม.ย.69'!AI9 -> 0 | S9: ='เม.ย.69'!AJ9 -> 0 | T9: ='เม.ย.69'!AK9 -> 0 | U9: ='พ.ค.69'!AJ9 -> 0 | V9: ='พ.ค.69'!AK9 -> 0 | W9: ='พ.ค.69'!AL9 -> 0 | X9: ='มิ.ย.69'!AI9 -> 0 | Y9: ='มิ.ย.69'!AJ9 -> 0 | Z9: ='มิ.ย.69'!AK9 -> 0 | AA9: ='ก.ค.69'!AJ9 -> 0 | AB9: ='ก.ค.69'!AK9 -> 0 | AC9: ='ก.ค.69'!AL9 -> 0 | AD9: ='ส.ค.69'!AJ9 -> 0 | AE9: ='ส.ค.69'!AK9 -> 0 | AF9: ='ส.ค.69'!AL9 -> 0 | AG9: ='ก.ย.69'!AI9 -> 0 | AH9: ='ก.ย.69'!AJ9 -> 0 | AI9: ='ก.ย.69'!AK9 -> 0 | AJ9: ='ต.ค.69'!AJ9 -> 0 | AK9: ='ต.ค.69'!AK9 -> 0 | AL9: ='ต.ค.69'!AL9 -> 0 | AM9: ='พ.ย.69'!AI9 -> 0 | AN9: ='พ.ย.69'!AJ9 -> 0 | AO9: ='พ.ย.69'!AK9 -> 0 | AP9: ='ธ.ค.69'!AJ9 -> 0 | AQ9: ='ธ.ค.69'!AK9 -> 0 | AR9: ='ธ.ค.69'!AL9 -> 0
A11: 5 | B11: ศรีราชา | C11: =SUM(F11,I11,L11,O11,R11,U11,X11,AA11,AD11,AG11,AJ11,AM11,AP11) -> 7 | D11: =SUM(G11,J11,M11,P11,S11,V11,Y11,AB11,AE11,AH11,AK11,AN11,AQ11) -> 0 | E11: =C11+D11 -> 7 | F11: ='ธ.ค.68'!AJ27 -> 1 | G11: ='ธ.ค.68'!AK27 -> 0 | H11: ='ธ.ค.68'!AL27 -> 1 | I11: ='ม.ค.69'!AJ11 -> 1 | J11: ='ม.ค.69'!AK11 -> 0 | K11: ='ม.ค.69'!AL11 -> 1 | L11: ='ก.พ.69'!AG11 -> 2 | M11: ='ก.พ.69'!AH11 -> 0 | N11: ='ก.พ.69'!AI11 -> 2 | O11: ='มี.ค.69'!AJ11 -> 3 | P11: ='มี.ค.69'!AK11 -> 0 | Q11: ='มี.ค.69'!AL11 -> 3 | R11: ='เม.ย.69'!AI11 -> 0 | S11: ='เม.ย.69'!AJ11 -> 0 | T11: ='เม.ย.69'!AK11 -> 0 | U11: ='พ.ค.69'!AJ11 -> 0 | V11: ='พ.ค.69'!AK11 -> 0 | W11: ='พ.ค.69'!AL11 -> 0 | X11: ='มิ.ย.69'!AI11 -> 0 | Y11: ='มิ.ย.69'!AJ11 -> 0 | Z11: ='มิ.ย.69'!AK11 -> 0 | AA11: ='ก.ค.69'!AJ11 -> 0 | AB11: ='ก.ค.69'!AK11 -> 0 | AC11: ='ก.ค.69'!AL11 -> 0 | AD11: ='ส.ค.69'!AJ11 -> 0 | AE11: ='ส.ค.69'!AK11 -> 0 | AF11: ='ส.ค.69'!AL11 -> 0 | AG11: ='ก.ย.69'!AI11 -> 0 | AH11: ='ก.ย.69'!AJ11 -> 0 | AI11: ='ก.ย.69'!AK11 -> 0 | AJ11: ='ต.ค.69'!AJ11 -> 0 | AK11: ='ต.ค.69'!AK11 -> 0 | AL11: ='ต.ค.69'!AL11 -> 0 | AM11: ='พ.ย.69'!AI11 -> 0 | AN11: ='พ.ย.69'!AJ11 -> 0 | AO11: ='พ.ย.69'!AK11 -> 0 | AP11: ='ธ.ค.69'!AJ11 -> 0 | AQ11: ='ธ.ค.69'!AK11 -> 0 | AR11: ='ธ.ค.69'!AL11 -> 0
A13: 6 | B13: แหลมฉบัง | C13: =SUM(F13,I13,L13,O13,R13,U13,X13,AA13,AD13,AG13,AJ13,AM13,AP13) -> 12 | D13: =SUM(G13,J13,M13,P13,S13,V13,Y13,AB13,AE13,AH13,AK13,AN13,AQ13) -> 3 | E13: =C13+D13 -> 15 | F13: ='ธ.ค.68'!AJ25 -> 3 | G13: ='ธ.ค.68'!AK25 -> 0 | H13: ='ธ.ค.68'!AL25 -> 3 | I13: ='ม.ค.69'!AJ13 -> 1 | J13: ='ม.ค.69'!AK13 -> 0 | K13: ='ม.ค.69'!AL13 -> 1 | L13: ='ก.พ.69'!AG13 -> 7 | M13: ='ก.พ.69'!AH13 -> 2 | N13: ='ก.พ.69'!AI13 -> 9 | O13: ='มี.ค.69'!AJ13 -> 1 | P13: ='มี.ค.69'!AK13 -> 1 | Q13: ='มี.ค.69'!AL13 -> 2 | R13: ='เม.ย.69'!AI13 -> 0 | S13: ='เม.ย.69'!AJ13 -> 0 | T13: ='เม.ย.69'!AK13 -> 0 | U13: ='พ.ค.69'!AJ13 -> 0 | V13: ='พ.ค.69'!AK13 -> 0 | W13: ='พ.ค.69'!AL13 -> 0 | X13: ='มิ.ย.69'!AI13 -> 0 | Y13: ='มิ.ย.69'!AJ13 -> 0 | Z13: ='มิ.ย.69'!AK13 -> 0 | AA13: ='ก.ค.69'!AJ13 -> 0 | AB13: ='ก.ค.69'!AK13 -> 0 | AC13: ='ก.ค.69'!AL13 -> 0 | AD13: ='ส.ค.69'!AJ13 -> 0 | AE13: ='ส.ค.69'!AK13 -> 0 | AF13: ='ส.ค.69'!AL13 -> 0 | AG13: ='ก.ย.69'!AI13 -> 0 | AH13: ='ก.ย.69'!AJ13 -> 0 | AI13: ='ก.ย.69'!AK13 -> 0 | AJ13: ='ต.ค.69'!AJ13 -> 0 | AK13: ='ต.ค.69'!AK13 -> 0 | AL13: ='ต.ค.69'!AL13 -> 0 | AM13: ='พ.ย.69'!AI13 -> 0 | AN13: ='พ.ย.69'!AJ13 -> 0 | AO13: ='พ.ย.69'!AK13 -> 0 | AP13: ='ธ.ค.69'!AJ13 -> 0 | AQ13: ='ธ.ค.69'!AK13 -> 0 | AR13: ='ธ.ค.69'!AL13 -> 0
A15: 7 | B15: ฉะเชิงเทรา | C15: =SUM(F15,I15,L15,O15,R15,U15,X15,AA15,AD15,AG15,AJ15,AM15,AP15) -> 7 | D15: =SUM(G15,J15,M15,P15,S15,V15,Y15,AB15,AE15,AH15,AK15,AN15,AQ15) -> 1 | E15: =C15+D15 -> 8 | F15: ='ธ.ค.68'!AJ39 -> 1 | G15: ='ธ.ค.68'!AK39 -> 0 | H15: ='ธ.ค.68'!AL39 -> 1 | I15: ='ม.ค.69'!AJ15 -> 1 | J15: ='ม.ค.69'!AK15 -> 0 | K15: ='ม.ค.69'!AL15 -> 1 | L15: ='ก.พ.69'!AG15 -> 4 | M15: ='ก.พ.69'!AH15 -> 0 | N15: ='ก.พ.69'!AI15 -> 4 | O15: ='มี.ค.69'!AJ15 -> 1 | P15: ='มี.ค.69'!AK15 -> 1 | Q15: ='มี.ค.69'!AL15 -> 2 | R15: ='เม.ย.69'!AI15 -> 0 | S15: ='เม.ย.69'!AJ15 -> 0 | T15: ='เม.ย.69'!AK15 -> 0 | U15: ='พ.ค.69'!AJ15 -> 0 | V15: ='พ.ค.69'!AK15 -> 0 | W15: ='พ.ค.69'!AL15 -> 0 | X15: ='มิ.ย.69'!AI15 -> 0 | Y15: ='มิ.ย.69'!AJ15 -> 0 | Z15: ='มิ.ย.69'!AK15 -> 0 | AA15: ='ก.ค.69'!AJ15 -> 0 | AB15: ='ก.ค.69'!AK15 -> 0 | AC15: ='ก.ค.69'!AL15 -> 0 | AD15: ='ส.ค.69'!AJ15 -> 0 | AE15: ='ส.ค.69'!AK15 -> 0 | AF15: ='ส.ค.69'!AL15 -> 0 | AG15: ='ก.ย.69'!AI15 -> 0 | AH15: ='ก.ย.69'!AJ15 -> 0 | AI15: ='ก.ย.69'!AK15 -> 0 | AJ15: ='ต.ค.69'!AJ15 -> 0 | AK15: ='ต.ค.69'!AK15 -> 0 | AL15: ='ต.ค.69'!AL15 -> 0 | AM15: ='พ.ย.69'!AI15 -> 0 | AN15: ='พ.ย.69'!AJ15 -> 0 | AO15: ='พ.ย.69'!AK15 -> 0 | AP15: ='ธ.ค.69'!AJ15 -> 0 | AQ15: ='ธ.ค.69'!AK15 -> 0 | AR15: ='ธ.ค.69'!AL15 -> 0
A17: 8 | B17: บางปะกง | C17: =SUM(F17,I17,L17,O17,R17,U17,X17,AA17,AD17,AG17,AJ17,AM17,AP17) -> 10 | D17: =SUM(G17,J17,M17,P17,S17,V17,Y17,AB17,AE17,AH17,AK17,AN17,AQ17) -> 2 | E17: =C17+D17 -> 12 | F17: ='ธ.ค.68'!AJ21 -> 3 | G17: ='ธ.ค.68'!AK21 -> 2 | H17: ='ธ.ค.68'!AL21 -> 5 | I17: ='ม.ค.69'!AJ17 -> 3 | J17: ='ม.ค.69'!AK17 -> 0 | K17: ='ม.ค.69'!AL17 -> 3 | L17: ='ก.พ.69'!AG17 -> 2 | M17: ='ก.พ.69'!AH17 -> 0 | N17: ='ก.พ.69'!AI17 -> 2 | O17: ='มี.ค.69'!AJ17 -> 2 | P17: ='มี.ค.69'!AK17 -> 0 | Q17: ='มี.ค.69'!AL17 -> 2 | R17: ='เม.ย.69'!AI17 -> 0 | S17: ='เม.ย.69'!AJ17 -> 0 | T17: ='เม.ย.69'!AK17 -> 0 | U17: ='พ.ค.69'!AJ17 -> 0 | V17: ='พ.ค.69'!AK17 -> 0 | W17: ='พ.ค.69'!AL17 -> 0 | X17: ='มิ.ย.69'!AI17 -> 0 | Y17: ='มิ.ย.69'!AJ17 -> 0 | Z17: ='มิ.ย.69'!AK17 -> 0 | AA17: ='ก.ค.69'!AJ17 -> 0 | AB17: ='ก.ค.69'!AK17 -> 0 | AC17: ='ก.ค.69'!AL17 -> 0 | AD17: ='ส.ค.69'!AJ17 -> 0 | AE17: ='ส.ค.69'!AK17 -> 0 | AF17: ='ส.ค.69'!AL17 -> 0 | AG17: ='ก.ย.69'!AI17 -> 0 | AH17: ='ก.ย.69'!AJ17 -> 0 | AI17: ='ก.ย.69'!AK17 -> 0 | AJ17: ='ต.ค.69'!AJ17 -> 0 | AK17: ='ต.ค.69'!AK17 -> 0 | AL17: ='ต.ค.69'!AL17 -> 0 | AM17: ='พ.ย.69'!AI17 -> 0 | AN17: ='พ.ย.69'!AJ17 -> 0 | AO17: ='พ.ย.69'!AK17 -> 0 | AP17: ='ธ.ค.69'!AJ17 -> 0 | AQ17: ='ธ.ค.69'!AK17 -> 0 | AR17: ='ธ.ค.69'!AL17 -> 0
A19: 9 | B19: บางคล้า | C19: =SUM(F19,I19,L19,O19,R19,U19,X19,AA19,AD19,AG19,AJ19,AM19,AP19) -> 9 | D19: =SUM(G19,J19,M19,P19,S19,V19,Y19,AB19,AE19,AH19,AK19,AN19,AQ19) -> 0 | E19: =C19+D19 -> 9 | F19: ='ธ.ค.68'!AJ9 -> 3 | G19: ='ธ.ค.68'!AK9 -> 0 | H19: ='ธ.ค.68'!AL9 -> 3 | I19: ='ม.ค.69'!AJ19 -> 3 | J19: ='ม.ค.69'!AK19 -> 0 | K19: ='ม.ค.69'!AL19 -> 3 | L19: ='ก.พ.69'!AG19 -> 1 | M19: ='ก.พ.69'!AH19 -> 0 | N19: ='ก.พ.69'!AI19 -> 1 | O19: ='มี.ค.69'!AJ19 -> 2 | P19: ='มี.ค.69'!AK19 -> 0 | Q19: ='มี.ค.69'!AL19 -> 2 | R19: ='เม.ย.69'!AI19 -> 0 | S19: ='เม.ย.69'!AJ19 -> 0 | T19: ='เม.ย.69'!AK19 -> 0 | U19: ='พ.ค.69'!AJ19 -> 0 | V19: ='พ.ค.69'!AK19 -> 0 | W19: ='พ.ค.69'!AL19 -> 0 | X19: ='มิ.ย.69'!AI19 -> 0 | Y19: ='มิ.ย.69'!AJ19 -> 0 | Z19: ='มิ.ย.69'!AK19 -> 0 | AA19: ='ก.ค.69'!AJ19 -> 0 | AB19: ='ก.ค.69'!AK19 -> 0 | AC19: ='ก.ค.69'!AL19 -> 0 | AD19: ='ส.ค.69'!AJ19 -> 0 | AE19: ='ส.ค.69'!AK19 -> 0 | AF19: ='ส.ค.69'!AL19 -> 0 | AG19: ='ก.ย.69'!AI19 -> 0 | AH19: ='ก.ย.69'!AJ19 -> 0 | AI19: ='ก.ย.69'!AK19 -> 0 | AJ19: ='ต.ค.69'!AJ19 -> 0 | AK19: ='ต.ค.69'!AK19 -> 0 | AL19: ='ต.ค.69'!AL19 -> 0 | AM19: ='พ.ย.69'!AI19 -> 0 | AN19: ='พ.ย.69'!AJ19 -> 0 | AO19: ='พ.ย.69'!AK19 -> 0 | AP19: ='ธ.ค.69'!AJ19 -> 0 | AQ19: ='ธ.ค.69'!AK19 -> 0 | AR19: ='ธ.ค.69'!AL19 -> 0
A21: 10 | B21: พนมสารคาม | C21: =SUM(F21,I21,L21,O21,R21,U21,X21,AA21,AD21,AG21,AJ21,AM21,AP21) -> 9 | D21: =SUM(G21,J21,M21,P21,S21,V21,Y21,AB21,AE21,AH21,AK21,AN21,AQ21) -> 2 | E21: =C21+D21 -> 11 | F21: ='ธ.ค.68'!AJ23 -> 3 | G21: ='ธ.ค.68'!AK23 -> 0 | H21: ='ธ.ค.68'!AL23 -> 3 | I21: ='ม.ค.69'!AJ21 -> 1 | J21: ='ม.ค.69'!AK21 -> 0 | K21: ='ม.ค.69'!AL21 -> 1 | L21: ='ก.พ.69'!AG21 -> 5 | M21: ='ก.พ.69'!AH21 -> 2 | N21: ='ก.พ.69'!AI21 -> 7 | O21: ='มี.ค.69'!AJ21 -> 0 | P21: ='มี.ค.69'!AK21 -> 0 | Q21: ='มี.ค.69'!AL21 -> 0 | R21: ='เม.ย.69'!AI21 -> 0 | S21: ='เม.ย.69'!AJ21 -> 0 | T21: ='เม.ย.69'!AK21 -> 0 | U21: ='พ.ค.69'!AJ21 -> 0 | V21: ='พ.ค.69'!AK21 -> 0 | W21: ='พ.ค.69'!AL21 -> 0 | X21: ='มิ.ย.69'!AI21 -> 0 | Y21: ='มิ.ย.69'!AJ21 -> 0 | Z21: ='มิ.ย.69'!AK21 -> 0 | AA21: ='ก.ค.69'!AJ21 -> 0 | AB21: ='ก.ค.69'!AK21 -> 0 | AC21: ='ก.ค.69'!AL21 -> 0 | AD21: ='ส.ค.69'!AJ21 -> 0 | AE21: ='ส.ค.69'!AK21 -> 0 | AF21: ='ส.ค.69'!AL21 -> 0 | AG21: ='ก.ย.69'!AI21 -> 0 | AH21: ='ก.ย.69'!AJ21 -> 0 | AI21: ='ก.ย.69'!AK21 -> 0 | AJ21: ='ต.ค.69'!AJ21 -> 0 | AK21: ='ต.ค.69'!AK21 -> 0 | AL21: ='ต.ค.69'!AL21 -> 0 | AM21: ='พ.ย.69'!AI21 -> 0 | AN21: ='พ.ย.69'!AJ21 -> 0 | AO21: ='พ.ย.69'!AK21 -> 0 | AP21: ='ธ.ค.69'!AJ21 -> 0 | AQ21: ='ธ.ค.69'!AK21 -> 0 | AR21: ='ธ.ค.69'!AL21 -> 0
A23: 11 | B23: ระยอง | C23: =SUM(F23,I23,L23,O23,R23,U23,X23,AA23,AD23,AG23,AJ23,AM23,AP23) -> 65 | D23: =SUM(G23,J23,M23,P23,S23,V23,Y23,AB23,AE23,AH23,AK23,AN23,AQ23) -> 0 | E23: =C23+D23 -> 65 | F23: ='ธ.ค.68'!AJ5 -> 19 | G23: ='ธ.ค.68'!AK5 -> 0 | H23: ='ธ.ค.68'!AL5 -> 19 | I23: ='ม.ค.69'!AJ23 -> 17 | J23: ='ม.ค.69'!AK23 -> 0 | K23: ='ม.ค.69'!AL23 -> 17 | L23: ='ก.พ.69'!AG23 -> 18 | M23: ='ก.พ.69'!AH23 -> 0 | N23: ='ก.พ.69'!AI23 -> 18 | O23: ='มี.ค.69'!AJ23 -> 11 | P23: ='มี.ค.69'!AK23 -> 0 | Q23: ='มี.ค.69'!AL23 -> 11 | R23: ='เม.ย.69'!AI23 -> 0 | S23: ='เม.ย.69'!AJ23 -> 0 | T23: ='เม.ย.69'!AK23 -> 0 | U23: ='พ.ค.69'!AJ23 -> 0 | V23: ='พ.ค.69'!AK23 -> 0 | W23: ='พ.ค.69'!AL23 -> 0 | X23: ='มิ.ย.69'!AI23 -> 0 | Y23: ='มิ.ย.69'!AJ23 -> 0 | Z23: ='มิ.ย.69'!AK23 -> 0 | AA23: ='ก.ค.69'!AJ23 -> 0 | AB23: ='ก.ค.69'!AK23 -> 0 | AC23: ='ก.ค.69'!AL23 -> 0 | AD23: ='ส.ค.69'!AJ23 -> 0 | AE23: ='ส.ค.69'!AK23 -> 0 | AF23: ='ส.ค.69'!AL23 -> 0 | AG23: ='ก.ย.69'!AI23 -> 0 | AH23: ='ก.ย.69'!AJ23 -> 0 | AI23: ='ก.ย.69'!AK23 -> 0 | AJ23: ='ต.ค.69'!AJ23 -> 0 | AK23: ='ต.ค.69'!AK23 -> 0 | AL23: ='ต.ค.69'!AL23 -> 0 | AM23: ='พ.ย.69'!AI23 -> 0 | AN23: ='พ.ย.69'!AJ23 -> 0 | AO23: ='พ.ย.69'!AK23 -> 0 | AP23: ='ธ.ค.69'!AJ23 -> 0 | AQ23: ='ธ.ค.69'!AK23 -> 0 | AR23: ='ธ.ค.69'!AL23 -> 0
A25: 12 | B25: บ้านฉาง | C25: =SUM(F25,I25,L25,O25,R25,U25,X25,AA25,AD25,AG25,AJ25,AM25,AP25) -> 5 | D25: =SUM(G25,J25,M25,P25,S25,V25,Y25,AB25,AE25,AH25,AK25,AN25,AQ25) -> 0 | E25: =C25+D25 -> 5 | F25: ='ธ.ค.68'!AJ35 -> 1 | G25: ='ธ.ค.68'!AK35 -> 0 | H25: ='ธ.ค.68'!AL35 -> 1 | I25: ='ม.ค.69'!AJ25 -> 2 | J25: ='ม.ค.69'!AK25 -> 0 | K25: ='ม.ค.69'!AL25 -> 2 | L25: ='ก.พ.69'!AG25 -> 1 | M25: ='ก.พ.69'!AH25 -> 0 | N25: ='ก.พ.69'!AI25 -> 1 | O25: ='มี.ค.69'!AJ25 -> 1 | P25: ='มี.ค.69'!AK25 -> 0 | Q25: ='มี.ค.69'!AL25 -> 1 | R25: ='เม.ย.69'!AI25 -> 0 | S25: ='เม.ย.69'!AJ25 -> 0 | T25: ='เม.ย.69'!AK25 -> 0 | U25: ='พ.ค.69'!AJ25 -> 0 | V25: ='พ.ค.69'!AK25 -> 0 | W25: ='พ.ค.69'!AL25 -> 0 | X25: ='มิ.ย.69'!AI25 -> 0 | Y25: ='มิ.ย.69'!AJ25 -> 0 | Z25: ='มิ.ย.69'!AK25 -> 0 | AA25: ='ก.ค.69'!AJ25 -> 0 | AB25: ='ก.ค.69'!AK25 -> 0 | AC25: ='ก.ค.69'!AL25 -> 0 | AD25: ='ส.ค.69'!AJ25 -> 0 | AE25: ='ส.ค.69'!AK25 -> 0 | AF25: ='ส.ค.69'!AL25 -> 0 | AG25: ='ก.ย.69'!AI25 -> 0 | AH25: ='ก.ย.69'!AJ25 -> 0 | AI25: ='ก.ย.69'!AK25 -> 0 | AJ25: ='ต.ค.69'!AJ25 -> 0 | AK25: ='ต.ค.69'!AK25 -> 0 | AL25: ='ต.ค.69'!AL25 -> 0 | AM25: ='พ.ย.69'!AI25 -> 0 | AN25: ='พ.ย.69'!AJ25 -> 0 | AO25: ='พ.ย.69'!AK25 -> 0 | AP25: ='ธ.ค.69'!AJ25 -> 0 | AQ25: ='ธ.ค.69'!AK25 -> 0 | AR25: ='ธ.ค.69'!AL25 -> 0
A27: 13 | B27: ปากน้ำประแสร์ | C27: =SUM(F27,I27,L27,O27,R27,U27,X27,AA27,AD27,AG27,AJ27,AM27,AP27) -> 10 | D27: =SUM(G27,J27,M27,P27,S27,V27,Y27,AB27,AE27,AH27,AK27,AN27,AQ27) -> 0 | E27: =C27+D27 -> 10 | F27: ='ธ.ค.68'!AJ15 -> 1 | G27: ='ธ.ค.68'!AK15 -> 0 | H27: ='ธ.ค.68'!AL15 -> 1 | I27: ='ม.ค.69'!AJ27 -> 3 | J27: ='ม.ค.69'!AK27 -> 0 | K27: ='ม.ค.69'!AL27 -> 3 | L27: ='ก.พ.69'!AG27 -> 6 | M27: ='ก.พ.69'!AH27 -> 0 | N27: ='ก.พ.69'!AI27 -> 6 | O27: ='มี.ค.69'!AJ27 -> 0 | P27: ='มี.ค.69'!AK27 -> 0 | Q27: ='มี.ค.69'!AL27 -> 0 | R27: ='เม.ย.69'!AI27 -> 0 | S27: ='เม.ย.69'!AJ27 -> 0 | T27: ='เม.ย.69'!AK27 -> 0 | U27: ='พ.ค.69'!AJ27 -> 0 | V27: ='พ.ค.69'!AK27 -> 0 | W27: ='พ.ค.69'!AL27 -> 0 | X27: ='มิ.ย.69'!AI27 -> 0 | Y27: ='มิ.ย.69'!AJ27 -> 0 | Z27: ='มิ.ย.69'!AK27 -> 0 | AA27: ='ก.ค.69'!AJ27 -> 0 | AB27: ='ก.ค.69'!AK27 -> 0 | AC27: ='ก.ค.69'!AL27 -> 0 | AD27: ='ส.ค.69'!AJ27 -> 0 | AE27: ='ส.ค.69'!AK27 -> 0 | AF27: ='ส.ค.69'!AL27 -> 0 | AG27: ='ก.ย.69'!AI27 -> 0 | AH27: ='ก.ย.69'!AJ27 -> 0 | AI27: ='ก.ย.69'!AK27 -> 0 | AJ27: ='ต.ค.69'!AJ27 -> 0 | AK27: ='ต.ค.69'!AK27 -> 0 | AL27: ='ต.ค.69'!AL27 -> 0 | AM27: ='พ.ย.69'!AI27 -> 0 | AN27: ='พ.ย.69'!AJ27 -> 0 | AO27: ='พ.ย.69'!AK27 -> 0 | AP27: ='ธ.ค.69'!AJ27 -> 0 | AQ27: ='ธ.ค.69'!AK27 -> 0 | AR27: ='ธ.ค.69'!AL27 -> 0
A29: 14 | B29: จันทบุรี | C29: =SUM(F29,I29,L29,O29,R29,U29,X29,AA29,AD29,AG29,AJ29,AM29,AP29) -> 29 | D29: =SUM(G29,J29,M29,P29,S29,V29,Y29,AB29,AE29,AH29,AK29,AN29,AQ29) -> 0 | E29: =C29+D29 -> 29 | F29: ='ธ.ค.68'!AJ3 -> 7 | G29: ='ธ.ค.68'!AK3 -> 0 | H29: ='ธ.ค.68'!AL3 -> 7 | I29: ='ม.ค.69'!AJ29 -> 4 | J29: ='ม.ค.69'!AK29 -> 0 | K29: ='ม.ค.69'!AL29 -> 4 | L29: ='ก.พ.69'!AG29 -> 10 | M29: ='ก.พ.69'!AH29 -> 0 | N29: ='ก.พ.69'!AI29 -> 10 | O29: ='มี.ค.69'!AJ29 -> 8 | P29: ='มี.ค.69'!AK29 -> 0 | Q29: ='มี.ค.69'!AL29 -> 8 | R29: ='เม.ย.69'!AI29 -> 0 | S29: ='เม.ย.69'!AJ29 -> 0 | T29: ='เม.ย.69'!AK29 -> 0 | U29: ='พ.ค.69'!AJ29 -> 0 | V29: ='พ.ค.69'!AK29 -> 0 | W29: ='พ.ค.69'!AL29 -> 0 | X29: ='มิ.ย.69'!AI29 -> 0 | Y29: ='มิ.ย.69'!AJ29 -> 0 | Z29: ='มิ.ย.69'!AK29 -> 0 | AA29: ='ก.ค.69'!AJ29 -> 0 | AB29: ='ก.ค.69'!AK29 -> 0 | AC29: ='ก.ค.69'!AL29 -> 0 | AD29: ='ส.ค.69'!AJ29 -> 0 | AE29: ='ส.ค.69'!AK29 -> 0 | AF29: ='ส.ค.69'!AL29 -> 0 | AG29: ='ก.ย.69'!AI29 -> 0 | AH29: ='ก.ย.69'!AJ29 -> 0 | AI29: ='ก.ย.69'!AK29 -> 0 | AJ29: ='ต.ค.69'!AJ29 -> 0 | AK29: ='ต.ค.69'!AK29 -> 0 | AL29: ='ต.ค.69'!AL29 -> 0 | AM29: ='พ.ย.69'!AI29 -> 0 | AN29: ='พ.ย.69'!AJ29 -> 0 | AO29: ='พ.ย.69'!AK29 -> 0 | AP29: ='ธ.ค.69'!AJ29 -> 0 | AQ29: ='ธ.ค.69'!AK29 -> 0 | AR29: ='ธ.ค.69'!AL29 -> 0
A31: 15 | B31: ขลุง | C31: =SUM(F31,I31,L31,O31,R31,U31,X31,AA31,AD31,AG31,AJ31,AM31,AP31) -> 27 | D31: =SUM(G31,J31,M31,P31,S31,V31,Y31,AB31,AE31,AH31,AK31,AN31,AQ31) -> 1 | E31: =C31+D31 -> 28 | F31: ='ธ.ค.68'!AJ11 -> 8 | G31: ='ธ.ค.68'!AK11 -> 0 | H31: ='ธ.ค.68'!AL11 -> 8 | I31: ='ม.ค.69'!AJ31 -> 12 | J31: ='ม.ค.69'!AK31 -> 0 | K31: ='ม.ค.69'!AL31 -> 12 | L31: ='ก.พ.69'!AG31 -> 5 | M31: ='ก.พ.69'!AH31 -> 0 | N31: ='ก.พ.69'!AI31 -> 5 | O31: ='มี.ค.69'!AJ31 -> 2 | P31: ='มี.ค.69'!AK31 -> 1 | Q31: ='มี.ค.69'!AL31 -> 3 | R31: ='เม.ย.69'!AI31 -> 0 | S31: ='เม.ย.69'!AJ31 -> 0 | T31: ='เม.ย.69'!AK31 -> 0 | U31: ='พ.ค.69'!AJ31 -> 0 | V31: ='พ.ค.69'!AK31 -> 0 | W31: ='พ.ค.69'!AL31 -> 0 | X31: ='มิ.ย.69'!AI31 -> 0 | Y31: ='มิ.ย.69'!AJ31 -> 0 | Z31: ='มิ.ย.69'!AK31 -> 0 | AA31: ='ก.ค.69'!AJ31 -> 0 | AB31: ='ก.ค.69'!AK31 -> 0 | AC31: ='ก.ค.69'!AL31 -> 0 | AD31: ='ส.ค.69'!AJ31 -> 0 | AE31: ='ส.ค.69'!AK31 -> 0 | AF31: ='ส.ค.69'!AL31 -> 0 | AG31: ='ก.ย.69'!AI31 -> 0 | AH31: ='ก.ย.69'!AJ31 -> 0 | AI31: ='ก.ย.69'!AK31 -> 0 | AJ31: ='ต.ค.69'!AJ31 -> 0 | AK31: ='ต.ค.69'!AK31 -> 0 | AL31: ='ต.ค.69'!AL31 -> 0 | AM31: ='พ.ย.69'!AI31 -> 0 | AN31: ='พ.ย.69'!AJ31 -> 0 | AO31: ='พ.ย.69'!AK31 -> 0 | AP31: ='ธ.ค.69'!AJ31 -> 0 | AQ31: ='ธ.ค.69'!AK31 -> 0 | AR31: ='ธ.ค.69'!AL31 -> 0
A33: 16 | B33: ตราด | C33: =SUM(F33,I33,L33,O33,R33,U33,X33,AA33,AD33,AG33,AJ33,AM33,AP33) -> 13 | D33: =SUM(G33,J33,M33,P33,S33,V33,Y33,AB33,AE33,AH33,AK33,AN33,AQ33) -> 0 | E33: =C33+D33 -> 13 | F33: ='ธ.ค.68'!AJ29 -> 5 | G33: ='ธ.ค.68'!AK29 -> 0 | H33: ='ธ.ค.68'!AL29 -> 5 | I33: ='ม.ค.69'!AJ33 -> 4 | J33: ='ม.ค.69'!AK33 -> 0 | K33: ='ม.ค.69'!AL33 -> 4 | L33: ='ก.พ.69'!AG33 -> 3 | M33: ='ก.พ.69'!AH33 -> 0 | N33: ='ก.พ.69'!AI33 -> 3 | O33: ='มี.ค.69'!AJ33 -> 1 | P33: ='มี.ค.69'!AK33 -> 0 | Q33: ='มี.ค.69'!AL33 -> 1 | R33: ='เม.ย.69'!AI33 -> 0 | S33: ='เม.ย.69'!AJ33 -> 0 | T33: ='เม.ย.69'!AK33 -> 0 | U33: ='พ.ค.69'!AJ33 -> 0 | V33: ='พ.ค.69'!AK33 -> 0 | W33: ='พ.ค.69'!AL33 -> 0 | X33: ='มิ.ย.69'!AI33 -> 0 | Y33: ='มิ.ย.69'!AJ33 -> 0 | Z33: ='มิ.ย.69'!AK33 -> 0 | AA33: ='ก.ค.69'!AJ33 -> 0 | AB33: ='ก.ค.69'!AK33 -> 0 | AC33: ='ก.ค.69'!AL33 -> 0 | AD33: ='ส.ค.69'!AJ33 -> 0 | AE33: ='ส.ค.69'!AK33 -> 0 | AF33: ='ส.ค.69'!AL33 -> 0 | AG33: ='ก.ย.69'!AI33 -> 0 | AH33: ='ก.ย.69'!AJ33 -> 0 | AI33: ='ก.ย.69'!AK33 -> 0 | AJ33: ='ต.ค.69'!AJ33 -> 0 | AK33: ='ต.ค.69'!AK33 -> 0 | AL33: ='ต.ค.69'!AL33 -> 0 | AM33: ='พ.ย.69'!AI33 -> 0 | AN33: ='พ.ย.69'!AJ33 -> 0 | AO33: ='พ.ย.69'!AK33 -> 0 | AP33: ='ธ.ค.69'!AJ33 -> 0 | AQ33: ='ธ.ค.69'!AK33 -> 0 | AR33: ='ธ.ค.69'!AL33 -> 0
A35: 17 | B35: คลองใหญ่ | C35: =SUM(F35,I35,L35,O35,R35,U35,X35,AA35,AD35,AG35,AJ35,AM35,AP35) -> 6 | D35: =SUM(G35,J35,M35,P35,S35,V35,Y35,AB35,AE35,AH35,AK35,AN35,AQ35) -> 0 | E35: =C35+D35 -> 6 | F35: ='ธ.ค.68'!AJ43 -> 0 | G35: ='ธ.ค.68'!AK43 -> 0 | H35: ='ธ.ค.68'!AL43 -> 0 | I35: ='ม.ค.69'!AJ35 -> 2 | J35: ='ม.ค.69'!AK35 -> 0 | K35: ='ม.ค.69'!AL35 -> 2 | L35: ='ก.พ.69'!AG35 -> 2 | M35: ='ก.พ.69'!AH35 -> 0 | N35: ='ก.พ.69'!AI35 -> 2 | O35: ='มี.ค.69'!AJ35 -> 2 | P35: ='มี.ค.69'!AK35 -> 0 | Q35: ='มี.ค.69'!AL35 -> 2 | R35: ='เม.ย.69'!AI35 -> 0 | S35: ='เม.ย.69'!AJ35 -> 0 | T35: ='เม.ย.69'!AK35 -> 0 | U35: ='พ.ค.69'!AJ35 -> 0 | V35: ='พ.ค.69'!AK35 -> 0 | W35: ='พ.ค.69'!AL35 -> 0 | X35: ='มิ.ย.69'!AI35 -> 0 | Y35: ='มิ.ย.69'!AJ35 -> 0 | Z35: ='มิ.ย.69'!AK35 -> 0 | AA35: ='ก.ค.69'!AJ35 -> 0 | AB35: ='ก.ค.69'!AK35 -> 0 | AC35: ='ก.ค.69'!AL35 -> 0 | AD35: ='ส.ค.69'!AJ35 -> 0 | AE35: ='ส.ค.69'!AK35 -> 0 | AF35: ='ส.ค.69'!AL35 -> 0 | AG35: ='ก.ย.69'!AI35 -> 0 | AH35: ='ก.ย.69'!AJ35 -> 0 | AI35: ='ก.ย.69'!AK35 -> 0 | AJ35: ='ต.ค.69'!AJ35 -> 0 | AK35: ='ต.ค.69'!AK35 -> 0 | AL35: ='ต.ค.69'!AL35 -> 0 | AM35: ='พ.ย.69'!AI35 -> 0 | AN35: ='พ.ย.69'!AJ35 -> 0 | AO35: ='พ.ย.69'!AK35 -> 0 | AP35: ='ธ.ค.69'!AJ35 -> 0 | AQ35: ='ธ.ค.69'!AK35 -> 0 | AR35: ='ธ.ค.69'!AL35 -> 0
A37: 18 | B37: สระแก้ว | C37: =SUM(F37,I37,L37,O37,R37,U37,X37,AA37,AD37,AG37,AJ37,AM37,AP37) -> 21 | D37: =SUM(G37,J37,M37,P37,S37,V37,Y37,AB37,AE37,AH37,AK37,AN37,AQ37) -> 12 | E37: =C37+D37 -> 33 | F37: ='ธ.ค.68'!AJ33 -> 1 | G37: ='ธ.ค.68'!AK33 -> 0 | H37: ='ธ.ค.68'!AL33 -> 1 | I37: ='ม.ค.69'!AJ37 -> 2 | J37: ='ม.ค.69'!AK37 -> 0 | K37: ='ม.ค.69'!AL37 -> 2 | L37: ='ก.พ.69'!AG37 -> 6 | M37: ='ก.พ.69'!AH37 -> 0 | N37: ='ก.พ.69'!AI37 -> 6 | O37: ='มี.ค.69'!AJ37 -> 12 | P37: ='มี.ค.69'!AK37 -> 12 | Q37: ='มี.ค.69'!AL37 -> 24 | R37: ='เม.ย.69'!AI37 -> 0 | S37: ='เม.ย.69'!AJ37 -> 0 | T37: ='เม.ย.69'!AK37 -> 0 | U37: ='พ.ค.69'!AJ37 -> 0 | V37: ='พ.ค.69'!AK37 -> 0 | W37: ='พ.ค.69'!AL37 -> 0 | X37: ='มิ.ย.69'!AI37 -> 0 | Y37: ='มิ.ย.69'!AJ37 -> 0 | Z37: ='มิ.ย.69'!AK37 -> 0 | AA37: ='ก.ค.69'!AJ37 -> 0 | AB37: ='ก.ค.69'!AK37 -> 0 | AC37: ='ก.ค.69'!AL37 -> 0 | AD37: ='ส.ค.69'!AJ37 -> 0 | AE37: ='ส.ค.69'!AK37 -> 0 | AF37: ='ส.ค.69'!AL37 -> 0 | AG37: ='ก.ย.69'!AI37 -> 0 | AH37: ='ก.ย.69'!AJ37 -> 0 | AI37: ='ก.ย.69'!AK37 -> 0 | AJ37: ='ต.ค.69'!AJ37 -> 0 | AK37: ='ต.ค.69'!AK37 -> 0 | AL37: ='ต.ค.69'!AL37 -> 0 | AM37: ='พ.ย.69'!AI37 -> 0 | AN37: ='พ.ย.69'!AJ37 -> 0 | AO37: ='พ.ย.69'!AK37 -> 0 | AP37: ='ธ.ค.69'!AJ37 -> 0 | AQ37: ='ธ.ค.69'!AK37 -> 0 | AR37: ='ธ.ค.69'!AL37 -> 0
A39: 19 | B39: วัฒนานคร | C39: =SUM(F39,I39,L39,O39,R39,U39,X39,AA39,AD39,AG39,AJ39,AM39,AP39) -> 22 | D39: =SUM(G39,J39,M39,P39,S39,V39,Y39,AB39,AE39,AH39,AK39,AN39,AQ39) -> 2 | E39: =C39+D39 -> 24 | F39: ='ธ.ค.68'!AJ17 -> 2 | G39: ='ธ.ค.68'!AK17 -> 0 | H39: ='ธ.ค.68'!AL17 -> 2 | I39: ='ม.ค.69'!AJ39 -> 6 | J39: ='ม.ค.69'!AK39 -> 0 | K39: ='ม.ค.69'!AL39 -> 6 | L39: ='ก.พ.69'!AG39 -> 8 | M39: ='ก.พ.69'!AH39 -> 1 | N39: ='ก.พ.69'!AI39 -> 9 | O39: ='มี.ค.69'!AJ39 -> 6 | P39: ='มี.ค.69'!AK39 -> 1 | Q39: ='มี.ค.69'!AL39 -> 7 | R39: ='เม.ย.69'!AI39 -> 0 | S39: ='เม.ย.69'!AJ39 -> 0 | T39: ='เม.ย.69'!AK39 -> 0 | U39: ='พ.ค.69'!AJ39 -> 0 | V39: ='พ.ค.69'!AK39 -> 0 | W39: ='พ.ค.69'!AL39 -> 0 | X39: ='มิ.ย.69'!AI39 -> 0 | Y39: ='มิ.ย.69'!AJ39 -> 0 | Z39: ='มิ.ย.69'!AK39 -> 0 | AA39: ='ก.ค.69'!AJ39 -> 0 | AB39: ='ก.ค.69'!AK39 -> 0 | AC39: ='ก.ค.69'!AL39 -> 0 | AD39: ='ส.ค.69'!AJ39 -> 0 | AE39: ='ส.ค.69'!AK39 -> 0 | AF39: ='ส.ค.69'!AL39 -> 0 | AG39: ='ก.ย.69'!AI39 -> 0 | AH39: ='ก.ย.69'!AJ39 -> 0 | AI39: ='ก.ย.69'!AK39 -> 0 | AJ39: ='ต.ค.69'!AJ39 -> 0 | AK39: ='ต.ค.69'!AK39 -> 0 | AL39: ='ต.ค.69'!AL39 -> 0 | AM39: ='พ.ย.69'!AI39 -> 0 | AN39: ='พ.ย.69'!AJ39 -> 0 | AO39: ='พ.ย.69'!AK39 -> 0 | AP39: ='ธ.ค.69'!AJ39 -> 0 | AQ39: ='ธ.ค.69'!AK39 -> 0 | AR39: ='ธ.ค.69'!AL39 -> 0
A41: 20 | B41: อรัญประเทศ | C41: =SUM(F41,I41,L41,O41,R41,U41,X41,AA41,AD41,AG41,AJ41,AM41,AP41) -> 4 | D41: =SUM(G41,J41,M41,P41,S41,V41,Y41,AB41,AE41,AH41,AK41,AN41,AQ41) -> 0 | E41: =C41+D41 -> 4 | F41: ='ธ.ค.68'!AJ45 -> 0 | G41: ='ธ.ค.68'!AK45 -> 0 | H41: ='ธ.ค.68'!AL45 -> 0 | I41: ='ม.ค.69'!AJ41 -> 1 | J41: ='ม.ค.69'!AK41 -> 0 | K41: ='ม.ค.69'!AL41 -> 1 | L41: ='ก.พ.69'!AG41 -> 3 | M41: ='ก.พ.69'!AH41 -> 0 | N41: ='ก.พ.69'!AI41 -> 3 | O41: ='มี.ค.69'!AJ41 -> 0 | P41: ='มี.ค.69'!AK41 -> 0 | Q41: ='มี.ค.69'!AL41 -> 0 | R41: ='เม.ย.69'!AI41 -> 0 | S41: ='เม.ย.69'!AJ41 -> 0 | T41: ='เม.ย.69'!AK41 -> 0 | U41: ='พ.ค.69'!AJ41 -> 0 | V41: ='พ.ค.69'!AK41 -> 0 | W41: ='พ.ค.69'!AL41 -> 0 | X41: ='มิ.ย.69'!AI41 -> 0 | Y41: ='มิ.ย.69'!AJ41 -> 0 | Z41: ='มิ.ย.69'!AK41 -> 0 | AA41: ='ก.ค.69'!AJ41 -> 0 | AB41: ='ก.ค.69'!AK41 -> 0 | AC41: ='ก.ค.69'!AL41 -> 0 | AD41: ='ส.ค.69'!AJ41 -> 0 | AE41: ='ส.ค.69'!AK41 -> 0 | AF41: ='ส.ค.69'!AL41 -> 0 | AG41: ='ก.ย.69'!AI41 -> 0 | AH41: ='ก.ย.69'!AJ41 -> 0 | AI41: ='ก.ย.69'!AK41 -> 0 | AJ41: ='ต.ค.69'!AJ41 -> 0 | AK41: ='ต.ค.69'!AK41 -> 0 | AL41: ='ต.ค.69'!AL41 -> 0 | AM41: ='พ.ย.69'!AI41 -> 0 | AN41: ='พ.ย.69'!AJ41 -> 0 | AO41: ='พ.ย.69'!AK41 -> 0 | AP41: ='ธ.ค.69'!AJ41 -> 0 | AQ41: ='ธ.ค.69'!AK41 -> 0 | AR41: ='ธ.ค.69'!AL41 -> 0
A43: 21 | B43: ปราจีนบุรี | C43: =SUM(F43,I43,L43,O43,R43,U43,X43,AA43,AD43,AG43,AJ43,AM43,AP43) -> 35 | D43: =SUM(G43,J43,M43,P43,S43,V43,Y43,AB43,AE43,AH43,AK43,AN43,AQ43) -> 0 | E43: =C43+D43 -> 35 | F43: ='ธ.ค.68'!AJ13 -> 3 | G43: ='ธ.ค.68'!AK13 -> 0 | H43: ='ธ.ค.68'!AL13 -> 3 | I43: ='ม.ค.69'!AJ43 -> 3 | J43: ='ม.ค.69'!AK43 -> 0 | K43: ='ม.ค.69'!AL43 -> 3 | L43: ='ก.พ.69'!AG43 -> 22 | M43: ='ก.พ.69'!AH43 -> 0 | N43: ='ก.พ.69'!AI43 -> 22 | O43: ='มี.ค.69'!AJ43 -> 7 | P43: ='มี.ค.69'!AK43 -> 0 | Q43: ='มี.ค.69'!AL43 -> 7 | R43: ='เม.ย.69'!AI43 -> 0 | S43: ='เม.ย.69'!AJ43 -> 0 | T43: ='เม.ย.69'!AK43 -> 0 | U43: ='พ.ค.69'!AJ43 -> 0 | V43: ='พ.ค.69'!AK43 -> 0 | W43: ='พ.ค.69'!AL43 -> 0 | X43: ='มิ.ย.69'!AI43 -> 0 | Y43: ='มิ.ย.69'!AJ43 -> 0 | Z43: ='มิ.ย.69'!AK43 -> 0 | AA43: ='ก.ค.69'!AJ43 -> 0 | AB43: ='ก.ค.69'!AK43 -> 0 | AC43: ='ก.ค.69'!AL43 -> 0 | AD43: ='ส.ค.69'!AJ43 -> 0 | AE43: ='ส.ค.69'!AK43 -> 0 | AF43: ='ส.ค.69'!AL43 -> 0 | AG43: ='ก.ย.69'!AI43 -> 0 | AH43: ='ก.ย.69'!AJ43 -> 0 | AI43: ='ก.ย.69'!AK43 -> 0 | AJ43: ='ต.ค.69'!AJ43 -> 0 | AK43: ='ต.ค.69'!AK43 -> 0 | AL43: ='ต.ค.69'!AL43 -> 0 | AM43: ='พ.ย.69'!AI43 -> 0 | AN43: ='พ.ย.69'!AJ43 -> 0 | AO43: ='พ.ย.69'!AK43 -> 0 | AP43: ='ธ.ค.69'!AJ43 -> 0 | AQ43: ='ธ.ค.69'!AK43 -> 0 | AR43: ='ธ.ค.69'!AL43 -> 0
A45: 22 | B45: กบินทร์บุรี | C45: =SUM(F45,I45,L45,O45,R45,U45,X45,AA45,AD45,AG45,AJ45,AM45,AP45) -> 10 | D45: =SUM(G45,J45,M45,P45,S45,V45,Y45,AB45,AE45,AH45,AK45,AN45,AQ45) -> 0 | E45: =C45+D45 -> 10 | F45: ='ธ.ค.68'!AJ19 -> 4 | G45: ='ธ.ค.68'!AK19 -> 0 | H45: ='ธ.ค.68'!AL19 -> 4 | I45: ='ม.ค.69'!AJ45 -> 3 | J45: ='ม.ค.69'!AK45 -> 0 | K45: ='ม.ค.69'!AL45 -> 3 | L45: ='ก.พ.69'!AG45 -> 3 | M45: ='ก.พ.69'!AH45 -> 0 | N45: ='ก.พ.69'!AI45 -> 3 | O45: ='มี.ค.69'!AJ45 -> 0 | P45: ='มี.ค.69'!AK45 -> 0 | Q45: ='มี.ค.69'!AL45 -> 0 | R45: ='เม.ย.69'!AI45 -> 0 | S45: ='เม.ย.69'!AJ45 -> 0 | T45: ='เม.ย.69'!AK45 -> 0 | U45: ='พ.ค.69'!AJ45 -> 0 | V45: ='พ.ค.69'!AK45 -> 0 | W45: ='พ.ค.69'!AL45 -> 0 | X45: ='มิ.ย.69'!AI45 -> 0 | Y45: ='มิ.ย.69'!AJ45 -> 0 | Z45: ='มิ.ย.69'!AK45 -> 0 | AA45: ='ก.ค.69'!AJ45 -> 0 | AB45: ='ก.ค.69'!AK45 -> 0 | AC45: ='ก.ค.69'!AL45 -> 0 | AD45: ='ส.ค.69'!AJ45 -> 0 | AE45: ='ส.ค.69'!AK45 -> 0 | AF45: ='ส.ค.69'!AL45 -> 0 | AG45: ='ก.ย.69'!AI45 -> 0 | AH45: ='ก.ย.69'!AJ45 -> 0 | AI45: ='ก.ย.69'!AK45 -> 0 | AJ45: ='ต.ค.69'!AJ45 -> 0 | AK45: ='ต.ค.69'!AK45 -> 0 | AL45: ='ต.ค.69'!AL45 -> 0 | AM45: ='พ.ย.69'!AI45 -> 0 | AN45: ='พ.ย.69'!AJ45 -> 0 | AO45: ='พ.ย.69'!AK45 -> 0 | AP45: ='ธ.ค.69'!AJ45 -> 0 | AQ45: ='ธ.ค.69'!AK45 -> 0 | AR45: ='ธ.ค.69'!AL45 -> 0
C47: =SUM(C3:C46) -> 372 | D47: =SUM(D3:D46) -> 43 | E47: =SUM(E3:E46) -> 415

Sheet ธ.ค.68
A1: ลำดับ | B1: กปภ. สาขา | C1: กิจกรรมลดน้ำสูญเสีย | E1: วันที่ดำเนินกิจกรรมในเดือนธันวาคม 2568 | AJ1: เชิงกายภาพ (ครั้ง) | AK1: เชิงพาณิชย์ (ครั้ง) | AL1: รวมทั้งหมด (ครั้ง)
C2: เชิงกายภาพ | D2: เชิงพาณิชย์ | E2: 1 | F2: 2 | G2: 3 | H2: 4 | I2: 5 | J2: 6 | K2: 7 | L2: 8 | M2: 9 | N2: 10 | O2: 11 | P2: 12 | Q2: 13 | R2: 14 | S2: 15 | T2: 16 | U2: 17 | V2: 18 | W2: 19 | X2: 20 | Y2: 21 | Z2: 22 | AA2: 23 | AB2: 24 | AC2: 25 | AD2: 26 | AE2: 27 | AF2: 28 | AG2: 29 | AH2: 30 | AI2: 31
A3: 1 | B3: จันทบุรี | C3: ✔ | E3: ✔ | F3: ✔ | G3: ✔ | H3: ✔ | M3: ✔ | O3: ✔ | T3: ✔ | AJ3: =COUNTA(E3:AI3) -> 7 | AK3: =COUNTA(E4:AI4) -> 0 | AL3: =COUNTA(E3:AI4) -> 7
A5: 2 | B5: ระยอง | C5: ✔ | F5: ✔ | G5: ✔ | H5: ✔ | I5: ✔ | M5: ✔ | N5: ✔ | P5: ✔ | Q5: ✔ | R5: ✔ | S5: ✔ | U5: ✔ | W5: ✔ | X5: ✔ | Y5: ✔ | AA5: ✔ | AB5: ✔ | AD5: ✔ | AH5: ✔ | AI5: ✔ | AJ5: =COUNTA(E5:AI5) -> 19 | AK5: =COUNTA(E6:AI6) -> 0 | AL5: =COUNTA(E5:AI6) -> 19
A7: 3 | B7: บ้านบึง | C7: ✔ | F7: ✔ | G7: ✔ | AA7: ✔ | AJ7: =COUNTA(E7:AI7) -> 3 | AK7: =COUNTA(E8:AI8) -> 0 | AL7: =COUNTA(E7:AI8) -> 3
A9: 4 | B9: บางคล้า | C9: ✔ | F9: ✔ | M9: ✔ | AD9: ✔ | AJ9: =COUNTA(E9:AI9) -> 3 | AK9: =COUNTA(E10:AI10) -> 0 | AL9: =COUNTA(E9:AI10) -> 3
A11: 5 | B11: ขลุง | C11: ✔ | F11: ✔ | H11: ✔ | M11: ✔ | O11: ✔ | U11: ✔ | V11: ✔ | AA11: ✔ | AB11: ✔ | AJ11: =COUNTA(E11:AI11) -> 8 | AK11: =COUNTA(E12:AI12) -> 0 | AL11: =COUNTA(E11:AI12) -> 8
A13: 6 | B13: ปราจีนบุรี | C13: ✔ | E13: ✔ | G13: ✔ | Z13: ✔ | AJ13: =COUNTA(E13:AI13) -> 3 | AK13: =COUNTA(E14:AI14) -> 0 | AL13: =COUNTA(E13:AI14) -> 3
A15: 7 | B15: ปากน้ำประแสร์ | C15: ✔ | F15: ✔ | AJ15: =COUNTA(E15:AI15) -> 1 | AK15: =COUNTA(E16:AI16) -> 0 | AL15: =COUNTA(E15:AI16) -> 1
A17: 8 | B17: วัฒนานคร | C17: ✔ | G17: ✔ | AB17: ✔ | AJ17: =COUNTA(E17:AI17) -> 2 | AK17: =COUNTA(E18:AI18) -> 0 | AL17: =COUNTA(E17:AI18) -> 2
A19: 9 | B19: กบินทร์บุรี | C19: ✔ | H19: ✔ | R19: ✔ | AC19: ✔ | AD19: ✔ | AJ19: =COUNTA(E19:AI19) -> 4 | AK19: =COUNTA(E20:AI20) -> 0 | AL19: =COUNTA(E19:AI20) -> 4
A21: 10 | B21: บางปะกง | C21: ✔ | D21: ⭕ | G21: ✔ | H21: ✔ | AB21: ✔ | AJ21: =COUNTA(E21:AI21) -> 3 | AK21: =COUNTA(E22:AI22) -> 2 | AL21: =COUNTA(E21:AI22) -> 5
G22: ⭕ | H22: ⭕
A23: 11 | B23: พนมสารคาม | C23: ✔ | G23: ✔ | M23: ✔ | AG23: ✔ | AJ23: =COUNTA(E23:AI23) -> 3 | AK23: =COUNTA(E24:AI24) -> 0 | AL23: =COUNTA(E23:AI24) -> 3
A25: 12 | B25: แหลมฉบัง | C25: ✔ | J25: ✔ | P25: ✔ | T25: ✔ | AJ25: =COUNTA(E25:AI25) -> 3 | AK25: =COUNTA(E26:AI26) -> 0 | AL25: =COUNTA(E25:AI26) -> 3
A27: 13 | B27: ศรีราชา | C27: ✔ | M27: ✔ | AJ27: =COUNTA(E27:AI27) -> 1 | AK27: =COUNTA(E28:AI28) -> 0 | AL27: =COUNTA(E27:AI28) -> 1
A29: 14 | B29: ตราด | C29: ✔ | R29: ✔ | V29: ✔ | W29: ✔ | Z29: ✔ | AD29: ✔ | AJ29: =COUNTA(E29:AI29) -> 5 | AK29: =COUNTA(E30:AI30) -> 0 | AL29: =COUNTA(E29:AI30) -> 5
A31: 15 | B31: พนัสนิคม | C31: ✔ | V31: ✔ | AJ31: =COUNTA(E31:AI31) -> 1 | AK31: =COUNTA(E32:AI32) -> 0 | AL31: =COUNTA(E31:AI32) -> 1
A33: 16 | B33: สระแก้ว | C33: ✔ | AA33: ✔ | AJ33: =COUNTA(E33:AI33) -> 1 | AK33: =COUNTA(E34:AI34) -> 0 | AL33: =COUNTA(E33:AI34) -> 1
A35: 17 | B35: บ้านฉาง | C35: ✔ | AA35: ✔ | AJ35: =COUNTA(E35:AI35) -> 1 | AK35: =COUNTA(E36:AI36) -> 0 | AL35: =COUNTA(E35:AI36) -> 1
A37: 18 | B37: ชลบุรี(พิเศษ) | C37: ✔ | D37: ⭕ | AA37: ✔ | AC37: ✔ | AJ37: =COUNTA(E37:AI37) -> 2 | AK37: =COUNTA(E38:AI38) -> 1 | AL37: =COUNTA(E37:AI38) -> 3
AC38: ⭕
A39: 19 | B39: ฉะเชิงเทรา | C39: ✔ | AG39: ✔ | AJ39: =COUNTA(E39:AI39) -> 1 | AK39: =COUNTA(E40:AI40) -> 0 | AL39: =COUNTA(E39:AI40) -> 1
A41: 20 | B41: พัทยา(พิเศษ) | AJ41: =COUNTA(E41:AI41) -> 0 | AK41: =COUNTA(E42:AI42) -> 0 | AL41: =COUNTA(E41:AI42) -> 0
A43: 21 | B43: คลองใหญ่ | AJ43: =COUNTA(E43:AI43) -> 0 | AK43: =COUNTA(E44:AI44) -> 0 | AL43: =COUNTA(E43:AI44) -> 0
A45: 22 | B45: อรัญประเทศ | AJ45: =COUNTA(E45:AI45) -> 0 | AK45: =COUNTA(E46:AI46) -> 0 | AL45: =COUNTA(E45:AI46) -> 0
B48: * หมายเหตุ | C48: ✔ | D48: กิจกรรมลดน้ำสูญเสียเชิงกายภาพ
C49: ⭕ | D49: กิจกรรมลดน้ำสูญเสียเชิงพาณิชย์

Sheet ม.ค.69
A1: ลำดับ | B1: กปภ. สาขา | C1: กิจกรรมลดน้ำสูญเสีย | E1: วันที่ดำเนินกิจกรรมในเดือนมกราคม 2569 | AJ1: เชิงกายภาพ (ครั้ง) | AK1: เชิงพาณิชย์ (ครั้ง) | AL1: รวมทั้งหมด (ครั้ง)
C2: เชิงกายภาพ | D2: เชิงพาณิชย์ | E2: 1 | F2: 2 | G2: 3 | H2: 4 | I2: 5 | J2: 6 | K2: 7 | L2: 8 | M2: 9 | N2: 10 | O2: 11 | P2: 12 | Q2: 13 | R2: 14 | S2: 15 | T2: 16 | U2: 17 | V2: 18 | W2: 19 | X2: 20 | Y2: 21 | Z2: 22 | AA2: 23 | AB2: 24 | AC2: 25 | AD2: 26 | AE2: 27 | AF2: 28 | AG2: 29 | AH2: 30 | AI2: 31
A3: 1 | B3: ชลบุรี(พิเศษ) | C3: ✔ | D3: ⭕ | I3: ✔ | J3: ✔ | L3: ✔ | M3: ✔ | P3: ✔ | Q3: ✔ | R3: ✔ | S3: ✔ | Z3: ✔ | AA3: ✔ | AB3: ✔ | AC3: ✔ | AD3: ⭕ | AE3: ✔ | AF3: ✔ | AH3: ✔ | AJ3: =COUNTA(E3:AI3) -> 16 | AK3: =COUNTA(E4:AI4) -> 5 | AL3: =COUNTA(E3:AI4) -> 21
L4: ⭕ | M4: ⭕ | Z4: ⭕ | AE4: ⭕ | AF4: ⭕
A5: 2 | B5: พัทยา(พิเศษ) | C5: ✔ | S5: ✔ | AJ5: =COUNTA(E5:AI5) -> 1 | AK5: =COUNTA(E6:AI6) -> 0 | AL5: =COUNTA(E5:AI6) -> 1
A7: 3 | B7: บ้านบึง | C7: ✔ | S7: ✔ | AJ7: =COUNTA(E7:AI7) -> 1 | AK7: =COUNTA(E8:AI8) -> 0 | AL7: =COUNTA(E7:AI8) -> 1
A9: 4 | B9: พนัสนิคม | C9: ✔ | D9: ⭕ | R9: ✔ | S9: ✔ | X9: ✔ | AF9: ✔ | AH9: ✔ | AJ9: =COUNTA(E9:AI9) -> 5 | AK9: =COUNTA(E10:AI10) -> 2 | AL9: =COUNTA(E9:AI10) -> 7
S10: ⭕ | X10: ⭕
A11: 5 | B11: ศรีราชา | C11: ✔ | S11: ✔ | AJ11: =COUNTA(E11:AI11) -> 1 | AK11: =COUNTA(E12:AI12) -> 0 | AL11: =COUNTA(E11:AI12) -> 1
A13: 6 | B13: แหลมฉบัง | C13: ✔ | S13: ✔ | AJ13: =COUNTA(E13:AI13) -> 1 | AK13: =COUNTA(E14:AI14) -> 0 | AL13: =COUNTA(E13:AI14) -> 1
A15: 7 | B15: ฉะเชิงเทรา | C15: ✔ | S15: ✔ | AJ15: =COUNTA(E15:AI15) -> 1 | AK15: =COUNTA(E16:AI16) -> 0 | AL15: =COUNTA(E15:AI16) -> 1
A17: 8 | B17: บางปะกง | C17: ✔ | S17: ✔ | AD17: ✔ | AE17: ✔ | AJ17: =COUNTA(E17:AI17) -> 3 | AK17: =COUNTA(E18:AI18) -> 0 | AL17: =COUNTA(E17:AI18) -> 3
A19: 9 | B19: บางคล้า | C19: ✔ | R19: ✔ | S19: ✔ | X19: ✔ | AJ19: =COUNTA(E19:AI19) -> 3 | AK19: =COUNTA(E20:AI20) -> 0 | AL19: =COUNTA(E19:AI20) -> 3
A21: 10 | B21: พนมสารคาม | C21: ✔ | S21: ✔ | AJ21: =COUNTA(E21:AI21) -> 1 | AK21: =COUNTA(E22:AI22) -> 0 | AL21: =COUNTA(E21:AI22) -> 1
A23: 11 | B23: ระยอง | C23: ✔ | I23: ✔ | J23: ✔ | L23: ✔ | M23: ✔ | N23: ✔ | O23: ✔ | Q23: ✔ | R23: ✔ | S23: ✔ | X23: ✔ | Y23: ✔ | Z23: ✔ | AA23: ✔ | AC23: ✔ | AE23: ✔ | AF23: ✔ | AH23: ✔ | AJ23: =COUNTA(E23:AI23) -> 17 | AK23: =COUNTA(E24:AI24) -> 0 | AL23: =COUNTA(E23:AI24) -> 17
A25: 12 | B25: บ้านฉาง | C25: ✔ | I25: ✔ | S25: ✔ | AJ25: =COUNTA(E25:AI25) -> 2 | AK25: =COUNTA(E26:AI26) -> 0 | AL25: =COUNTA(E25:AI26) -> 2
A27: 13 | B27: ปากน้ำประแสร์ | C27: ✔ | S27: ✔ | AD27: ✔ | AE27: ✔ | AJ27: =COUNTA(E27:AI27) -> 3 | AK27: =COUNTA(E28:AI28) -> 0 | AL27: =COUNTA(E27:AI28) -> 3
A29: 14 | B29: จันทบุรี | C29: ✔ | J29: ✔ | S29: ✔ | AD29: ✔ | AE29: ✔ | AJ29: =COUNTA(E29:AI29) -> 4 | AK29: =COUNTA(E30:AI30) -> 0 | AL29: =COUNTA(E29:AI30) -> 4
A31: 15 | B31: ขลุง | C31: ✔ | I31: ✔ | J31: ✔ | L31: ✔ | M31: ✔ | P31: ✔ | Q31: ✔ | S31: ✔ | W31: ✔ | Y31: ✔ | Z31: ✔ | AD31: ✔ | AG31: ✔ | AJ31: =COUNTA(E31:AI31) -> 12 | AK31: =COUNTA(E32:AI32) -> 0 | AL31: =COUNTA(E31:AI32) -> 12
A33: 16 | B33: ตราด | C33: ✔ | I33: ✔ | L33: ✔ | S33: ✔ | AD33: ✔ | AJ33: =COUNTA(E33:AI33) -> 4 | AK33: =COUNTA(E34:AI34) -> 0 | AL33: =COUNTA(E33:AI34) -> 4
A35: 17 | B35: คลองใหญ่ | C35: ✔ | I35: ✔ | S35: ✔ | AJ35: =COUNTA(E35:AI35) -> 2 | AK35: =COUNTA(E36:AI36) -> 0 | AL35: =COUNTA(E35:AI36) -> 2
A37: 18 | B37: สระแก้ว | C37: ✔ | K37: ✔ | S37: ✔ | AJ37: =COUNTA(E37:AI37) -> 2 | AK37: =COUNTA(E38:AI38) -> 0 | AL37: =COUNTA(E37:AI38) -> 2
A39: 19 | B39: วัฒนานคร | C39: ✔ | K39: ✔ | S39: ✔ | Z39: ✔ | AA39: ✔ | AD39: ✔ | AH39: ✔ | AJ39: =COUNTA(E39:AI39) -> 6 | AK39: =COUNTA(E40:AI40) -> 0 | AL39: =COUNTA(E39:AI40) -> 6
A41: 20 | B41: อรัญประเทศ | C41: ✔ | S41: ✔ | AJ41: =COUNTA(E41:AI41) -> 1 | AK41: =COUNTA(E42:AI42) -> 0 | AL41: =COUNTA(E41:AI42) -> 1
A43: 21 | B43: ปราจีนบุรี | C43: ✔ | K43: ✔ | S43: ✔ | AE43: ✔ | AJ43: =COUNTA(E43:AI43) -> 3 | AK43: =COUNTA(E44:AI44) -> 0 | AL43: =COUNTA(E43:AI44) -> 3
A45: 22 | B45: กบินทร์บุรี | C45: ✔ | J45: ✔ | S45: ✔ | AD45: ✔ | AJ45: =COUNTA(E45:AI45) -> 3 | AK45: =COUNTA(E46:AI46) -> 0 | AL45: =COUNTA(E45:AI46) -> 3
B48: * หมายเหตุ | C48: ✔ | D48: กิจกรรมลดน้ำสูญเสียเชิงกายภาพ
C49: ⭕ | D49: กิจกรรมลดน้ำสูญเสียเชิงพาณิชย์

Sheet ก.พ.69
A1: ลำดับ | B1: กปภ. สาขา | C1: กิจกรรมลดน้ำสูญเสีย | E1: วันที่ดำเนินกิจกรรมในเดือนกุมภาพันธ์ 2569 | AG1: เชิงกายภาพ (ครั้ง) | AH1: เชิงพาณิชย์ (ครั้ง) | AI1: รวมทั้งหมด (ครั้ง)
C2: เชิงกายภาพ | D2: เชิงพาณิชย์ | E2: 1 | F2: 2 | G2: 3 | H2: 4 | I2: 5 | J2: 6 | K2: 7 | L2: 8 | M2: 9 | N2: 10 | O2: 11 | P2: 12 | Q2: 13 | R2: 14 | S2: 15 | T2: 16 | U2: 17 | V2: 18 | W2: 19 | X2: 20 | Y2: 21 | Z2: 22 | AA2: 23 | AB2: 24 | AC2: 25 | AD2: 26 | AE2: 27 | AF2: 28
A3: 1 | B3: ชลบุรี(พิเศษ) | C3: ✔ | D3: ⭕ | F3: ✔ | G3: ✔ | H3: ✔ | M3: ✔ | Q3: ✔ | R3: ✔ | S3: ✔ | T3: ✔ | U3: ✔ | V3: ✔ | W3: ✔ | X3: ✔ | AG3: =COUNTA(E3:AF3) -> 12 | AH3: =COUNTA(E4:AF4) -> 5 | AI3: =COUNTA(E3:AF4) -> 17
F4: ⭕ | Q4: ⭕ | R4: ⭕ | V4: ⭕ | X4: ⭕
A5: 2 | B5: พัทยา(พิเศษ) | C5: ✔ | P5: ✔ | U5: ✔ | V5: ✔ | X5: ✔ | AA5: ✔ | AE5: ✔ | AG5: =COUNTA(E5:AF5) -> 6 | AH5: =COUNTA(E6:AF6) -> 0 | AI5: =COUNTA(E5:AF6) -> 6
A7: 3 | B7: บ้านบึง | C7: ✔ | M7: ✔ | O7: ✔ | AG7: =COUNTA(E7:AF7) -> 2 | AH7: =COUNTA(E8:AF8) -> 0 | AI7: =COUNTA(E7:AF8) -> 2
A9: 4 | B9: พนัสนิคม | C9: ✔ | G9: ✔ | M9: ✔ | AD9: ✔ | AG9: =COUNTA(E9:AF9) -> 3 | AH9: =COUNTA(E10:AF10) -> 0 | AI9: =COUNTA(E9:AF10) -> 3
A11: 5 | B11: ศรีราชา | C11: ✔ | G11: ✔ | U11: ✔ | AG11: =COUNTA(E11:AF11) -> 2 | AH11: =COUNTA(E12:AF12) -> 0 | AI11: =COUNTA(E11:AF12) -> 2
A13: 6 | B13: แหลมฉบัง | C13: ✔ | I13: ✔ | N13: ✔ | O13: ✔ | U13: ✔ | V13: ✔ | AD13: ✔ | AE13: ✔ | AG13: =COUNTA(E13:AF13) -> 7 | AH13: =COUNTA(E14:AF14) -> 2 | AI13: =COUNTA(E13:AF14) -> 9
AD14: ⭕ | AE14: ⭕
A15: 7 | B15: ฉะเชิงเทรา | C15: ✔ | T15: ✔ | W15: ✔ | AB15: ✔ | AD15: ✔ | AG15: =COUNTA(E15:AF15) -> 4 | AH15: =COUNTA(E16:AF16) -> 0 | AI15: =COUNTA(E15:AF16) -> 4
A17: 8 | B17: บางปะกง | C17: ✔ | Q17: ✔ | AE17: ✔ | AG17: =COUNTA(E17:AF17) -> 2 | AH17: =COUNTA(E18:AF18) -> 0 | AI17: =COUNTA(E17:AF18) -> 2
A19: 9 | B19: บางคล้า | C19: ✔ | G19: ✔ | AG19: =COUNTA(E19:AF19) -> 1 | AH19: =COUNTA(E20:AF20) -> 0 | AI19: =COUNTA(E19:AF20) -> 1
A21: 10 | B21: พนมสารคาม | C21: ✔ | D21: ⭕ | F21: ✔ | H21: ✔ | O21: ✔ | P21: ✔ | U21: ✔ | AG21: =COUNTA(E21:AF21) -> 5 | AH21: =COUNTA(E22:AF22) -> 2 | AI21: =COUNTA(E21:AF22) -> 7
O22: ⭕ | AA22: ⭕
A23: 11 | B23: ระยอง | C23: ✔ | G23: ✔ | I23: ✔ | J23: ✔ | K23: ✔ | N23: ✔ | O23: ✔ | P23: ✔ | Q23: ✔ | R23: ✔ | S23: ✔ | U23: ✔ | V23: ✔ | X23: ✔ | Y23: ✔ | Z23: ✔ | AB23: ✔ | AC23: ✔ | AF23: ✔ | AG23: =COUNTA(E23:AF23) -> 18 | AH23: =COUNTA(E24:AF24) -> 0 | AI23: =COUNTA(E23:AF24) -> 18
A25: 12 | B25: บ้านฉาง | C25: ✔ | F25: ✔ | AG25: =COUNTA(E25:AF25) -> 1 | AH25: =COUNTA(E26:AF26) -> 0 | AI25: =COUNTA(E25:AF26) -> 1
A27: 13 | B27: ปากน้ำประแสร์ | C27: ✔ | N27: ✔ | O27: ✔ | P27: ✔ | V27: ✔ | AA27: ✔ | AB27: ✔ | AG27: =COUNTA(E27:AF27) -> 6 | AH27: =COUNTA(E28:AF28) -> 0 | AI27: =COUNTA(E27:AF28) -> 6
A29: 14 | B29: จันทบุรี | C29: ✔ | M29: ✔ | P29: ✔ | Q29: ✔ | V29: ✔ | W29: ✔ | AA29: ✔ | AB29: ✔ | AC29: ✔ | AD29: ✔ | AE29: ✔ | AG29: =COUNTA(E29:AF29) -> 10 | AH29: =COUNTA(E30:AF30) -> 0 | AI29: =COUNTA(E29:AF30) -> 10
A31: 15 | B31: ขลุง | C31: ✔ | F31: ✔ | H31: ✔ | M31: ✔ | T31: ✔ | U31: ✔ | AG31: =COUNTA(E31:AF31) -> 5 | AH31: =COUNTA(E32:AF32) -> 0 | AI31: =COUNTA(E31:AF32) -> 5
A33: 16 | B33: ตราด | C33: ✔ | F33: ✔ | N33: ✔ | Y33: ✔ | AG33: =COUNTA(E33:AF33) -> 3 | AH33: =COUNTA(E34:AF34) -> 0 | AI33: =COUNTA(E33:AF34) -> 3
A35: 17 | B35: คลองใหญ่ | C35: ✔ | I35: ✔ | O35: ✔ | AG35: =COUNTA(E35:AF35) -> 2 | AH35: =COUNTA(E36:AF36) -> 0 | AI35: =COUNTA(E35:AF36) -> 2
A37: 18 | B37: สระแก้ว | C37: ✔ | F37: ✔ | G37: ✔ | H37: ✔ | I37: ✔ | J37: ✔ | AE37: ✔ | AG37: =COUNTA(E37:AF37) -> 6 | AH37: =COUNTA(E38:AF38) -> 0 | AI37: =COUNTA(E37:AF38) -> 6
A39: 19 | B39: วัฒนานคร | C39: ✔ | D39: ⭕ | G39: ✔ | P39: ✔ | T39: ✔ | U39: ✔ | V39: ✔ | X39: ✔ | AB39: ✔ | AE39: ✔ | AG39: =COUNTA(E39:AF39) -> 8 | AH39: =COUNTA(E40:AF40) -> 1 | AI39: =COUNTA(E39:AF40) -> 9
M40: ⭕
A41: 20 | B41: อรัญประเทศ | C41: ✔ | H41: ✔ | P41: ✔ | W41: ✔ | AG41: =COUNTA(E41:AF41) -> 3 | AH41: =COUNTA(E42:AF42) -> 0 | AI41: =COUNTA(E41:AF42) -> 3
A43: 21 | B43: ปราจีนบุรี | C43: ✔ | G43: ✔ | H43: ✔ | I43: ✔ | J43: ✔ | K43: ✔ | L43: ✔ | M43: ✔ | N43: ✔ | O43: ✔ | T43: ✔ | U43: ✔ | V43: ✔ | W43: ✔ | X43: ✔ | Y43: ✔ | Z43: ✔ | AA43: ✔ | AB43: ✔ | AC43: ✔ | AD43: ✔ | AE43: ✔ | AF43: ✔ | AG43: =COUNTA(E43:AF43) -> 22 | AH43: =COUNTA(E44:AF44) -> 0 | AI43: =COUNTA(E43:AF44) -> 22
A45: 22 | B45: กบินทร์บุรี | C45: ✔ | H45: ✔ | T45: ✔ | AB45: ✔ | AG45: =COUNTA(E45:AF45) -> 3 | AH45: =COUNTA(E46:AF46) -> 0 | AI45: =COUNTA(E45:AF46) -> 3
B48: * หมายเหตุ | C48: ✔ | D48: กิจกรรมลดน้ำสูญเสียเชิงกายภาพ
C49: ⭕ | D49: กิจกรรมลดน้ำสูญเสียเชิงพาณิชย์

Sheet มี.ค.69
A1: ลำดับ | B1: กปภ. สาขา | C1: กิจกรรมลดน้ำสูญเสีย | E1: วันที่ดำเนินกิจกรรมในเดือนมีนาคม 2569 | AJ1: เชิงกายภาพ (ครั้ง) | AK1: เชิงพาณิชย์ (ครั้ง) | AL1: รวมทั้งหมด (ครั้ง)
C2: เชิงกายภาพ | D2: เชิงพาณิชย์ | E2: 1 | F2: 2 | G2: 3 | H2: 4 | I2: 5 | J2: 6 | K2: 7 | L2: 8 | M2: 9 | N2: 10 | O2: 11 | P2: 12 | Q2: 13 | R2: 14 | S2: 15 | T2: 16 | U2: 17 | V2: 18 | W2: 19 | X2: 20 | Y2: 21 | Z2: 22 | AA2: 23 | AB2: 24 | AC2: 25 | AD2: 26 | AE2: 27 | AF2: 28 | AG2: 29 | AH2: 30 | AI2: 31
A3: 1 | B3: ชลบุรี(พิเศษ) | C3: ✔ | D3: ⭕ | E3: ✔ | F3: ✔ | H3: ✔ | I3: ✔ | M3: ✔ | N3: ✔ | O3: ✔ | Q3: ✔ | R3: ✔ | S3: ✔ | T3: ✔ | AJ3: =COUNTA(E3:AI3) -> 11 | AK3: =COUNTA(E4:AI4) -> 6 | AL3: =COUNTA(E3:AI4) -> 17
E4: ⭕ | F4: ⭕ | H4: ⭕ | O4: ⭕ | Q4: ⭕ | T4: ⭕
A5: 2 | B5: พัทยา(พิเศษ) | C5: ✔ | D5: ⭕ | F5: ✔ | I5: ✔ | K5: ✔ | M5: ✔ | O5: ✔ | T5: ✔ | AJ5: =COUNTA(E5:AI5) -> 6 | AK5: =COUNTA(E6:AI6) -> 1 | AL5: =COUNTA(E5:AI6) -> 7
P6: ⭕
A7: 3 | B7: บ้านบึง | C7: ✔ | I7: ✔ | AJ7: =COUNTA(E7:AI7) -> 1 | AK7: =COUNTA(E8:AI8) -> 0 | AL7: =COUNTA(E7:AI8) -> 1
A9: 4 | B9: พนัสนิคม | C9: ✔ | L9: ✔ | AJ9: =COUNTA(E9:AI9) -> 1 | AK9: =COUNTA(E10:AI10) -> 0 | AL9: =COUNTA(E9:AI10) -> 1
A11: 5 | B11: ศรีราชา | C11: ✔ | H11: ✔ | J11: ✔ | O11: ✔ | AJ11: =COUNTA(E11:AI11) -> 3 | AK11: =COUNTA(E12:AI12) -> 0 | AL11: =COUNTA(E11:AI12) -> 3
A13: 6 | B13: แหลมฉบัง | C13: ✔ | D13: ⭕ | P13: ✔ | AJ13: =COUNTA(E13:AI13) -> 1 | AK13: =COUNTA(E14:AI14) -> 1 | AL13: =COUNTA(E13:AI14) -> 2
P14: ⭕
A15: 7 | B15: ฉะเชิงเทรา | C15: ✔ | D15: ⭕ | I15: ✔ | AJ15: =COUNTA(E15:AI15) -> 1 | AK15: =COUNTA(E16:AI16) -> 1 | AL15: =COUNTA(E15:AI16) -> 2
M16: ⭕
A17: 8 | B17: บางปะกง | C17: ✔ | J17: ✔ | Q17: ✔ | AJ17: =COUNTA(E17:AI17) -> 2 | AK17: =COUNTA(E18:AI18) -> 0 | AL17: =COUNTA(E17:AI18) -> 2
A19: 9 | B19: บางคล้า | C19: ✔ | F19: ✔ | M19: ✔ | AJ19: =COUNTA(E19:AI19) -> 2 | AK19: =COUNTA(E20:AI20) -> 0 | AL19: =COUNTA(E19:AI20) -> 2
A21: 10 | B21: พนมสารคาม | AJ21: =COUNTA(E21:AI21) -> 0 | AK21: =COUNTA(E22:AI22) -> 0 | AL21: =COUNTA(E21:AI22) -> 0
A23: 11 | B23: ระยอง | C23: ✔ | E23: ✔ | G23: ✔ | I23: ✔ | J23: ✔ | K23: ✔ | L23: ✔ | N23: ✔ | O23: ✔ | P23: ✔ | R23: ✔ | U23: ✔ | AJ23: =COUNTA(E23:AI23) -> 11 | AK23: =COUNTA(E24:AI24) -> 0 | AL23: =COUNTA(E23:AI24) -> 11
A25: 12 | B25: บ้านฉาง | C25: ✔ | I25: ✔ | AJ25: =COUNTA(E25:AI25) -> 1 | AK25: =COUNTA(E26:AI26) -> 0 | AL25: =COUNTA(E25:AI26) -> 1
A27: 13 | B27: ปากน้ำประแสร์ | AJ27: =COUNTA(E27:AI27) -> 0 | AK27: =COUNTA(E28:AI28) -> 0 | AL27: =COUNTA(E27:AI28) -> 0
A29: 14 | B29: จันทบุรี | C29: ✔ | I29: ✔ | J29: ✔ | M29: ✔ | N29: ✔ | O29: ✔ | P29: ✔ | Q29: ✔ | T29: ✔ | AJ29: =COUNTA(E29:AI29) -> 8 | AK29: =COUNTA(E30:AI30) -> 0 | AL29: =COUNTA(E29:AI30) -> 8
A31: 15 | B31: ขลุง | C31: ✔ | D31: ⭕ | N31: ✔ | P31: ✔ | AJ31: =COUNTA(E31:AI31) -> 2 | AK31: =COUNTA(E32:AI32) -> 1 | AL31: =COUNTA(E31:AI32) -> 3
Q32: ⭕
A33: 16 | B33: ตราด | C33: ✔ | P33: ✔ | AJ33: =COUNTA(E33:AI33) -> 1 | AK33: =COUNTA(E34:AI34) -> 0 | AL33: =COUNTA(E33:AI34) -> 1
A35: 17 | B35: คลองใหญ่ | C35: ✔ | O35: ✔ | P35: ✔ | AJ35: =COUNTA(E35:AI35) -> 2 | AK35: =COUNTA(E36:AI36) -> 0 | AL35: =COUNTA(E35:AI36) -> 2
A37: 18 | B37: สระแก้ว | C37: ✔ | D37: ⭕ | F37: ✔ | G37: ✔ | H37: ✔ | I37: ✔ | J37: ✔ | K37: ✔ | L37: ✔ | M37: ✔ | N37: ✔ | O37: ✔ | P37: ✔ | Q37: ✔ | AJ37: =COUNTA(E37:AI37) -> 12 | AK37: =COUNTA(E38:AI38) -> 12 | AL37: =COUNTA(E37:AI38) -> 24
F38: ⭕ | G38: ⭕ | H38: ⭕ | I38: ⭕ | J38: ⭕ | K38: ⭕ | L38: ⭕ | M38: ⭕ | N38: ⭕ | O38: ⭕ | P38: ⭕ | Q38: ⭕
A39: 19 | B39: วัฒนานคร | C39: ✔ | D39: ⭕ | F39: ✔ | I39: ✔ | M39: ✔ | N39: ✔ | P39: ✔ | T39: ✔ | AJ39: =COUNTA(E39:AI39) -> 6 | AK39: =COUNTA(E40:AI40) -> 1 | AL39: =COUNTA(E39:AI40) -> 7
T40: ⭕
A41: 20 | B41: อรัญประเทศ | AJ41: =COUNTA(E41:AI41) -> 0 | AK41: =COUNTA(E42:AI42) -> 0 | AL41: =COUNTA(E41:AI42) -> 0
A43: 21 | B43: ปราจีนบุรี | C43: ✔ | E43: ✔ | F43: ✔ | G43: ✔ | H43: ✔ | I43: ✔ | J43: ✔ | N43: ✔ | AJ43: =COUNTA(E43:AI43) -> 7 | AK43: =COUNTA(E44:AI44) -> 0 | AL43: =COUNTA(E43:AI44) -> 7
A45: 22 | B45: กบินทร์บุรี | AJ45: =COUNTA(E45:AI45) -> 0 | AK45: =COUNTA(E46:AI46) -> 0 | AL45: =COUNTA(E45:AI46) -> 0
B48: * หมายเหตุ | C48: ✔ | D48: กิจกรรมลดน้ำสูญเสียเชิงกายภาพ
C49: ⭕ | D49: กิจกรรมลดน้ำสูญเสียเชิงพาณิชย์

Sheet เม.ย.69
A1: ลำดับ | B1: กปภ. สาขา | C1: กิจกรรมลดน้ำสูญเสีย | E1: วันที่ดำเนินกิจกรรมในเดือนเมษายน 2569 | AI1: เชิงกายภาพ (ครั้ง) | AJ1: เชิงพาณิชย์ (ครั้ง) | AK1: รวมทั้งหมด (ครั้ง)
C2: เชิงกายภาพ | D2: เชิงพาณิชย์ | E2: 1 | F2: 2 | G2: 3 | H2: 4 | I2: 5 | J2: 6 | K2: 7 | L2: 8 | M2: 9 | N2: 10 | O2: 11 | P2: 12 | Q2: 13 | R2: 14 | S2: 15 | T2: 16 | U2: 17 | V2: 18 | W2: 19 | X2: 20 | Y2: 21 | Z2: 22 | AA2: 23 | AB2: 24 | AC2: 25 | AD2: 26 | AE2: 27 | AF2: 28 | AG2: 29 | AH2: 30
A3: 1 | B3: ชลบุรี(พิเศษ) | AI3: =COUNTA(E3:AH3) -> 0 | AJ3: =COUNTA(E4:AH4) -> 0 | AK3: =COUNTA(E3:AH4) -> 0
A5: 2 | B5: พัทยา(พิเศษ) | AI5: =COUNTA(E5:AH5) -> 0 | AJ5: =COUNTA(E6:AH6) -> 0 | AK5: =COUNTA(E5:AH6) -> 0
A7: 3 | B7: บ้านบึง | AI7: =COUNTA(E7:AH7) -> 0 | AJ7: =COUNTA(E8:AH8) -> 0 | AK7: =COUNTA(E7:AH8) -> 0
A9: 4 | B9: พนัสนิคม | AI9: =COUNTA(E9:AH9) -> 0 | AJ9: =COUNTA(E10:AH10) -> 0 | AK9: =COUNTA(E9:AH10) -> 0
A11: 5 | B11: ศรีราชา | AI11: =COUNTA(E11:AH11) -> 0 | AJ11: =COUNTA(E12:AH12) -> 0 | AK11: =COUNTA(E11:AH12) -> 0
A13: 6 | B13: แหลมฉบัง | AI13: =COUNTA(E13:AH13) -> 0 | AJ13: =COUNTA(E14:AH14) -> 0 | AK13: =COUNTA(E13:AH14) -> 0
A15: 7 | B15: ฉะเชิงเทรา | AI15: =COUNTA(E15:AH15) -> 0 | AJ15: =COUNTA(E16:AH16) -> 0 | AK15: =COUNTA(E15:AH16) -> 0
A17: 8 | B17: บางปะกง | AI17: =COUNTA(E17:AH17) -> 0 | AJ17: =COUNTA(E18:AH18) -> 0 | AK17: =COUNTA(E17:AH18) -> 0
A19: 9 | B19: บางคล้า | AI19: =COUNTA(E19:AH19) -> 0 | AJ19: =COUNTA(E20:AH20) -> 0 | AK19: =COUNTA(E19:AH20) -> 0
A21: 10 | B21: พนมสารคาม | AI21: =COUNTA(E21:AH21) -> 0 | AJ21: =COUNTA(E22:AH22) -> 0 | AK21: =COUNTA(E21:AH22) -> 0
A23: 11 | B23: ระยอง | AI23: =COUNTA(E23:AH23) -> 0 | AJ23: =COUNTA(E24:AH24) -> 0 | AK23: =COUNTA(E23:AH24) -> 0
A25: 12 | B25: บ้านฉาง | AI25: =COUNTA(E25:AH25) -> 0 | AJ25: =COUNTA(E26:AH26) -> 0 | AK25: =COUNTA(E25:AH26) -> 0
... A45: 22 | B45: กบินทร์บุรี | AI45: =COUNTA(E45:AH45) -> 0 | AJ45: =COUNTA(E46:AH46) -> 0 | AK45: =COUNTA(E45:AH46) -> 0
B48: * หมายเหตุ | C48: ✔ | D48: กิจกรรมลดน้ำสูญเสียเชิงกายภาพ
C49: ⭕ | D49: กิจกรรมลดน้ำสูญเสียเชิงพาณิชย์

Sheet พ.ค.69
A1: ลำดับ | B1: กปภ. สาขา | C1: กิจกรรมลดน้ำสูญเสีย | E1: วันที่ดำเนินกิจกรรมในเดือนพฤษภาคม 2569 | AJ1: เชิงกายภาพ (ครั้ง) | AK1: เชิงพาณิชย์ (ครั้ง) | AL1: รวมทั้งหมด (ครั้ง)
C2: เชิงกายภาพ | D2: เชิงพาณิชย์ | E2: 1 | F2: 2 | G2: 3 | H2: 4 | I2: 5 | J2: 6 | K2: 7 | L2: 8 | M2: 9 | N2: 10 | O2: 11 | P2: 12 | Q2: 13 | R2: 14 | S2: 15 | T2: 16 | U2: 17 | V2: 18 | W2: 19 | X2: 20 | Y2: 21 | Z2: 22 | AA2: 23 | AB2: 24 | AC2: 25 | AD2: 26 | AE2: 27 | AF2: 28 | AG2: 29 | AH2: 30 | AI2: 31
A3: 1 | B3: ชลบุรี(พิเศษ) | AJ3: =COUNTA(E3:AI3) -> 0 | AK3: =COUNTA(E4:AI4) -> 0 | AL3: =COUNTA(E3:AI4) -> 0
A5: 2 | B5: พัทยา(พิเศษ) | AJ5: =COUNTA(E5:AI5) -> 0 | AK5: =COUNTA(E6:AI6) -> 0 | AL5: =COUNTA(E5:AI6) -> 0
A7: 3 | B7: บ้านบึง | AJ7: =COUNTA(E7:AI7) -> 0 | AK7: =COUNTA(E8:AI8) -> 0 | AL7: =COUNTA(E7:AI8) -> 0
A9: 4 | B9: พนัสนิคม | AJ9: =COUNTA(E9:AI9) -> 0 | AK9: =COUNTA(E10:AI10) -> 0 | AL9: =COUNTA(E9:AI10) -> 0
A11: 5 | B11: ศรีราชา | AJ11: =COUNTA(E11:AI11) -> 0 | AK11: =COUNTA(E12:AI12) -> 0 | AL11: =COUNTA(E11:AI12) -> 0
A13: 6 | B13: แหลมฉบัง | AJ13: =COUNTA(E13:AI13) -> 0 | AK13: =COUNTA(E14:AI14) -> 0 | AL13: =COUNTA(E13:AI14) -> 0
A15: 7 | B15: ฉะเชิงเทรา | AJ15: =COUNTA(E15:AI15) -> 0 | AK15: =COUNTA(E16:AI16) -> 0 | AL15: =COUNTA(E15:AI16) -> 0
A17: 8 | B17: บางปะกง | AJ17: =COUNTA(E17:AI17) -> 0 | AK17: =COUNTA(E18:AI18) -> 0 | AL17: =COUNTA(E17:AI18) -> 0
A19: 9 | B19: บางคล้า | AJ19: =COUNTA(E19:AI19) -> 0 | AK19: =COUNTA(E20:AI20) -> 0 | AL19: =COUNTA(E19:AI20) -> 0
A21: 10 | B21: พนมสารคาม | AJ21: =COUNTA(E21:AI21) -> 0 | AK21: =COUNTA(E22:AI22) -> 0 | AL21: =COUNTA(E21:AI22) -> 0
A23: 11 | B23: ระยอง | AJ23: =COUNTA(E23:AI23) -> 0 | AK23: =COUNTA(E24:AI24) -> 0 | AL23: =COUNTA(E23:AI24) -> 0
A25: 12 | B25: บ้านฉาง | AJ25: =COUNTA(E25:AI25) -> 0 | AK25: =COUNTA(E26:AI26) -> 0 | AL25: =COUNTA(E25:AI26) -> 0
... A45: 22 | B45: กบินทร์บุรี | AJ45: =COUNTA(E45:AI45) -> 0 | AK45: =COUNTA(E46:AI46) -> 0 | AL45: =COUNTA(E45:AI46) -> 0
B48: * หมายเหตุ | C48: ✔ | D48: กิจกรรมลดน้ำสูญเสียเชิงกายภาพ
C49: ⭕ | D49: กิจกรรมลดน้ำสูญเสียเชิงพาณิชย์

Sheet มิ.ย.69
A1: ลำดับ | B1: กปภ. สาขา | C1: กิจกรรมลดน้ำสูญเสีย | E1: วันที่ดำเนินกิจกรรมในเดือนมิถุนายน 2569 | AI1: เชิงกายภาพ (ครั้ง) | AJ1: เชิงพาณิชย์ (ครั้ง) | AK1: รวมทั้งหมด (ครั้ง)
C2: เชิงกายภาพ | D2: เชิงพาณิชย์ | E2: 1 | F2: 2 | G2: 3 | H2: 4 | I2: 5 | J2: 6 | K2: 7 | L2: 8 | M2: 9 | N2: 10 | O2: 11 | P2: 12 | Q2: 13 | R2: 14 | S2: 15 | T2: 16 | U2: 17 | V2: 18 | W2: 19 | X2: 20 | Y2: 21 | Z2: 22 | AA2: 23 | AB2: 24 | AC2: 25 | AD2: 26 | AE2: 27 | AF2: 28 | AG2: 29 | AH2: 30
A3: 1 | B3: ชลบุรี(พิเศษ) | AI3: =COUNTA(E3:AH3) -> 0 | AJ3: =COUNTA(E4:AH4) -> 0 | AK3: =COUNTA(E3:AH4) -> 0
A5: 2 | B5: พัทยา(พิเศษ) | AI5: =COUNTA(E5:AH5) -> 0 | AJ5: =COUNTA(E6:AH6) -> 0 | AK5: =COUNTA(E5:AH6) -> 0
A7: 3 | B7: บ้านบึง | AI7: =COUNTA(E7:AH7) -> 0 | AJ7: =COUNTA(E8:AH8) -> 0 | AK7: =COUNTA(E7:AH8) -> 0
A9: 4 | B9: พนัสนิคม | AI9: =COUNTA(E9:AH9) -> 0 | AJ9: =COUNTA(E10:AH10) -> 0 | AK9: =COUNTA(E9:AH10) -> 0
A11: 5 | B11: ศรีราชา | AI11: =COUNTA(E11:AH11) -> 0 | AJ11: =COUNTA(E12:AH12) -> 0 | AK11: =COUNTA(E11:AH12) -> 0
A13: 6 | B13: แหลมฉบัง | AI13: =COUNTA(E13:AH13) -> 0 | AJ13: =COUNTA(E14:AH14) -> 0 | AK13: =COUNTA(E13:AH14) -> 0
A15: 7 | B15: ฉะเชิงเทรา | AI15: =COUNTA(E15:AH15) -> 0 | AJ15: =COUNTA(E16:AH16) -> 0 | AK15: =COUNTA(E15:AH16) -> 0
A17: 8 | B17: บางปะกง | AI17: =COUNTA(E17:AH17) -> 0 | AJ17: =COUNTA(E18:AH18) -> 0 | AK17: =COUNTA(E17:AH18) -> 0
A19: 9 | B19: บางคล้า | AI19: =COUNTA(E19:AH19) -> 0 | AJ19: =COUNTA(E20:AH20) -> 0 | AK19: =COUNTA(E19:AH20) -> 0
A21: 10 | B21: พนมสารคาม | AI21: =COUNTA(E21:AH21) -> 0 | AJ21: =COUNTA(E22:AH22) -> 0 | AK21: =COUNTA(E21:AH22) -> 0
A23: 11 | B23: ระยอง | AI23: =COUNTA(E23:AH23) -> 0 | AJ23: =COUNTA(E24:AH24) -> 0 | AK23: =COUNTA(E23:AH24) -> 0
A25: 12 | B25: บ้านฉาง | AI25: =COUNTA(E25:AH25) -> 0 | AJ25: =COUNTA(E26:AH26) -> 0 | AK25: =COUNTA(E25:AH26) -> 0
... A45: 22 | B45: กบินทร์บุรี | AI45: =COUNTA(E45:AH45) -> 0 | AJ45: =COUNTA(E46:AH46) -> 0 | AK45: =COUNTA(E45:AH46) -> 0
B48: * หมายเหตุ | C48: ✔ | D48: กิจกรรมลดน้ำสูญเสียเชิงกายภาพ
C49: ⭕ | D49: กิจกรรมลดน้ำสูญเสียเชิงพาณิชย์

Sheet ก.ค.69
A1: ลำดับ | B1: กปภ. สาขา | C1: กิจกรรมลดน้ำสูญเสีย | E1: วันที่ดำเนินกิจกรรมในเดือนกรกฎาคม 2569 | AJ1: เชิงกายภาพ (ครั้ง) | AK1: เชิงพาณิชย์ (ครั้ง) | AL1: รวมทั้งหมด (ครั้ง)
C2: เชิงกายภาพ | D2: เชิงพาณิชย์ | E2: 1 | F2: 2 | G2: 3 | H2: 4 | I2: 5 | J2: 6 | K2: 7 | L2: 8 | M2: 9 | N2: 10 | O2: 11 | P2: 12 | Q2: 13 | R2: 14 | S2: 15 | T2: 16 | U2: 17 | V2: 18 | W2: 19 | X2: 20 | Y2: 21 | Z2: 22 | AA2: 23 | AB2: 24 | AC2: 25 | AD2: 26 | AE2: 27 | AF2: 28 | AG2: 29 | AH2: 30 | AI2: 31
A3: 1 | B3: ชลบุรี(พิเศษ) | AJ3: =COUNTA(E3:AI3) -> 0 | AK3: =COUNTA(E4:AI4) -> 0 | AL3: =COUNTA(E3:AI4) -> 0
A5: 2 | B5: พัทยา(พิเศษ) | AJ5: =COUNTA(E5:AI5) -> 0 | AK5: =COUNTA(E6:AI6) -> 0 | AL5: =COUNTA(E5:AI6) -> 0
A7: 3 | B7: บ้านบึง | AJ7: =COUNTA(E7:AI7) -> 0 | AK7: =COUNTA(E8:AI8) -> 0 | AL7: =COUNTA(E7:AI8) -> 0
A9: 4 | B9: พนัสนิคม | AJ9: =COUNTA(E9:AI9) -> 0 | AK9: =COUNTA(E10:AI10) -> 0 | AL9: =COUNTA(E9:AI10) -> 0
A11: 5 | B11: ศรีราชา | AJ11: =COUNTA(E11:AI11) -> 0 | AK11: =COUNTA(E12:AI12) -> 0 | AL11: =COUNTA(E11:AI12) -> 0
A13: 6 | B13: แหลมฉบัง | AJ13: =COUNTA(E13:AI13) -> 0 | AK13: =COUNTA(E14:AI14) -> 0 | AL13: =COUNTA(E13:AI14) -> 0
A15: 7 | B15: ฉะเชิงเทรา | AJ15: =COUNTA(E15:AI15) -> 0 | AK15: =COUNTA(E16:AI16) -> 0 | AL15: =COUNTA(E15:AI16) -> 0
A17: 8 | B17: บางปะกง | AJ17: =COUNTA(E17:AI17) -> 0 | AK17: =COUNTA(E18:AI18) -> 0 | AL17: =COUNTA(E17:AI18) -> 0
A19: 9 | B19: บางคล้า | AJ19: =COUNTA(E19:AI19) -> 0 | AK19: =COUNTA(E20:AI20) -> 0 | AL19: =COUNTA(E19:AI20) -> 0
A21: 10 | B21: พนมสารคาม | AJ21: =COUNTA(E21:AI21) -> 0 | AK21: =COUNTA(E22:AI22) -> 0 | AL21: =COUNTA(E21:AI22) -> 0
A23: 11 | B23: ระยอง | AJ23: =COUNTA(E23:AI23) -> 0 | AK23: =COUNTA(E24:AI24) -> 0 | AL23: =COUNTA(E23:AI24) -> 0
A25: 12 | B25: บ้านฉาง | AJ25: =COUNTA(E25:AI25) -> 0 | AK25: =COUNTA(E26:AI26) -> 0 | AL25: =COUNTA(E25:AI26) -> 0
... A45: 22 | B45: กบินทร์บุรี | AJ45: =COUNTA(E45:AI45) -> 0 | AK45: =COUNTA(E46:AI46) -> 0 | AL45: =COUNTA(E45:AI46) -> 0
B48: * หมายเหตุ | C48: ✔ | D48: กิจกรรมลดน้ำสูญเสียเชิงกายภาพ
C49: ⭕ | D49: กิจกรรมลดน้ำสูญเสียเชิงพาณิชย์

Sheet ส.ค.69
A1: ลำดับ | B1: กปภ. สาขา | C1: กิจกรรมลดน้ำสูญเสีย | E1: วันที่ดำเนินกิจกรรมในเดือนสิงหาคม 2569 | AJ1: เชิงกายภาพ (ครั้ง) | AK1: เชิงพาณิชย์ (ครั้ง) | AL1: รวมทั้งหมด (ครั้ง)
C2: เชิงกายภาพ | D2: เชิงพาณิชย์ | E2: 1 | F2: 2 | G2: 3 | H2: 4 | I2: 5 | J2: 6 | K2: 7 | L2: 8 | M2: 9 | N2: 10 | O2: 11 | P2: 12 | Q2: 13 | R2: 14 | S2: 15 | T2: 16 | U2: 17 | V2: 18 | W2: 19 | X2: 20 | Y2: 21 | Z2: 22 | AA2: 23 | AB2: 24 | AC2: 25 | AD2: 26 | AE2: 27 | AF2: 28 | AG2: 29 | AH2: 30 | AI2: 31
A3: 1 | B3: ชลบุรี(พิเศษ) | AJ3: =COUNTA(E3:AI3) -> 0 | AK3: =COUNTA(E4:AI4) -> 0 | AL3: =COUNTA(E3:AI4) -> 0
A5: 2 | B5: พัทยา(พิเศษ) | AJ5: =COUNTA(E5:AI5) -> 0 | AK5: =COUNTA(E6:AI6) -> 0 | AL5: =COUNTA(E5:AI6) -> 0
A7: 3 | B7: บ้านบึง | AJ7: =COUNTA(E7:AI7) -> 0 | AK7: =COUNTA(E8:AI8) -> 0 | AL7: =COUNTA(E7:AI8) -> 0
A9: 4 | B9: พนัสนิคม | AJ9: =COUNTA(E9:AI9) -> 0 | AK9: =COUNTA(E10:AI10) -> 0 | AL9: =COUNTA(E9:AI10) -> 0
A11: 5 | B11: ศรีราชา | AJ11: =COUNTA(E11:AI11) -> 0 | AK11: =COUNTA(E12:AI12) -> 0 | AL11: =COUNTA(E11:AI12) -> 0
A13: 6 | B13: แหลมฉบัง | AJ13: =COUNTA(E13:AI13) -> 0 | AK13: =COUNTA(E14:AI14) -> 0 | AL13: =COUNTA(E13:AI14) -> 0
A15: 7 | B15: ฉะเชิงเทรา | AJ15: =COUNTA(E15:AI15) -> 0 | AK15: =COUNTA(E16:AI16) -> 0 | AL15: =COUNTA(E15:AI16) -> 0
A17: 8 | B17: บางปะกง | AJ17: =COUNTA(E17:AI17) -> 0 | AK17: =COUNTA(E18:AI18) -> 0 | AL17: =COUNTA(E17:AI18) -> 0
A19: 9 | B19: บางคล้า | AJ19: =COUNTA(E19:AI19) -> 0 | AK19: =COUNTA(E20:AI20) -> 0 | AL19: =COUNTA(E19:AI20) -> 0
A21: 10 | B21: พนมสารคาม | AJ21: =COUNTA(E21:AI21) -> 0 | AK21: =COUNTA(E22:AI22) -> 0 | AL21: =COUNTA(E21:AI22) -> 0
A23: 11 | B23: ระยอง | AJ23: =COUNTA(E23:AI23) -> 0 | AK23: =COUNTA(E24:AI24) -> 0 | AL23: =COUNTA(E23:AI24) -> 0
A25: 12 | B25: บ้านฉาง | AJ25: =COUNTA(E25:AI25) -> 0 | AK25: =COUNTA(E26:AI26) -> 0 | AL25: =COUNTA(E25:AI26) -> 0
... A45: 22 | B45: กบินทร์บุรี | AJ45: =COUNTA(E45:AI45) -> 0 | AK45: =COUNTA(E46:AI46) -> 0 | AL45: =COUNTA(E45:AI46) -> 0
B48: * หมายเหตุ | C48: ✔ | D48: กิจกรรมลดน้ำสูญเสียเชิงกายภาพ
C49: ⭕ | D49: กิจกรรมลดน้ำสูญเสียเชิงพาณิชย์

Sheet ก.ย.69
A1: ลำดับ | B1: กปภ. สาขา | C1: กิจกรรมลดน้ำสูญเสีย | E1: วันที่ดำเนินกิจกรรมในเดือนกันยายน 2569 | AI1: เชิงกายภาพ (ครั้ง) | AJ1: เชิงพาณิชย์ (ครั้ง) | AK1: รวมทั้งหมด (ครั้ง)
C2: เชิงกายภาพ | D2: เชิงพาณิชย์ | E2: 1 | F2: 2 | G2: 3 | H2: 4 | I2: 5 | J2: 6 | K2: 7 | L2: 8 | M2: 9 | N2: 10 | O2: 11 | P2: 12 | Q2: 13 | R2: 14 | S2: 15 | T2: 16 | U2: 17 | V2: 18 | W2: 19 | X2: 20 | Y2: 21 | Z2: 22 | AA2: 23 | AB2: 24 | AC2: 25 | AD2: 26 | AE2: 27 | AF2: 28 | AG2: 29 | AH2: 30
A3: 1 | B3: ชลบุรี(พิเศษ) | AI3: =COUNTA(E3:AH3) -> 0 | AJ3: =COUNTA(E4:AH4) -> 0 | AK3: =COUNTA(E3:AH4) -> 0
A5: 2 | B5: พัทยา(พิเศษ) | AI5: =COUNTA(E5:AH5) -> 0 | AJ5: =COUNTA(E6:AH6) -> 0 | AK5: =COUNTA(E5:AH6) -> 0
A7: 3 | B7: บ้านบึง | AI7: =COUNTA(E7:AH7) -> 0 | AJ7: =COUNTA(E8:AH8) -> 0 | AK7: =COUNTA(E7:AH8) -> 0
A9: 4 | B9: พนัสนิคม | AI9: =COUNTA(E9:AH9) -> 0 | AJ9: =COUNTA(E10:AH10) -> 0 | AK9: =COUNTA(E9:AH10) -> 0
A11: 5 | B11: ศรีราชา | AI11: =COUNTA(E11:AH11) -> 0 | AJ11: =COUNTA(E12:AH12) -> 0 | AK11: =COUNTA(E11:AH12) -> 0
A13: 6 | B13: แหลมฉบัง | AI13: =COUNTA(E13:AH13) -> 0 | AJ13: =COUNTA(E14:AH14) -> 0 | AK13: =COUNTA(E13:AH14) -> 0
A15: 7 | B15: ฉะเชิงเทรา | AI15: =COUNTA(E15:AH15) -> 0 | AJ15: =COUNTA(E16:AH16) -> 0 | AK15: =COUNTA(E15:AH16) -> 0
A17: 8 | B17: บางปะกง | AI17: =COUNTA(E17:AH17) -> 0 | AJ17: =COUNTA(E18:AH18) -> 0 | AK17: =COUNTA(E17:AH18) -> 0
A19: 9 | B19: บางคล้า | AI19: =COUNTA(E19:AH19) -> 0 | AJ19: =COUNTA(E20:AH20) -> 0 | AK19: =COUNTA(E19:AH20) -> 0
A21: 10 | B21: พนมสารคาม | AI21: =COUNTA(E21:AH21) -> 0 | AJ21: =COUNTA(E22:AH22) -> 0 | AK21: =COUNTA(E21:AH22) -> 0
A23: 11 | B23: ระยอง | AI23: =COUNTA(E23:AH23) -> 0 | AJ23: =COUNTA(E24:AH24) -> 0 | AK23: =COUNTA(E23:AH24) -> 0
A25: 12 | B25: บ้านฉาง | AI25: =COUNTA(E25:AH25) -> 0 | AJ25: =COUNTA(E26:AH26) -> 0 | AK25: =COUNTA(E25:AH26) -> 0
... A45: 22 | B45: กบินทร์บุรี | AI45: =COUNTA(E45:AH45) -> 0 | AJ45: =COUNTA(E46:AH46) -> 0 | AK45: =COUNTA(E45:AH46) -> 0
B48: * หมายเหตุ | C48: ✔ | D48: กิจกรรมลดน้ำสูญเสียเชิงกายภาพ
C49: ⭕ | D49: กิจกรรมลดน้ำสูญเสียเชิงพาณิชย์

Sheet ต.ค.69
A1: ลำดับ | B1: กปภ. สาขา | C1: กิจกรรมลดน้ำสูญเสีย | E1: วันที่ดำเนินกิจกรรมในเดือนตุลาคม 2569 | AJ1: เชิงกายภาพ (ครั้ง) | AK1: เชิงพาณิชย์ (ครั้ง) | AL1: รวมทั้งหมด (ครั้ง)
C2: เชิงกายภาพ | D2: เชิงพาณิชย์ | E2: 1 | F2: 2 | G2: 3 | H2: 4 | I2: 5 | J2: 6 | K2: 7 | L2: 8 | M2: 9 | N2: 10 | O2: 11 | P2: 12 | Q2: 13 | R2: 14 | S2: 15 | T2: 16 | U2: 17 | V2: 18 | W2: 19 | X2: 20 | Y2: 21 | Z2: 22 | AA2: 23 | AB2: 24 | AC2: 25 | AD2: 26 | AE2: 27 | AF2: 28 | AG2: 29 | AH2: 30 | AI2: 31
A3: 1 | B3: ชลบุรี(พิเศษ) | AJ3: =COUNTA(E3:AI3) -> 0 | AK3: =COUNTA(E4:AI4) -> 0 | AL3: =COUNTA(E3:AI4) -> 0
A5: 2 | B5: พัทยา(พิเศษ) | AJ5: =COUNTA(E5:AI5) -> 0 | AK5: =COUNTA(E6:AI6) -> 0 | AL5: =COUNTA(E5:AI6) -> 0
A7: 3 | B7: บ้านบึง | AJ7: =COUNTA(E7:AI7) -> 0 | AK7: =COUNTA(E8:AI8) -> 0 | AL7: =COUNTA(E7:AI8) -> 0
A9: 4 | B9: พนัสนิคม | AJ9: =COUNTA(E9:AI9) -> 0 | AK9: =COUNTA(E10:AI10) -> 0 | AL9: =COUNTA(E9:AI10) -> 0
A11: 5 | B11: ศรีราชา | AJ11: =COUNTA(E11:AI11) -> 0 | AK11: =COUNTA(E12:AI12) -> 0 | AL11: =COUNTA(E11:AI12) -> 0
A13: 6 | B13: แหลมฉบัง | AJ13: =COUNTA(E13:AI13) -> 0 | AK13: =COUNTA(E14:AI14) -> 0 | AL13: =COUNTA(E13:AI14) -> 0
A15: 7 | B15: ฉะเชิงเทรา | AJ15: =COUNTA(E15:AI15) -> 0 | AK15: =COUNTA(E16:AI16) -> 0 | AL15: =COUNTA(E15:AI16) -> 0
A17: 8 | B17: บางปะกง | AJ17: =COUNTA(E17:AI17) -> 0 | AK17: =COUNTA(E18:AI18) -> 0 | AL17: =COUNTA(E17:AI18) -> 0
A19: 9 | B19: บางคล้า | AJ19: =COUNTA(E19:AI19) -> 0 | AK19: =COUNTA(E20:AI20) -> 0 | AL19: =COUNTA(E19:AI20) -> 0
A21: 10 | B21: พนมสารคาม | AJ21: =COUNTA(E21:AI21) -> 0 | AK21: =COUNTA(E22:AI22) -> 0 | AL21: =COUNTA(E21:AI22) -> 0
A23: 11 | B23: ระยอง | AJ23: =COUNTA(E23:AI23) -> 0 | AK23: =COUNTA(E24:AI24) -> 0 | AL23: =COUNTA(E23:AI24) -> 0
